Workbook

Sheet PAGAMENTO
A1: Lucas Santana | B1: OK
A2: Josué | B2: OK
A3: Daniel | B3: OK
A4: Diana | B4: OK
A5: Lucas Joels | B5: OK
A6: Humberto | B6: OK
A7: Barrão | B7: OK
A8: Copeiro X | B8: OK
A9: Jê | B9: OK
A10: Zé Luis
A11: Bento
A12: Tuka
A13: Tello | B13: OK
A14: Matheus
A15: Noé
A16: Camilla
A17: Nelson Razão
A18: Nelson Emoção
A19: Valentina
A20: Quito | B20: OK
A21: Laufer

Sheet APOSTAS
B2: SEU NOME AQUI | H2: DATA | K2: PONTUAÇÃO | L2: =SUM(K:K) -> 0
B4: DEZESSEIS AVOS | H4: DIA | I4: HORA | K4: total | L4: cravou | M4: venc + 1 gol | N4: venc + saldo | O4: venc | P4: cravou empate | Q4: empate | R4: quem passou
B5: =RESULTADOS!B5 -> Alemanha | D5: x | F5: =RESULTADOS!F5 -> Paraguai | H5: 46202 | I5: 0.72916667 | K5: =SUM(L5:R5) -> 0 | L5: =IF(AND(ISNUMBER(C5), ISNUMBER(E5), ISNUMBER(RESULTADOS!C5), ISNUMBER(RESULTADOS!E5), C5=RESULTADOS!C5, E5=RESULTADOS!E5, C5<>E5), 5, 0) -> 0 | M5: =IF( AND(ISNUMBER(C5), ISNUMBER(E5), ISNUMBER(RESULTADOS!C5), ISNUMBER(RESULTADOS!E5), L5=0, OR(AND(C5>E5, RESULTADOS!C5>RESULTADOS!E5), AND(E5>C5, RESULTADOS!E5>RESULTADOS!C5)), OR(C5=RESULTADOS!C5, E5=RESULTADOS!E5) ), 3, 0 ) -> 0 | N5: =IF( AND(ISNUMBER(C5), ISNUMBER(E5), ISNUMBER(RESULTADOS!C5), ISNUMBER(RESULTADOS!E5), L5=0, M5=0, C5<>E5, C5-E5=RESULTADOS!C5-RESULTADOS!E5 ), 2, 0 ) -> 0 | O5: =IF( AND(ISNUMBER(C5), ISNUMBER(E5), ISNUMBER(RESULTADOS!C5), ISNUMBER(RESULTADOS!E5), L5=0, M5=0, N5=0, OR(AND(C5>E5, RESULTADOS!C5>RESULTADOS!E5), AND(E5>C5, RESULTADOS!E5>RESULTADOS!C5)) ), 1, 0 ) -> 0 | P5: =IF(AND(ISNUMBER(C5), ISNUMBER(E5), ISNUMBER(RESULTADOS!C5), ISNUMBER(RESULTADOS!E5), L5=0,M5=0,O5=0, C5=RESULTADOS!C5, E5=RESULTADOS!E5), 4, 0) -> 0 | Q5: =IF(AND(ISNUMBER(C5), ISNUMBER(E5), ISNUMBER(RESULTADOS!C5), ISNUMBER(RESULTADOS!E5), L5=0,M5=0,O5=0, P5=0,C5=E5, RESULTADOS!C5=RESULTADOS!E5), 2, 0) -> 0 | R5: =IF(AND(ISNUMBER(C5), ISNUMBER(E5), ISNUMBER(RESULTADOS!C5), ISNUMBER(RESULTADOS!E5), ISNUMBER(C6), ISNUMBER(E6), ISNUMBER(RESULTADOS!C5), ISNUMBER(RESULTADOS!E5),L5=0,M5=0,O5=0, C5=E5, RESULTADOS!C5=RESULTADOS!E5, OR(AND(C6>E6, RESULTADOS!C6>RESULTADOS!E6), AND(E6>C6, RESULTADOS!E6>RESULTADOS!C6))), 1, 0) -> 0
B6: =IF(AND(ISNUMBER(C5),ISNUMBER(E5),C5=E5),"Pênaltis","")
B7: =RESULTADOS!B7 -> França | D7: x | F7: =RESULTADOS!F7 -> Suécia | H7: 46203 | I7: 0.75 | K7: =SUM(L7:R7) -> 0 | L7: =IF(AND(ISNUMBER(C7), ISNUMBER(E7), ISNUMBER(RESULTADOS!C7), ISNUMBER(RESULTADOS!E7), C7=RESULTADOS!C7, E7=RESULTADOS!E7, C7<>E7), 5, 0) -> 0 | M7: =IF( AND(ISNUMBER(C7), ISNUMBER(E7), ISNUMBER(RESULTADOS!C7), ISNUMBER(RESULTADOS!E7), L7=0, OR(AND(C7>E7, RESULTADOS!C7>RESULTADOS!E7), AND(E7>C7, RESULTADOS!E7>RESULTADOS!C7)), OR(C7=RESULTADOS!C7, E7=RESULTADOS!E7) ), 3, 0 ) -> 0 | N7: =IF( AND(ISNUMBER(C7), ISNUMBER(E7), ISNUMBER(RESULTADOS!C7), ISNUMBER(RESULTADOS!E7), L7=0, M7=0, C7<>E7, C7-E7=RESULTADOS!C7-RESULTADOS!E7 ), 2, 0 ) -> 0 | O7: =IF( AND(ISNUMBER(C7), ISNUMBER(E7), ISNUMBER(RESULTADOS!C7), ISNUMBER(RESULTADOS!E7), L7=0, M7=0, N7=0, OR(AND(C7>E7, RESULTADOS!C7>RESULTADOS!E7), AND(E7>C7, RESULTADOS!E7>RESULTADOS!C7)) ), 1, 0 ) -> 0 | P7: =IF(AND(ISNUMBER(C7), ISNUMBER(E7), ISNUMBER(RESULTADOS!C7), ISNUMBER(RESULTADOS!E7), L7=0,M7=0,O7=0, C7=RESULTADOS!C7, E7=RESULTADOS!E7), 4, 0) -> 0 | Q7: =IF(AND(ISNUMBER(C7), ISNUMBER(E7), ISNUMBER(RESULTADOS!C7), ISNUMBER(RESULTADOS!E7), L7=0,M7=0,O7=0, P7=0,C7=E7, RESULTADOS!C7=RESULTADOS!E7), 2, 0) -> 0 | R7: =IF(AND(ISNUMBER(C7), ISNUMBER(E7), ISNUMBER(RESULTADOS!C7), ISNUMBER(RESULTADOS!E7), ISNUMBER(C8), ISNUMBER(E8), ISNUMBER(RESULTADOS!C7), ISNUMBER(RESULTADOS!E7),L7=0,M7=0,O7=0, C7=E7, RESULTADOS!C7=RESULTADOS!E7, OR(AND(C8>E8, RESULTADOS!C8>RESULTADOS!E8), AND(E8>C8, RESULTADOS!E8>RESULTADOS!C8))), 1, 0) -> 0
B8: =IF(AND(ISNUMBER(C7),ISNUMBER(E7),C7=E7),"Pênaltis","")
B9: =RESULTADOS!B9 -> África do Sul | D9: x | F9: =RESULTADOS!F9 -> Canadá | H9: 46201 | I9: 0.66666667 | K9: =SUM(L9:R9) -> 0 | L9: =IF(AND(ISNUMBER(C9), ISNUMBER(E9), ISNUMBER(RESULTADOS!C9), ISNUMBER(RESULTADOS!E9), C9=RESULTADOS!C9, E9=RESULTADOS!E9, C9<>E9), 5, 0) -> 0 | M9: =IF( AND(ISNUMBER(C9), ISNUMBER(E9), ISNUMBER(RESULTADOS!C9), ISNUMBER(RESULTADOS!E9), L9=0, OR(AND(C9>E9, RESULTADOS!C9>RESULTADOS!E9), AND(E9>C9, RESULTADOS!E9>RESULTADOS!C9)), OR(C9=RESULTADOS!C9, E9=RESULTADOS!E9) ), 3, 0 ) -> 0 | N9: =IF( AND(ISNUMBER(C9), ISNUMBER(E9), ISNUMBER(RESULTADOS!C9), ISNUMBER(RESULTADOS!E9), L9=0, M9=0, C9<>E9, C9-E9=RESULTADOS!C9-RESULTADOS!E9 ), 2, 0 ) -> 0 | O9: =IF( AND(ISNUMBER(C9), ISNUMBER(E9), ISNUMBER(RESULTADOS!C9), ISNUMBER(RESULTADOS!E9), L9=0, M9=0, N9=0, OR(AND(C9>E9, RESULTADOS!C9>RESULTADOS!E9), AND(E9>C9, RESULTADOS!E9>RESULTADOS!C9)) ), 1, 0 ) -> 0 | P9: =IF(AND(ISNUMBER(C9), ISNUMBER(E9), ISNUMBER(RESULTADOS!C9), ISNUMBER(RESULTADOS!E9), L9=0,M9=0,O9=0, C9=RESULTADOS!C9, E9=RESULTADOS!E9), 4, 0) -> 0 | Q9: =IF(AND(ISNUMBER(C9), ISNUMBER(E9), ISNUMBER(RESULTADOS!C9), ISNUMBER(RESULTADOS!E9), L9=0,M9=0,O9=0, P9=0,C9=E9, RESULTADOS!C9=RESULTADOS!E9), 2, 0) -> 0 | R9: =IF(AND(ISNUMBER(C9), ISNUMBER(E9), ISNUMBER(RESULTADOS!C9), ISNUMBER(RESULTADOS!E9), ISNUMBER(C10), ISNUMBER(E10), ISNUMBER(RESULTADOS!C9), ISNUMBER(RESULTADOS!E9),L9=0,M9=0,O9=0, C9=E9, RESULTADOS!C9=RESULTADOS!E9, OR(AND(C10>E10, RESULTADOS!C10>RESULTADOS!E10), AND(E10>C10, RESULTADOS!E10>RESULTADOS!C10))), 1, 0) -> 0
B10: =IF(AND(ISNUMBER(C9),ISNUMBER(E9),C9=E9),"Pênaltis","")
B11: =RESULTADOS!B11 -> Holanda | D11: x | F11: =RESULTADOS!F11 -> Marrocos | H11: 46202 | I11: 0.91666667 | K11: =SUM(L11:R11) -> 0 | L11: =IF(AND(ISNUMBER(C11), ISNUMBER(E11), ISNUMBER(RESULTADOS!C11), ISNUMBER(RESULTADOS!E11), C11=RESULTADOS!C11, E11=RESULTADOS!E11, C11<>E11), 5, 0) -> 0 | M11: =IF( AND(ISNUMBER(C11), ISNUMBER(E11), ISNUMBER(RESULTADOS!C11), ISNUMBER(RESULTADOS!E11), L11=0, OR(AND(C11>E11, RESULTADOS!C11>RESULTADOS!E11), AND(E11>C11, RESULTADOS!E11>RESULTADOS!C11)), OR(C11=RESULTADOS!C11, E11=RESULTADOS!E11) ), 3, 0 ) -> 0 | N11: =IF( AND(ISNUMBER(C11), ISNUMBER(E11), ISNUMBER(RESULTADOS!C11), ISNUMBER(RESULTADOS!E11), L11=0, M11=0, C11<>E11, C11-E11=RESULTADOS!C11-RESULTADOS!E11 ), 2, 0 ) -> 0 | O11: =IF( AND(ISNUMBER(C11), ISNUMBER(E11), ISNUMBER(RESULTADOS!C11), ISNUMBER(RESULTADOS!E11), L11=0, M11=0, N11=0, OR(AND(C11>E11, RESULTADOS!C11>RESULTADOS!E11), AND(E11>C11, RESULTADOS!E11>RESULTADOS!C11)) ), 1, 0 ) -> 0 | P11: =IF(AND(ISNUMBER(C11), ISNUMBER(E11), ISNUMBER(RESULTADOS!C11), ISNUMBER(RESULTADOS!E11), L11=0,M11=0,O11=0, C11=RESULTADOS!C11, E11=RESULTADOS!E11), 4, 0) -> 0 | Q11: =IF(AND(ISNUMBER(C11), ISNUMBER(E11), ISNUMBER(RESULTADOS!C11), ISNUMBER(RESULTADOS!E11), L11=0,M11=0,O11=0, P11=0,C11=E11, RESULTADOS!C11=RESULTADOS!E11), 2, 0) -> 0 | R11: =IF(AND(ISNUMBER(C11), ISNUMBER(E11), ISNUMBER(RESULTADOS!C11), ISNUMBER(RESULTADOS!E11), ISNUMBER(C12), ISNUMBER(E12), ISNUMBER(RESULTADOS!C11), ISNUMBER(RESULTADOS!E11),L11=0,M11=0,O11=0, C11=E11, RESULTADOS!C11=RESULTADOS!E11, OR(AND(C12>E12, RESULTADOS!C12>RESULTADOS!E12), AND(E12>C12, RESULTADOS!E12>RESULTADOS!C12))), 1, 0) -> 0
B12: =IF(AND(ISNUMBER(C11),ISNUMBER(E11),C11=E11),"Pênaltis","")
B13: =RESULTADOS!B13 -> Portugal | D13: x | F13: =RESULTADOS!F13 -> Croácia | H13: 46205 | I13: 0.83333333 | K13: =SUM(L13:R13) -> 0 | L13: =IF(AND(ISNUMBER(C13), ISNUMBER(E13), ISNUMBER(RESULTADOS!C13), ISNUMBER(RESULTADOS!E13), C13=RESULTADOS!C13, E13=RESULTADOS!E13, C13<>E13), 5, 0) -> 0 | M13: =IF( AND(ISNUMBER(C13), ISNUMBER(E13), ISNUMBER(RESULTADOS!C13), ISNUMBER(RESULTADOS!E13), L13=0, OR(AND(C13>E13, RESULTADOS!C13>RESULTADOS!E13), AND(E13>C13, RESULTADOS!E13>RESULTADOS!C13)), OR(C13=RESULTADOS!C13, E13=RESULTADOS!E13) ), 3, 0 ) -> 0 | N13: =IF( AND(ISNUMBER(C13), ISNUMBER(E13), ISNUMBER(RESULTADOS!C13), ISNUMBER(RESULTADOS!E13), L13=0, M13=0, C13<>E13, C13-E13=RESULTADOS!C13-RESULTADOS!E13 ), 2, 0 ) -> 0 | O13: =IF( AND(ISNUMBER(C13), ISNUMBER(E13), ISNUMBER(RESULTADOS!C13), ISNUMBER(RESULTADOS!E13), L13=0, M13=0, N13=0, OR(AND(C13>E13, RESULTADOS!C13>RESULTADOS!E13), AND(E13>C13, RESULTADOS!E13>RESULTADOS!C13)) ), 1, 0 ) -> 0 | P13: =IF(AND(ISNUMBER(C13), ISNUMBER(E13), ISNUMBER(RESULTADOS!C13), ISNUMBER(RESULTADOS!E13), L13=0,M13=0,O13=0, C13=RESULTADOS!C13, E13=RESULTADOS!E13), 4, 0) -> 0 | Q13: =IF(AND(ISNUMBER(C13), ISNUMBER(E13), ISNUMBER(RESULTADOS!C13), ISNUMBER(RESULTADOS!E13), L13=0,M13=0,O13=0, P13=0,C13=E13, RESULTADOS!C13=RESULTADOS!E13), 2, 0) -> 0 | R13: =IF(AND(ISNUMBER(C13), ISNUMBER(E13), ISNUMBER(RESULTADOS!C13), ISNUMBER(RESULTADOS!E13), ISNUMBER(C14), ISNUMBER(E14), ISNUMBER(RESULTADOS!C13), ISNUMBER(RESULTADOS!E13),L13=0,M13=0,O13=0, C13=E13, RESULTADOS!C13=RESULTADOS!E13, OR(AND(C14>E14, RESULTADOS!C14>RESULTADOS!E14), AND(E14>C14, RESULTADOS!E14>RESULTADOS!C14))), 1, 0) -> 0
B14: =IF(AND(ISNUMBER(C13),ISNUMBER(E13),C13=E13),"Pênaltis","")
B15: =RESULTADOS!B15 -> Espanha | D15: x | F15: =RESULTADOS!F15 -> Áustria | H15: 46205 | I15: 0.66666667 | K15: =SUM(L15:R15) -> 0 | L15: =IF(AND(ISNUMBER(C15), ISNUMBER(E15), ISNUMBER(RESULTADOS!C15), ISNUMBER(RESULTADOS!E15), C15=RESULTADOS!C15, E15=RESULTADOS!E15, C15<>E15), 5, 0) -> 0 | M15: =IF( AND(ISNUMBER(C15), ISNUMBER(E15), ISNUMBER(RESULTADOS!C15), ISNUMBER(RESULTADOS!E15), L15=0, OR(AND(C15>E15, RESULTADOS!C15>RESULTADOS!E15), AND(E15>C15, RESULTADOS!E15>RESULTADOS!C15)), OR(C15=RESULTADOS!C15, E15=RESULTADOS!E15) ), 3, 0 ) -> 0 | N15: =IF( AND(ISNUMBER(C15), ISNUMBER(E15), ISNUMBER(RESULTADOS!C15), ISNUMBER(RESULTADOS!E15), L15=0, M15=0, C15<>E15, C15-E15=RESULTADOS!C15-RESULTADOS!E15 ), 2, 0 ) -> 0 | O15: =IF( AND(ISNUMBER(C15), ISNUMBER(E15), ISNUMBER(RESULTADOS!C15), ISNUMBER(RESULTADOS!E15), L15=0, M15=0, N15=0, OR(AND(C15>E15, RESULTADOS!C15>RESULTADOS!E15), AND(E15>C15, RESULTADOS!E15>RESULTADOS!C15)) ), 1, 0 ) -> 0 | P15: =IF(AND(ISNUMBER(C15), ISNUMBER(E15), ISNUMBER(RESULTADOS!C15), ISNUMBER(RESULTADOS!E15), L15=0,M15=0,O15=0, C15=RESULTADOS!C15, E15=RESULTADOS!E15), 4, 0) -> 0 | Q15: =IF(AND(ISNUMBER(C15), ISNUMBER(E15), ISNUMBER(RESULTADOS!C15), ISNUMBER(RESULTADOS!E15), L15=0,M15=0,O15=0, P15=0,C15=E15, RESULTADOS!C15=RESULTADOS!E15), 2, 0) -> 0 | R15: =IF(AND(ISNUMBER(C15), ISNUMBER(E15), ISNUMBER(RESULTADOS!C15), ISNUMBER(RESULTADOS!E15), ISNUMBER(C16), ISNUMBER(E16), ISNUMBER(RESULTADOS!C15), ISNUMBER(RESULTADOS!E15),L15=0,M15=0,O15=0, C15=E15, RESULTADOS!C15=RESULTADOS!E15, OR(AND(C16>E16, RESULTADOS!C16>RESULTADOS!E16), AND(E16>C16, RESULTADOS!E16>RESULTADOS!C16))), 1, 0) -> 0
B16: =IF(AND(ISNUMBER(C15),ISNUMBER(E15),C15=E15),"Pênaltis","")
B17: =RESULTADOS!B17 -> Estados Unidos | D17: x | F17: =RESULTADOS!F17 -> Bósnia | H17: 46204 | I17: 0.875 | K17: =SUM(L17:R17) -> 0 | L17: =IF(AND(ISNUMBER(C17), ISNUMBER(E17), ISNUMBER(RESULTADOS!C17), ISNUMBER(RESULTADOS!E17), C17=RESULTADOS!C17, E17=RESULTADOS!E17, C17<>E17), 5, 0) -> 0 | M17: =IF( AND(ISNUMBER(C17), ISNUMBER(E17), ISNUMBER(RESULTADOS!C17), ISNUMBER(RESULTADOS!E17), L17=0, OR(AND(C17>E17, RESULTADOS!C17>RESULTADOS!E17), AND(E17>C17, RESULTADOS!E17>RESULTADOS!C17)), OR(C17=RESULTADOS!C17, E17=RESULTADOS!E17) ), 3, 0 ) -> 0 | N17: =IF( AND(ISNUMBER(C17), ISNUMBER(E17), ISNUMBER(RESULTADOS!C17), ISNUMBER(RESULTADOS!E17), L17=0, M17=0, C17<>E17, C17-E17=RESULTADOS!C17-RESULTADOS!E17 ), 2, 0 ) -> 0 | O17: =IF( AND(ISNUMBER(C17), ISNUMBER(E17), ISNUMBER(RESULTADOS!C17), ISNUMBER(RESULTADOS!E17), L17=0, M17=0, N17=0, OR(AND(C17>E17, RESULTADOS!C17>RESULTADOS!E17), AND(E17>C17, RESULTADOS!E17>RESULTADOS!C17)) ), 1, 0 ) -> 0 | P17: =IF(AND(ISNUMBER(C17), ISNUMBER(E17), ISNUMBER(RESULTADOS!C17), ISNUMBER(RESULTADOS!E17), L17=0,M17=0,O17=0, C17=RESULTADOS!C17, E17=RESULTADOS!E17), 4, 0) -> 0 | Q17: =IF(AND(ISNUMBER(C17), ISNUMBER(E17), ISNUMBER(RESULTADOS!C17), ISNUMBER(RESULTADOS!E17), L17=0,M17=0,O17=0, P17=0,C17=E17, RESULTADOS!C17=RESULTADOS!E17), 2, 0) -> 0 | R17: =IF(AND(ISNUMBER(C17), ISNUMBER(E17), ISNUMBER(RESULTADOS!C17), ISNUMBER(RESULTADOS!E17), ISNUMBER(C18), ISNUMBER(E18), ISNUMBER(RESULTADOS!C17), ISNUMBER(RESULTADOS!E17),L17=0,M17=0,O17=0, C17=E17, RESULTADOS!C17=RESULTADOS!E17, OR(AND(C18>E18, RESULTADOS!C18>RESULTADOS!E18), AND(E18>C18, RESULTADOS!E18>RESULTADOS!C18))), 1, 0) -> 0
B18: =IF(AND(ISNUMBER(C17),ISNUMBER(E17),C17=E17),"Pênaltis","")
B19: =RESULTADOS!B19 -> Bélgica | D19: x | F19: =RESULTADOS!F19 -> Senegal | H19: 46204 | I19: 0.70833333 | K19: =SUM(L19:R19) -> 0 | L19: =IF(AND(ISNUMBER(C19), ISNUMBER(E19), ISNUMBER(RESULTADOS!C19), ISNUMBER(RESULTADOS!E19), C19=RESULTADOS!C19, E19=RESULTADOS!E19, C19<>E19), 5, 0) -> 0 | M19: =IF( AND(ISNUMBER(C19), ISNUMBER(E19), ISNUMBER(RESULTADOS!C19), ISNUMBER(RESULTADOS!E19), L19=0, OR(AND(C19>E19, RESULTADOS!C19>RESULTADOS!E19), AND(E19>C19, RESULTADOS!E19>RESULTADOS!C19)), OR(C19=RESULTADOS!C19, E19=RESULTADOS!E19) ), 3, 0 ) -> 0 | N19: =IF( AND(ISNUMBER(C19), ISNUMBER(E19), ISNUMBER(RESULTADOS!C19), ISNUMBER(RESULTADOS!E19), L19=0, M19=0, C19<>E19, C19-E19=RESULTADOS!C19-RESULTADOS!E19 ), 2, 0 ) -> 0 | O19: =IF( AND(ISNUMBER(C19), ISNUMBER(E19), ISNUMBER(RESULTADOS!C19), ISNUMBER(RESULTADOS!E19), L19=0, M19=0, N19=0, OR(AND(C19>E19, RESULTADOS!C19>RESULTADOS!E19), AND(E19>C19, RESULTADOS!E19>RESULTADOS!C19)) ), 1, 0 ) -> 0 | P19: =IF(AND(ISNUMBER(C19), ISNUMBER(E19), ISNUMBER(RESULTADOS!C19), ISNUMBER(RESULTADOS!E19), L19=0,M19=0,O19=0, C19=RESULTADOS!C19, E19=RESULTADOS!E19), 4, 0) -> 0 | Q19: =IF(AND(ISNUMBER(C19), ISNUMBER(E19), ISNUMBER(RESULTADOS!C19), ISNUMBER(RESULTADOS!E19), L19=0,M19=0,O19=0, P19=0,C19=E19, RESULTADOS!C19=RESULTADOS!E19), 2, 0) -> 0 | R19: =IF(AND(ISNUMBER(C19), ISNUMBER(E19), ISNUMBER(RESULTADOS!C19), ISNUMBER(RESULTADOS!E19), ISNUMBER(C20), ISNUMBER(E20), ISNUMBER(RESULTADOS!C19), ISNUMBER(RESULTADOS!E19),L19=0,M19=0,O19=0, C19=E19, RESULTADOS!C19=RESULTADOS!E19, OR(AND(C20>E20, RESULTADOS!C20>RESULTADOS!E20), AND(E20>C20, RESULTADOS!E20>RESULTADOS!C20))), 1, 0) -> 0
B20: =IF(AND(ISNUMBER(C19),ISNUMBER(E19),C19=E19),"Pênaltis","")
B21: =RESULTADOS!B21 -> Brasil | D21: x | F21: =RESULTADOS!F21 -> Japão | H21: 46202 | I21: 0.58333333 | K21: =SUM(L21:R21) -> 0 | L21: =IF(AND(ISNUMBER(C21), ISNUMBER(E21), ISNUMBER(RESULTADOS!C21), ISNUMBER(RESULTADOS!E21), C21=RESULTADOS!C21, E21=RESULTADOS!E21, C21<>E21), 5, 0) -> 0 | M21: =IF( AND(ISNUMBER(C21), ISNUMBER(E21), ISNUMBER(RESULTADOS!C21), ISNUMBER(RESULTADOS!E21), L21=0, OR(AND(C21>E21, RESULTADOS!C21>RESULTADOS!E21), AND(E21>C21, RESULTADOS!E21>RESULTADOS!C21)), OR(C21=RESULTADOS!C21, E21=RESULTADOS!E21) ), 3, 0 ) -> 0 | N21: =IF( AND(ISNUMBER(C21), ISNUMBER(E21), ISNUMBER(RESULTADOS!C21), ISNUMBER(RESULTADOS!E21), L21=0, M21=0, C21<>E21, C21-E21=RESULTADOS!C21-RESULTADOS!E21 ), 2, 0 ) -> 0 | O21: =IF( AND(ISNUMBER(C21), ISNUMBER(E21), ISNUMBER(RESULTADOS!C21), ISNUMBER(RESULTADOS!E21), L21=0, M21=0, N21=0, OR(AND(C21>E21, RESULTADOS!C21>RESULTADOS!E21), AND(E21>C21, RESULTADOS!E21>RESULTADOS!C21)) ), 1, 0 ) -> 0 | P21: =IF(AND(ISNUMBER(C21), ISNUMBER(E21), ISNUMBER(RESULTADOS!C21), ISNUMBER(RESULTADOS!E21), L21=0,M21=0,O21=0, C21=RESULTADOS!C21, E21=RESULTADOS!E21), 4, 0) -> 0 | Q21: =IF(AND(ISNUMBER(C21), ISNUMBER(E21), ISNUMBER(RESULTADOS!C21), ISNUMBER(RESULTADOS!E21), L21=0,M21=0,O21=0, P21=0,C21=E21, RESULTADOS!C21=RESULTADOS!E21), 2, 0) -> 0 | R21: =IF(AND(ISNUMBER(C21), ISNUMBER(E21), ISNUMBER(RESULTADOS!C21), ISNUMBER(RESULTADOS!E21), ISNUMBER(C22), ISNUMBER(E22), ISNUMBER(RESULTADOS!C21), ISNUMBER(RESULTADOS!E21),L21=0,M21=0,O21=0, C21=E21, RESULTADOS!C21=RESULTADOS!E21, OR(AND(C22>E22, RESULTADOS!C22>RESULTADOS!E22), AND(E22>C22, RESULTADOS!E22>RESULTADOS!C22))), 1, 0) -> 0
B22: =IF(AND(ISNUMBER(C21),ISNUMBER(E21),C21=E21),"Pênaltis","")
B23: =RESULTADOS!B23 -> Costa do Marfim | D23: x | F23: =RESULTADOS!F23 -> Noruega | H23: 46203 | I23: 0.58333333 | K23: =SUM(L23:R23) -> 0 | L23: =IF(AND(ISNUMBER(C23), ISNUMBER(E23), ISNUMBER(RESULTADOS!C23), ISNUMBER(RESULTADOS!E23), C23=RESULTADOS!C23, E23=RESULTADOS!E23, C23<>E23), 5, 0) -> 0 | M23: =IF( AND(ISNUMBER(C23), ISNUMBER(E23), ISNUMBER(RESULTADOS!C23), ISNUMBER(RESULTADOS!E23), L23=0, OR(AND(C23>E23, RESULTADOS!C23>RESULTADOS!E23), AND(E23>C23, RESULTADOS!E23>RESULTADOS!C23)), OR(C23=RESULTADOS!C23, E23=RESULTADOS!E23) ), 3, 0 ) -> 0 | N23: =IF( AND(ISNUMBER(C23), ISNUMBER(E23), ISNUMBER(RESULTADOS!C23), ISNUMBER(RESULTADOS!E23), L23=0, M23=0, C23<>E23, C23-E23=RESULTADOS!C23-RESULTADOS!E23 ), 2, 0 ) -> 0 | O23: =IF( AND(ISNUMBER(C23), ISNUMBER(E23), ISNUMBER(RESULTADOS!C23), ISNUMBER(RESULTADOS!E23), L23=0, M23=0, N23=0, OR(AND(C23>E23, RESULTADOS!C23>RESULTADOS!E23), AND(E23>C23, RESULTADOS!E23>RESULTADOS!C23)) ), 1, 0 ) -> 0 | P23: =IF(AND(ISNUMBER(C23), ISNUMBER(E23), ISNUMBER(RESULTADOS!C23), ISNUMBER(RESULTADOS!E23), L23=0,M23=0,O23=0, C23=RESULTADOS!C23, E23=RESULTADOS!E23), 4, 0) -> 0 | Q23: =IF(AND(ISNUMBER(C23), ISNUMBER(E23), ISNUMBER(RESULTADOS!C23), ISNUMBER(RESULTADOS!E23), L23=0,M23=0,O23=0, P23=0,C23=E23, RESULTADOS!C23=RESULTADOS!E23), 2, 0) -> 0 | R23: =IF(AND(ISNUMBER(C23), ISNUMBER(E23), ISNUMBER(RESULTADOS!C23), ISNUMBER(RESULTADOS!E23), ISNUMBER(C24), ISNUMBER(E24), ISNUMBER(RESULTADOS!C23), ISNUMBER(RESULTADOS!E23),L23=0,M23=0,O23=0, C23=E23, RESULTADOS!C23=RESULTADOS!E23, OR(AND(C24>E24, RESULTADOS!C24>RESULTADOS!E24), AND(E24>C24, RESULTADOS!E24>RESULTADOS!C24))), 1, 0) -> 0
B24: =IF(AND(ISNUMBER(C23),ISNUMBER(E23),C23=E23),"Pênaltis","")
B25: =RESULTADOS!B25 -> México | D25: x | F25: =RESULTADOS!F25 -> Equador | H25: 46203 | I25: 0.91666667 | K25: =SUM(L25:R25) -> 0 | L25: =IF(AND(ISNUMBER(C25), ISNUMBER(E25), ISNUMBER(RESULTADOS!C25), ISNUMBER(RESULTADOS!E25), C25=RESULTADOS!C25, E25=RESULTADOS!E25, C25<>E25), 5, 0) -> 0 | M25: =IF( AND(ISNUMBER(C25), ISNUMBER(E25), ISNUMBER(RESULTADOS!C25), ISNUMBER(RESULTADOS!E25), L25=0, OR(AND(C25>E25, RESULTADOS!C25>RESULTADOS!E25), AND(E25>C25, RESULTADOS!E25>RESULTADOS!C25)), OR(C25=RESULTADOS!C25, E25=RESULTADOS!E25) ), 3, 0 ) -> 0 | N25: =IF( AND(ISNUMBER(C25), ISNUMBER(E25), ISNUMBER(RESULTADOS!C25), ISNUMBER(RESULTADOS!E25), L25=0, M25=0, C25<>E25, C25-E25=RESULTADOS!C25-RESULTADOS!E25 ), 2, 0 ) -> 0 | O25: =IF( AND(ISNUMBER(C25), ISNUMBER(E25), ISNUMBER(RESULTADOS!C25), ISNUMBER(RESULTADOS!E25), L25=0, M25=0, N25=0, OR(AND(C25>E25, RESULTADOS!C25>RESULTADOS!E25), AND(E25>C25, RESULTADOS!E25>RESULTADOS!C25)) ), 1, 0 ) -> 0 | P25: =IF(AND(ISNUMBER(C25), ISNUMBER(E25), ISNUMBER(RESULTADOS!C25), ISNUMBER(RESULTADOS!E25), L25=0,M25=0,O25=0, C25=RESULTADOS!C25, E25=RESULTADOS!E25), 4, 0) -> 0 | Q25: =IF(AND(ISNUMBER(C25), ISNUMBER(E25), ISNUMBER(RESULTADOS!C25), ISNUMBER(RESULTADOS!E25), L25=0,M25=0,O25=0, P25=0,C25=E25, RESULTADOS!C25=RESULTADOS!E25), 2, 0) -> 0 | R25: =IF(AND(ISNUMBER(C25), ISNUMBER(E25), ISNUMBER(RESULTADOS!C25), ISNUMBER(RESULTADOS!E25), ISNUMBER(C26), ISNUMBER(E26), ISNUMBER(RESULTADOS!C25), ISNUMBER(RESULTADOS!E25),L25=0,M25=0,O25=0, C25=E25, RESULTADOS!C25=RESULTADOS!E25, OR(AND(C26>E26, RESULTADOS!C26>RESULTADOS!E26), AND(E26>C26, RESULTADOS!E26>RESULTADOS!C26))), 1, 0) -> 0
B26: =IF(AND(ISNUMBER(C25),ISNUMBER(E25),C25=E25),"Pênaltis","")
B27: =RESULTADOS!B27 -> Inglaterra | D27: x | F27: =RESULTADOS!F27 -> RD Congo | H27: 46204 | I27: 0.54166667 | K27: =SUM(L27:R27) -> 0 | L27: =IF(AND(ISNUMBER(C27), ISNUMBER(E27), ISNUMBER(RESULTADOS!C27), ISNUMBER(RESULTADOS!E27), C27=RESULTADOS!C27, E27=RESULTADOS!E27, C27<>E27), 5, 0) -> 0 | M27: =IF( AND(ISNUMBER(C27), ISNUMBER(E27), ISNUMBER(RESULTADOS!C27), ISNUMBER(RESULTADOS!E27), L27=0, OR(AND(C27>E27, RESULTADOS!C27>RESULTADOS!E27), AND(E27>C27, RESULTADOS!E27>RESULTADOS!C27)), OR(C27=RESULTADOS!C27, E27=RESULTADOS!E27) ), 3, 0 ) -> 0 | N27: =IF( AND(ISNUMBER(C27), ISNUMBER(E27), ISNUMBER(RESULTADOS!C27), ISNUMBER(RESULTADOS!E27), L27=0, M27=0, C27<>E27, C27-E27=RESULTADOS!C27-RESULTADOS!E27 ), 2, 0 ) -> 0 | O27: =IF( AND(ISNUMBER(C27), ISNUMBER(E27), ISNUMBER(RESULTADOS!C27), ISNUMBER(RESULTADOS!E27), L27=0, M27=0, N27=0, OR(AND(C27>E27, RESULTADOS!C27>RESULTADOS!E27), AND(E27>C27, RESULTADOS!E27>RESULTADOS!C27)) ), 1, 0 ) -> 0 | P27: =IF(AND(ISNUMBER(C27), ISNUMBER(E27), ISNUMBER(RESULTADOS!C27), ISNUMBER(RESULTADOS!E27), L27=0,M27=0,O27=0, C27=RESULTADOS!C27, E27=RESULTADOS!E27), 4, 0) -> 0 | Q27: =IF(AND(ISNUMBER(C27), ISNUMBER(E27), ISNUMBER(RESULTADOS!C27), ISNUMBER(RESULTADOS!E27), L27=0,M27=0,O27=0, P27=0,C27=E27, RESULTADOS!C27=RESULTADOS!E27), 2, 0) -> 0 | R27: =IF(AND(ISNUMBER(C27), ISNUMBER(E27), ISNUMBER(RESULTADOS!C27), ISNUMBER(RESULTADOS!E27), ISNUMBER(C28), ISNUMBER(E28), ISNUMBER(RESULTADOS!C27), ISNUMBER(RESULTADOS!E27),L27=0,M27=0,O27=0, C27=E27, RESULTADOS!C27=RESULTADOS!E27, OR(AND(C28>E28, RESULTADOS!C28>RESULTADOS!E28), AND(E28>C28, RESULTADOS!E28>RESULTADOS!C28))), 1, 0) -> 0
B28: =IF(AND(ISNUMBER(C27),ISNUMBER(E27),C27=E27),"Pênaltis","")
B29: =RESULTADOS!B29 -> Argentina | D29: x | F29: =RESULTADOS!F29 -> Cabo Verde | H29: 46206 | I29: 0.79166667 | K29: =SUM(L29:R29) -> 0 | L29: =IF(AND(ISNUMBER(C29), ISNUMBER(E29), ISNUMBER(RESULTADOS!C29), ISNUMBER(RESULTADOS!E29), C29=RESULTADOS!C29, E29=RESULTADOS!E29, C29<>E29), 5, 0) -> 0 | M29: =IF( AND(ISNUMBER(C29), ISNUMBER(E29), ISNUMBER(RESULTADOS!C29), ISNUMBER(RESULTADOS!E29), L29=0, OR(AND(C29>E29, RESULTADOS!C29>RESULTADOS!E29), AND(E29>C29, RESULTADOS!E29>RESULTADOS!C29)), OR(C29=RESULTADOS!C29, E29=RESULTADOS!E29) ), 3, 0 ) -> 0 | N29: =IF( AND(ISNUMBER(C29), ISNUMBER(E29), ISNUMBER(RESULTADOS!C29), ISNUMBER(RESULTADOS!E29), L29=0, M29=0, C29<>E29, C29-E29=RESULTADOS!C29-RESULTADOS!E29 ), 2, 0 ) -> 0 | O29: =IF( AND(ISNUMBER(C29), ISNUMBER(E29), ISNUMBER(RESULTADOS!C29), ISNUMBER(RESULTADOS!E29), L29=0, M29=0, N29=0, OR(AND(C29>E29, RESULTADOS!C29>RESULTADOS!E29), AND(E29>C29, RESULTADOS!E29>RESULTADOS!C29)) ), 1, 0 ) -> 0 | P29: =IF(AND(ISNUMBER(C29), ISNUMBER(E29), ISNUMBER(RESULTADOS!C29), ISNUMBER(RESULTADOS!E29), L29=0,M29=0,O29=0, C29=RESULTADOS!C29, E29=RESULTADOS!E29), 4, 0) -> 0 | Q29: =IF(AND(ISNUMBER(C29), ISNUMBER(E29), ISNUMBER(RESULTADOS!C29), ISNUMBER(RESULTADOS!E29), L29=0,M29=0,O29=0, P29=0,C29=E29, RESULTADOS!C29=RESULTADOS!E29), 2, 0) -> 0 | R29: =IF(AND(ISNUMBER(C29), ISNUMBER(E29), ISNUMBER(RESULTADOS!C29), ISNUMBER(RESULTADOS!E29), ISNUMBER(C30), ISNUMBER(E30), ISNUMBER(RESULTADOS!C29), ISNUMBER(RESULTADOS!E29),L29=0,M29=0,O29=0, C29=E29, RESULTADOS!C29=RESULTADOS!E29, OR(AND(C30>E30, RESULTADOS!C30>RESULTADOS!E30), AND(E30>C30, RESULTADOS!E30>RESULTADOS!C30))), 1, 0) -> 0
B30: =IF(AND(ISNUMBER(C29),ISNUMBER(E29),C29=E29),"Pênaltis","")
B31: =RESULTADOS!B31 -> Austrália | D31: x | F31: =RESULTADOS!F31 -> Egito | H31: 46206 | I31: 0.625 | K31: =SUM(L31:R31) -> 0 | L31: =IF(AND(ISNUMBER(C31), ISNUMBER(E31), ISNUMBER(RESULTADOS!C31), ISNUMBER(RESULTADOS!E31), C31=RESULTADOS!C31, E31=RESULTADOS!E31, C31<>E31), 5, 0) -> 0 | M31: =IF( AND(ISNUMBER(C31), ISNUMBER(E31), ISNUMBER(RESULTADOS!C31), ISNUMBER(RESULTADOS!E31), L31=0, OR(AND(C31>E31, RESULTADOS!C31>RESULTADOS!E31), AND(E31>C31, RESULTADOS!E31>RESULTADOS!C31)), OR(C31=RESULTADOS!C31, E31=RESULTADOS!E31) ), 3, 0 ) -> 0 | N31: =IF( AND(ISNUMBER(C31), ISNUMBER(E31), ISNUMBER(RESULTADOS!C31), ISNUMBER(RESULTADOS!E31), L31=0, M31=0, C31<>E31, C31-E31=RESULTADOS!C31-RESULTADOS!E31 ), 2, 0 ) -> 0 | O31: =IF( AND(ISNUMBER(C31), ISNUMBER(E31), ISNUMBER(RESULTADOS!C31), ISNUMBER(RESULTADOS!E31), L31=0, M31=0, N31=0, OR(AND(C31>E31, RESULTADOS!C31>RESULTADOS!E31), AND(E31>C31, RESULTADOS!E31>RESULTADOS!C31)) ), 1, 0 ) -> 0 | P31: =IF(AND(ISNUMBER(C31), ISNUMBER(E31), ISNUMBER(RESULTADOS!C31), ISNUMBER(RESULTADOS!E31), L31=0,M31=0,O31=0, C31=RESULTADOS!C31, E31=RESULTADOS!E31), 4, 0) -> 0 | Q31: =IF(AND(ISNUMBER(C31), ISNUMBER(E31), ISNUMBER(RESULTADOS!C31), ISNUMBER(RESULTADOS!E31), L31=0,M31=0,O31=0, P31=0,C31=E31, RESULTADOS!C31=RESULTADOS!E31), 2, 0) -> 0 | R31: =IF(AND(ISNUMBER(C31), ISNUMBER(E31), ISNUMBER(RESULTADOS!C31), ISNUMBER(RESULTADOS!E31), ISNUMBER(C32), ISNUMBER(E32), ISNUMBER(RESULTADOS!C31), ISNUMBER(RESULTADOS!E31),L31=0,M31=0,O31=0, C31=E31, RESULTADOS!C31=RESULTADOS!E31, OR(AND(C32>E32, RESULTADOS!C32>RESULTADOS!E32), AND(E32>C32, RESULTADOS!E32>RESULTADOS!C32))), 1, 0) -> 0
B32: =IF(AND(ISNUMBER(C31),ISNUMBER(E31),C31=E31),"Pênaltis","")
B33: =RESULTADOS!B33 -> Suíça | D33: x | F33: =RESULTADOS!F33 -> Argélia | H33: 46206 | I33: 0 | K33: =SUM(L33:R33) -> 0 | L33: =IF(AND(ISNUMBER(C33), ISNUMBER(E33), ISNUMBER(RESULTADOS!C33), ISNUMBER(RESULTADOS!E33), C33=RESULTADOS!C33, E33=RESULTADOS!E33, C33<>E33), 5, 0) -> 0 | M33: =IF( AND(ISNUMBER(C33), ISNUMBER(E33), ISNUMBER(RESULTADOS!C33), ISNUMBER(RESULTADOS!E33), L33=0, OR(AND(C33>E33, RESULTADOS!C33>RESULTADOS!E33), AND(E33>C33, RESULTADOS!E33>RESULTADOS!C33)), OR(C33=RESULTADOS!C33, E33=RESULTADOS!E33) ), 3, 0 ) -> 0 | N33: =IF( AND(ISNUMBER(C33), ISNUMBER(E33), ISNUMBER(RESULTADOS!C33), ISNUMBER(RESULTADOS!E33), L33=0, M33=0, C33<>E33, C33-E33=RESULTADOS!C33-RESULTADOS!E33 ), 2, 0 ) -> 0 | O33: =IF( AND(ISNUMBER(C33), ISNUMBER(E33), ISNUMBER(RESULTADOS!C33), ISNUMBER(RESULTADOS!E33), L33=0, M33=0, N33=0, OR(AND(C33>E33, RESULTADOS!C33>RESULTADOS!E33), AND(E33>C33, RESULTADOS!E33>RESULTADOS!C33)) ), 1, 0 ) -> 0 | P33: =IF(AND(ISNUMBER(C33), ISNUMBER(E33), ISNUMBER(RESULTADOS!C33), ISNUMBER(RESULTADOS!E33), L33=0,M33=0,O33=0, C33=RESULTADOS!C33, E33=RESULTADOS!E33), 4, 0) -> 0 | Q33: =IF(AND(ISNUMBER(C33), ISNUMBER(E33), ISNUMBER(RESULTADOS!C33), ISNUMBER(RESULTADOS!E33), L33=0,M33=0,O33=0, P33=0,C33=E33, RESULTADOS!C33=RESULTADOS!E33), 2, 0) -> 0 | R33: =IF(AND(ISNUMBER(C33), ISNUMBER(E33), ISNUMBER(RESULTADOS!C33), ISNUMBER(RESULTADOS!E33), ISNUMBER(C34), ISNUMBER(E34), ISNUMBER(RESULTADOS!C33), ISNUMBER(RESULTADOS!E33),L33=0,M33=0,O33=0, C33=E33, RESULTADOS!C33=RESULTADOS!E33, OR(AND(C34>E34, RESULTADOS!C34>RESULTADOS!E34), AND(E34>C34, RESULTADOS!E34>RESULTADOS!C34))), 1, 0) -> 0
B34: =IF(AND(ISNUMBER(C33),ISNUMBER(E33),C33=E33),"Pênaltis","")
B35: =RESULTADOS!B35 -> Colômbia | D35: x | F35: =RESULTADOS!F35 -> Gana | H35: 46206 | I35: 0.9375 | K35: =SUM(L35:R35) -> 0 | L35: =IF(AND(ISNUMBER(C35), ISNUMBER(E35), ISNUMBER(RESULTADOS!C35), ISNUMBER(RESULTADOS!E35), C35=RESULTADOS!C35, E35=RESULTADOS!E35, C35<>E35), 5, 0) -> 0 | M35: =IF( AND(ISNUMBER(C35), ISNUMBER(E35), ISNUMBER(RESULTADOS!C35), ISNUMBER(RESULTADOS!E35), L35=0, OR(AND(C35>E35, RESULTADOS!C35>RESULTADOS!E35), AND(E35>C35, RESULTADOS!E35>RESULTADOS!C35)), OR(C35=RESULTADOS!C35, E35=RESULTADOS!E35) ), 3, 0 ) -> 0 | N35: =IF( AND(ISNUMBER(C35), ISNUMBER(E35), ISNUMBER(RESULTADOS!C35), ISNUMBER(RESULTADOS!E35), L35=0, M35=0, C35<>E35, C35-E35=RESULTADOS!C35-RESULTADOS!E35 ), 2, 0 ) -> 0 | O35: =IF( AND(ISNUMBER(C35), ISNUMBER(E35), ISNUMBER(RESULTADOS!C35), ISNUMBER(RESULTADOS!E35), L35=0, M35=0, N35=0, OR(AND(C35>E35, RESULTADOS!C35>RESULTADOS!E35), AND(E35>C35, RESULTADOS!E35>RESULTADOS!C35)) ), 1, 0 ) -> 0 | P35: =IF(AND(ISNUMBER(C35), ISNUMBER(E35), ISNUMBER(RESULTADOS!C35), ISNUMBER(RESULTADOS!E35), L35=0,M35=0,O35=0, C35=RESULTADOS!C35, E35=RESULTADOS!E35), 4, 0) -> 0 | Q35: =IF(AND(ISNUMBER(C35), ISNUMBER(E35), ISNUMBER(RESULTADOS!C35), ISNUMBER(RESULTADOS!E35), L35=0,M35=0,O35=0, P35=0,C35=E35, RESULTADOS!C35=RESULTADOS!E35), 2, 0) -> 0 | R35: =IF(AND(ISNUMBER(C35), ISNUMBER(E35), ISNUMBER(RESULTADOS!C35), ISNUMBER(RESULTADOS!E35), ISNUMBER(C36), ISNUMBER(E36), ISNUMBER(RESULTADOS!C35), ISNUMBER(RESULTADOS!E35),L35=0,M35=0,O35=0, C35=E35, RESULTADOS!C35=RESULTADOS!E35, OR(AND(C36>E36, RESULTADOS!C36>RESULTADOS!E36), AND(E36>C36, RESULTADOS!E36>RESULTADOS!C36))), 1, 0) -> 0
B36: =IF(AND(ISNUMBER(C35),ISNUMBER(E35),C35=E35),"Pênaltis","")
B38: OITAVAS | H38: DIA | I38: HORA
B39: =RESULTADOS!B39 -> Paraguai | D39: x | F39: =RESULTADOS!F39 -> França | H39: 46207 | I39: 0.75 | K39: =SUM(L39:R39) -> 0 | L39: =IF(AND(ISNUMBER(C39), ISNUMBER(E39), ISNUMBER(RESULTADOS!C39), ISNUMBER(RESULTADOS!E39), C39=RESULTADOS!C39, E39=RESULTADOS!E39, C39<>E39), 5, 0) -> 0 | M39: =IF( AND(ISNUMBER(C39), ISNUMBER(E39), ISNUMBER(RESULTADOS!C39), ISNUMBER(RESULTADOS!E39), L39=0, OR(AND(C39>E39, RESULTADOS!C39>RESULTADOS!E39), AND(E39>C39, RESULTADOS!E39>RESULTADOS!C39)), OR(C39=RESULTADOS!C39, E39=RESULTADOS!E39) ), 3, 0 ) -> 0 | N39: =IF( AND(ISNUMBER(C39), ISNUMBER(E39), ISNUMBER(RESULTADOS!C39), ISNUMBER(RESULTADOS!E39), L39=0, M39=0, C39<>E39, C39-E39=RESULTADOS!C39-RESULTADOS!E39 ), 2, 0 ) -> 0 | O39: =IF( AND(ISNUMBER(C39), ISNUMBER(E39), ISNUMBER(RESULTADOS!C39), ISNUMBER(RESULTADOS!E39), L39=0, M39=0, N39=0, OR(AND(C39>E39, RESULTADOS!C39>RESULTADOS!E39), AND(E39>C39, RESULTADOS!E39>RESULTADOS!C39)) ), 1, 0 ) -> 0 | P39: =IF(AND(ISNUMBER(C39), ISNUMBER(E39), ISNUMBER(RESULTADOS!C39), ISNUMBER(RESULTADOS!E39), L39=0,M39=0,O39=0, C39=RESULTADOS!C39, E39=RESULTADOS!E39), 4, 0) -> 0 | Q39: =IF(AND(ISNUMBER(C39), ISNUMBER(E39), ISNUMBER(RESULTADOS!C39), ISNUMBER(RESULTADOS!E39), L39=0,M39=0,O39=0, P39=0,C39=E39, RESULTADOS!C39=RESULTADOS!E39), 2, 0) -> 0 | R39: =IF(AND(ISNUMBER(C39), ISNUMBER(E39), ISNUMBER(RESULTADOS!C39), ISNUMBER(RESULTADOS!E39), ISNUMBER(C40), ISNUMBER(E40), ISNUMBER(RESULTADOS!C39), ISNUMBER(RESULTADOS!E39),L39=0,M39=0,O39=0, C39=E39, RESULTADOS!C39=RESULTADOS!E39, OR(AND(C40>E40, RESULTADOS!C40>RESULTADOS!E40), AND(E40>C40, RESULTADOS!E40>RESULTADOS!C40))), 1, 0) -> 0
B40: =IF(AND(ISNUMBER(C39),ISNUMBER(E39),C39=E39),"Pênaltis","")
B41: =RESULTADOS!B41 -> Canadá | D41: x | F41: =RESULTADOS!F41 -> Marrocos | H41: 46207 | I41: 0.58333333 | K41: =SUM(L41:R41) -> 0 | L41: =IF(AND(ISNUMBER(C41), ISNUMBER(E41), ISNUMBER(RESULTADOS!C41), ISNUMBER(RESULTADOS!E41), C41=RESULTADOS!C41, E41=RESULTADOS!E41, C41<>E41), 5, 0) -> 0 | M41: =IF( AND(ISNUMBER(C41), ISNUMBER(E41), ISNUMBER(RESULTADOS!C41), ISNUMBER(RESULTADOS!E41), L41=0, OR(AND(C41>E41, RESULTADOS!C41>RESULTADOS!E41), AND(E41>C41, RESULTADOS!E41>RESULTADOS!C41)), OR(C41=RESULTADOS!C41, E41=RESULTADOS!E41) ), 3, 0 ) -> 0 | N41: =IF( AND(ISNUMBER(C41), ISNUMBER(E41), ISNUMBER(RESULTADOS!C41), ISNUMBER(RESULTADOS!E41), L41=0, M41=0, C41<>E41, C41-E41=RESULTADOS!C41-RESULTADOS!E41 ), 2, 0 ) -> 0 | O41: =IF( AND(ISNUMBER(C41), ISNUMBER(E41), ISNUMBER(RESULTADOS!C41), ISNUMBER(RESULTADOS!E41), L41=0, M41=0, N41=0, OR(AND(C41>E41, RESULTADOS!C41>RESULTADOS!E41), AND(E41>C41, RESULTADOS!E41>RESULTADOS!C41)) ), 1, 0 ) -> 0 | P41: =IF(AND(ISNUMBER(C41), ISNUMBER(E41), ISNUMBER(RESULTADOS!C41), ISNUMBER(RESULTADOS!E41), L41=0,M41=0,O41=0, C41=RESULTADOS!C41, E41=RESULTADOS!E41), 4, 0) -> 0 | Q41: =IF(AND(ISNUMBER(C41), ISNUMBER(E41), ISNUMBER(RESULTADOS!C41), ISNUMBER(RESULTADOS!E41), L41=0,M41=0,O41=0, P41=0,C41=E41, RESULTADOS!C41=RESULTADOS!E41), 2, 0) -> 0 | R41: =IF(AND(ISNUMBER(C41), ISNUMBER(E41), ISNUMBER(RESULTADOS!C41), ISNUMBER(RESULTADOS!E41), ISNUMBER(C42), ISNUMBER(E42), ISNUMBER(RESULTADOS!C41), ISNUMBER(RESULTADOS!E41),L41=0,M41=0,O41=0, C41=E41, RESULTADOS!C41=RESULTADOS!E41, OR(AND(C42>E42, RESULTADOS!C42>RESULTADOS!E42), AND(E42>C42, RESULTADOS!E42>RESULTADOS!C42))), 1, 0) -> 0
B42: =IF(AND(ISNUMBER(C41),ISNUMBER(E41),C41=E41),"Pênaltis","")
B43: =RESULTADOS!B43 -> Portugal | D43: x | F43: =RESULTADOS!F43 -> Espanha | H43: 46209 | I43: 0.66666667 | K43: =SUM(L43:R43) -> 0 | L43: =IF(AND(ISNUMBER(C43), ISNUMBER(E43), ISNUMBER(RESULTADOS!C43), ISNUMBER(RESULTADOS!E43), C43=RESULTADOS!C43, E43=RESULTADOS!E43, C43<>E43), 5, 0) -> 0 | M43: =IF( AND(ISNUMBER(C43), ISNUMBER(E43), ISNUMBER(RESULTADOS!C43), ISNUMBER(RESULTADOS!E43), L43=0, OR(AND(C43>E43, RESULTADOS!C43>RESULTADOS!E43), AND(E43>C43, RESULTADOS!E43>RESULTADOS!C43)), OR(C43=RESULTADOS!C43, E43=RESULTADOS!E43) ), 3, 0 ) -> 0 | N43: =IF( AND(ISNUMBER(C43), ISNUMBER(E43), ISNUMBER(RESULTADOS!C43), ISNUMBER(RESULTADOS!E43), L43=0, M43=0, C43<>E43, C43-E43=RESULTADOS!C43-RESULTADOS!E43 ), 2, 0 ) -> 0 | O43: =IF( AND(ISNUMBER(C43), ISNUMBER(E43), ISNUMBER(RESULTADOS!C43), ISNUMBER(RESULTADOS!E43), L43=0, M43=0, N43=0, OR(AND(C43>E43, RESULTADOS!C43>RESULTADOS!E43), AND(E43>C43, RESULTADOS!E43>RESULTADOS!C43)) ), 1, 0 ) -> 0 | P43: =IF(AND(ISNUMBER(C43), ISNUMBER(E43), ISNUMBER(RESULTADOS!C43), ISNUMBER(RESULTADOS!E43), L43=0,M43=0,O43=0, C43=RESULTADOS!C43, E43=RESULTADOS!E43), 4, 0) -> 0 | Q43: =IF(AND(ISNUMBER(C43), ISNUMBER(E43), ISNUMBER(RESULTADOS!C43), ISNUMBER(RESULTADOS!E43), L43=0,M43=0,O43=0, P43=0,C43=E43, RESULTADOS!C43=RESULTADOS!E43), 2, 0) -> 0 | R43: =IF(AND(ISNUMBER(C43), ISNUMBER(E43), ISNUMBER(RESULTADOS!C43), ISNUMBER(RESULTADOS!E43), ISNUMBER(C44), ISNUMBER(E44), ISNUMBER(RESULTADOS!C43), ISNUMBER(RESULTADOS!E43),L43=0,M43=0,O43=0, C43=E43, RESULTADOS!C43=RESULTADOS!E43, OR(AND(C44>E44, RESULTADOS!C44>RESULTADOS!E44), AND(E44>C44, RESULTADOS!E44>RESULTADOS!C44))), 1, 0) -> 0
...

Sheet RESULTADOS
B2: SEU NOME AQUI | H2: DATA
B4: DEZESSEIS AVOS | H4: DIA | I4: HORA
B5: Alemanha | C5: 1 | D5: x | E5: 1 | F5: Paraguai | H5: 46202 | I5: 0.72916667
B6: =IF(AND(ISNUMBER(C5),ISNUMBER(E5),C5=E5),"Pênaltis","") -> Pênaltis | C6: 0 | E6: 1
B7: França | C7: 3 | D7: x | E7: 0 | F7: Suécia | H7: 46203 | I7: 0.75
B8: =IF(AND(ISNUMBER(C7),ISNUMBER(E7),C7=E7),"Pênaltis","")
B9: África do Sul | C9: 0 | D9: x | E9: 1 | F9: Canadá | H9: 46201 | I9: 0.66666667
B10: =IF(AND(ISNUMBER(C9),ISNUMBER(E9),C9=E9),"Pênaltis","")
B11: Holanda | C11: 1 | D11: x | E11: 1 | F11: Marrocos | H11: 46202 | I11: 0.91666667
B12: =IF(AND(ISNUMBER(C11),ISNUMBER(E11),C11=E11),"Pênaltis","") -> Pênaltis | C12: 0 | E12: 1
B13: Portugal | C13: 2 | D13: x | E13: 1 | F13: Croácia | H13: 46205 | I13: 0.83333333
B14: =IF(AND(ISNUMBER(C13),ISNUMBER(E13),C13=E13),"Pênaltis","")
B15: Espanha | C15: 3 | D15: x | E15: 0 | F15: Áustria | H15: 46205 | I15: 0.66666667
B16: =IF(AND(ISNUMBER(C15),ISNUMBER(E15),C15=E15),"Pênaltis","")
B17: Estados Unidos | C17: 2 | D17: x | E17: 0 | F17: Bósnia | H17: 46204 | I17: 0.875
B18: =IF(AND(ISNUMBER(C17),ISNUMBER(E17),C17=E17),"Pênaltis","")
B19: Bélgica | C19: 3 | D19: x | E19: 2 | F19: Senegal | H19: 46204 | I19: 0.70833333
B20: =IF(AND(ISNUMBER(C19),ISNUMBER(E19),C19=E19),"Pênaltis","")
B21: Brasil | C21: 2 | D21: x | E21: 1 | F21: Japão | H21: 46202 | I21: 0.58333333
B22: =IF(AND(ISNUMBER(C21),ISNUMBER(E21),C21=E21),"Pênaltis","")
B23: Costa do Marfim | C23: 1 | D23: x | E23: 2 | F23: Noruega | H23: 46203 | I23: 0.58333333
B24: =IF(AND(ISNUMBER(C23),ISNUMBER(E23),C23=E23),"Pênaltis","")
B25: México | C25: 2 | D25: x | E25: 0 | F25: Equador | H25: 46203 | I25: 0.91666667
B26: =IF(AND(ISNUMBER(C25),ISNUMBER(E25),C25=E25),"Pênaltis","")
B27: Inglaterra | C27: 2 | D27: x | E27: 1 | F27: RD Congo | H27: 46204 | I27: 0.54166667
B28: =IF(AND(ISNUMBER(C27),ISNUMBER(E27),C27=E27),"Pênaltis","")
B29: Argentina | C29: 3 | D29: x | E29: 2 | F29: Cabo Verde | H29: 46206 | I29: 0.79166667
B30: =IF(AND(ISNUMBER(C29),ISNUMBER(E29),C29=E29),"Pênaltis","")
B31: Austrália | C31: 1 | D31: x | E31: 1 | F31: Egito | H31: 46206 | I31: 0.625
B32: =IF(AND(ISNUMBER(C31),ISNUMBER(E31),C31=E31),"Pênaltis","") -> Pênaltis | C32: 0 | E32: 1
B33: Suíça | C33: 2 | D33: x | E33: 0 | F33: Argélia | H33: 46206 | I33: 0
B34: =IF(AND(ISNUMBER(C33),ISNUMBER(E33),C33=E33),"Pênaltis","")
B35: Colômbia | C35: 1 | D35: x | E35: 0 | F35: Gana | H35: 46206 | I35: 0.9375
B36: =IF(AND(ISNUMBER(C35),ISNUMBER(E35),C35=E35),"Pênaltis","")
B38: OITAVAS | H38: DIA | I38: HORA
B39: =IF(AND(ISNUMBER(C5), ISNUMBER(E5)), IF(OR(C5>E5, E5>C5), IF(C5>E5, B5, F5), IF(AND(ISNUMBER(C6), ISNUMBER(E6)), IF(C6>E6, B5, F5), "xxx")), "xxx") -> Paraguai | C39: 0 | D39: x | E39: 1 | F39: =IF(AND(ISNUMBER(C7), ISNUMBER(E7)), IF(OR(C7>E7, E7>C7), IF(C7>E7, B7, F7), IF(AND(ISNUMBER(C8), ISNUMBER(E8)), IF(C8>E8, B7, F7), "xxx")), "xxx") -> França | H39: 46207 | I39: 0.75
B40: =IF(AND(ISNUMBER(C39),ISNUMBER(E39),C39=E39),"Pênaltis","")
B41: =IF(AND(ISNUMBER(C9), ISNUMBER(E9)), IF(OR(C9>E9, E9>C9), IF(C9>E9, B9, F9), IF(AND(ISNUMBER(C10), ISNUMBER(E10)), IF(C10>E10, B9, F9), "xxx")), "xxx") -> Canadá | C41: 0 | D41: x | E41: 3 | F41: =IF(AND(ISNUMBER(C11), ISNUMBER(E11)), IF(OR(C11>E11, E11>C11), IF(C11>E11, B11, F11), IF(AND(ISNUMBER(C12), ISNUMBER(E12)), IF(C12>E12, B11, F11), "xxx")), "xxx") -> Marrocos | H41: 46207 | I41: 0.58333333
B42: =IF(AND(ISNUMBER(C41),ISNUMBER(E41),C41=E41),"Pênaltis","")
B43: =IF(AND(ISNUMBER(C13), ISNUMBER(E13)), IF(OR(C13>E13, E13>C13), IF(C13>E13, B13, F13), IF(AND(ISNUMBER(C14), ISNUMBER(E14)), IF(C14>E14, B13, F13), "xxx")), "xxx") -> Portugal | C43: 0 | D43: x | E43: 1 | F43: =IF(AND(ISNUMBER(C15), ISNUMBER(E15)), IF(OR(C15>E15, E15>C15), IF(C15>E15, B15, F15), IF(AND(ISNUMBER(C16), ISNUMBER(E16)), IF(C16>E16, B15, F15), "xxx")), "xxx") -> Espanha | H43: 46209 | I43: 0.66666667
...

Sheet Daniel
B2: DANIEL | H2: DATA | K2: PONTUAÇÃO | L2: =SUM(K:K) -> 74
B4: DEZESSEIS AVOS | H4: DIA | I4: HORA | K4: total | L4: cravou | M4: venc + 1 gol | N4: venc + saldo | O4: venc | P4: cravou empate | Q4: empate | R4: quem passou | T4: odds esq | U4: odds emp | V4: odds dir | X4: pesq | Y4: pemp | Z4: pdir
B5: =RESULTADOS!B5 -> Alemanha | C5: 3 | D5: x | E5: 1 | F5: =RESULTADOS!F5 -> Paraguai | H5: 46202 | I5: 0.72916667 | K5: =SUM(L5:R5) -> 0 | L5: =IF(AND(ISNUMBER(C5), ISNUMBER(E5), ISNUMBER(RESULTADOS!C5), ISNUMBER(RESULTADOS!E5), C5=RESULTADOS!C5, E5=RESULTADOS!E5, C5<>E5), 5, 0) -> 0 | M5: =IF( AND(ISNUMBER(C5), ISNUMBER(E5), ISNUMBER(RESULTADOS!C5), ISNUMBER(RESULTADOS!E5), L5=0, OR(AND(C5>E5, RESULTADOS!C5>RESULTADOS!E5), AND(E5>C5, RESULTADOS!E5>RESULTADOS!C5)), OR(C5=RESULTADOS!C5, E5=RESULTADOS!E5) ), 3, 0 ) -> 0 | N5: =IF( AND(ISNUMBER(C5), ISNUMBER(E5), ISNUMBER(RESULTADOS!C5), ISNUMBER(RESULTADOS!E5), L5=0, M5=0, C5<>E5, C5-E5=RESULTADOS!C5-RESULTADOS!E5 ), 2, 0 ) -> 0 | O5: =IF( AND(ISNUMBER(C5), ISNUMBER(E5), ISNUMBER(RESULTADOS!C5), ISNUMBER(RESULTADOS!E5), L5=0, M5=0, N5=0, OR(AND(C5>E5, RESULTADOS!C5>RESULTADOS!E5), AND(E5>C5, RESULTADOS!E5>RESULTADOS!C5)) ), 1, 0 ) -> 0 | P5: =IF(AND(ISNUMBER(C5), ISNUMBER(E5), ISNUMBER(RESULTADOS!C5), ISNUMBER(RESULTADOS!E5), L5=0,M5=0,O5=0, C5=RESULTADOS!C5, E5=RESULTADOS!E5), 4, 0) -> 0 | Q5: =IF(AND(ISNUMBER(C5), ISNUMBER(E5), ISNUMBER(RESULTADOS!C5), ISNUMBER(RESULTADOS!E5), L5=0,M5=0,O5=0, P5=0,C5=E5, RESULTADOS!C5=RESULTADOS!E5), 2, 0) -> 0 | R5: =IF(AND(ISNUMBER(C5), ISNUMBER(E5), ISNUMBER(RESULTADOS!C5), ISNUMBER(RESULTADOS!E5), ISNUMBER(C6), ISNUMBER(E6), ISNUMBER(RESULTADOS!C5), ISNUMBER(RESULTADOS!E5),L5=0,M5=0,O5=0, C5=E5, RESULTADOS!C5=RESULTADOS!E5, OR(AND(C6>E6, RESULTADOS!C6>RESULTADOS!E6), AND(E6>C6, RESULTADOS!E6>RESULTADOS!C6))), 1, 0) -> 0 | T5: 1.38 | U5: 4.94 | V5: 8.13 | X5: =1/T5 -> 0.72463768 | Y5: =1/U5 -> 0.20242915 | Z5: =1/V5 -> 0.12300123
B6: =IF(AND(ISNUMBER(C5),ISNUMBER(E5),C5=E5),"Pênaltis","")
B7: =RESULTADOS!B7 -> França | C7: 3 | D7: x | E7: 1 | F7: =RESULTADOS!F7 -> Suécia | H7: 46203 | I7: 0.75 | K7: =SUM(L7:R7) -> 3 | L7: =IF(AND(ISNUMBER(C7), ISNUMBER(E7), ISNUMBER(RESULTADOS!C7), ISNUMBER(RESULTADOS!E7), C7=RESULTADOS!C7, E7=RESULTADOS!E7, C7<>E7), 5, 0) -> 0 | M7: =IF( AND(ISNUMBER(C7), ISNUMBER(E7), ISNUMBER(RESULTADOS!C7), ISNUMBER(RESULTADOS!E7), L7=0, OR(AND(C7>E7, RESULTADOS!C7>RESULTADOS!E7), AND(E7>C7, RESULTADOS!E7>RESULTADOS!C7)), OR(C7=RESULTADOS!C7, E7=RESULTADOS!E7) ), 3, 0 ) -> 3 | N7: =IF( AND(ISNUMBER(C7), ISNUMBER(E7), ISNUMBER(RESULTADOS!C7), ISNUMBER(RESULTADOS!E7), L7=0, M7=0, C7<>E7, C7-E7=RESULTADOS!C7-RESULTADOS!E7 ), 2, 0 ) -> 0 | O7: =IF( AND(ISNUMBER(C7), ISNUMBER(E7), ISNUMBER(RESULTADOS!C7), ISNUMBER(RESULTADOS!E7), L7=0, M7=0, N7=0, OR(AND(C7>E7, RESULTADOS!C7>RESULTADOS!E7), AND(E7>C7, RESULTADOS!E7>RESULTADOS!C7)) ), 1, 0 ) -> 0 | P7: =IF(AND(ISNUMBER(C7), ISNUMBER(E7), ISNUMBER(RESULTADOS!C7), ISNUMBER(RESULTADOS!E7), L7=0,M7=0,O7=0, C7=RESULTADOS!C7, E7=RESULTADOS!E7), 4, 0) -> 0 | Q7: =IF(AND(ISNUMBER(C7), ISNUMBER(E7), ISNUMBER(RESULTADOS!C7), ISNUMBER(RESULTADOS!E7), L7=0,M7=0,O7=0, P7=0,C7=E7, RESULTADOS!C7=RESULTADOS!E7), 2, 0) -> 0 | R7: =IF(AND(ISNUMBER(C7), ISNUMBER(E7), ISNUMBER(RESULTADOS!C7), ISNUMBER(RESULTADOS!E7), ISNUMBER(C8), ISNUMBER(E8), ISNUMBER(RESULTADOS!C7), ISNUMBER(RESULTADOS!E7),L7=0,M7=0,O7=0, C7=E7, RESULTADOS!C7=RESULTADOS!E7, OR(AND(C8>E8, RESULTADOS!C8>RESULTADOS!E8), AND(E8>C8, RESULTADOS!E8>RESULTADOS!C8))), 1, 0) -> 0 | T7: 1.3 | U7: 5.6 | V7: 10.12 | X7: =1/T7 -> 0.76923077 | Y7: =1/U7 -> 0.17857143 | Z7: =1/V7 -> 0.098814229
B8: =IF(AND(ISNUMBER(C7),ISNUMBER(E7),C7=E7),"Pênaltis","")
B9: =RESULTADOS!B9 -> África do Sul | C9: 1 | D9: x | E9: 2 | F9: =RESULTADOS!F9 -> Canadá | H9: 46201 | I9: 0.66666667 | K9: =SUM(L9:R9) -> 2 | L9: =IF(AND(ISNUMBER(C9), ISNUMBER(E9), ISNUMBER(RESULTADOS!C9), ISNUMBER(RESULTADOS!E9), C9=RESULTADOS!C9, E9=RESULTADOS!E9, C9<>E9), 5, 0) -> 0 | M9: =IF( AND(ISNUMBER(C9), ISNUMBER(E9), ISNUMBER(RESULTADOS!C9), ISNUMBER(RESULTADOS!E9), L9=0, OR(AND(C9>E9, RESULTADOS!C9>RESULTADOS!E9), AND(E9>C9, RESULTADOS!E9>RESULTADOS!C9)), OR(C9=RESULTADOS!C9, E9=RESULTADOS!E9) ), 3, 0 ) -> 0 | N9: =IF( AND(ISNUMBER(C9), ISNUMBER(E9), ISNUMBER(RESULTADOS!C9), ISNUMBER(RESULTADOS!E9), L9=0, M9=0, C9<>E9, C9-E9=RESULTADOS!C9-RESULTADOS!E9 ), 2, 0 ) -> 2 | O9: =IF( AND(ISNUMBER(C9), ISNUMBER(E9), ISNUMBER(RESULTADOS!C9), ISNUMBER(RESULTADOS!E9), L9=0, M9=0, N9=0, OR(AND(C9>E9, RESULTADOS!C9>RESULTADOS!E9), AND(E9>C9, RESULTADOS!E9>RESULTADOS!C9)) ), 1, 0 ) -> 0 | P9: =IF(AND(ISNUMBER(C9), ISNUMBER(E9), ISNUMBER(RESULTADOS!C9), ISNUMBER(RESULTADOS!E9), L9=0,M9=0,O9=0, C9=RESULTADOS!C9, E9=RESULTADOS!E9), 4, 0) -> 0 | Q9: =IF(AND(ISNUMBER(C9), ISNUMBER(E9), ISNUMBER(RESULTADOS!C9), ISNUMBER(RESULTADOS!E9), L9=0,M9=0,O9=0, P9=0,C9=E9, RESULTADOS!C9=RESULTADOS!E9), 2, 0) -> 0 | R9: =IF(AND(ISNUMBER(C9), ISNUMBER(E9), ISNUMBER(RESULTADOS!C9), ISNUMBER(RESULTADOS!E9), ISNUMBER(C10), ISNUMBER(E10), ISNUMBER(RESULTADOS!C9), ISNUMBER(RESULTADOS!E9),L9=0,M9=0,O9=0, C9=E9, RESULTADOS!C9=RESULTADOS!E9, OR(AND(C10>E10, RESULTADOS!C10>RESULTADOS!E10), AND(E10>C10, RESULTADOS!E10>RESULTADOS!C10))), 1, 0) -> 0 | T9: 5.36 | U9: 3.59 | V9: 1.72 | X9: =1/T9 -> 0.18656716 | Y9: =1/U9 -> 0.27855153 | Z9: =1/V9 -> 0.58139535
B10: =IF(AND(ISNUMBER(C9),ISNUMBER(E9),C9=E9),"Pênaltis","")
B11: =RESULTADOS!B11 -> Holanda | C11: 2 | D11: x | E11: 1 | F11: =RESULTADOS!F11 -> Marrocos | H11: 46202 | I11: 0.91666667 | K11: =SUM(L11:R11) -> 0 | L11: =IF(AND(ISNUMBER(C11), ISNUMBER(E11), ISNUMBER(RESULTADOS!C11), ISNUMBER(RESULTADOS!E11), C11=RESULTADOS!C11, E11=RESULTADOS!E11, C11<>E11), 5, 0) -> 0 | M11: =IF( AND(ISNUMBER(C11), ISNUMBER(E11), ISNUMBER(RESULTADOS!C11), ISNUMBER(RESULTADOS!E11), L11=0, OR(AND(C11>E11, RESULTADOS!C11>RESULTADOS!E11), AND(E11>C11, RESULTADOS!E11>RESULTADOS!C11)), OR(C11=RESULTADOS!C11, E11=RESULTADOS!E11) ), 3, 0 ) -> 0 | N11: =IF( AND(ISNUMBER(C11), ISNUMBER(E11), ISNUMBER(RESULTADOS!C11), ISNUMBER(RESULTADOS!E11), L11=0, M11=0, C11<>E11, C11-E11=RESULTADOS!C11-RESULTADOS!E11 ), 2, 0 ) -> 0 | O11: =IF( AND(ISNUMBER(C11), ISNUMBER(E11), ISNUMBER(RESULTADOS!C11), ISNUMBER(RESULTADOS!E11), L11=0, M11=0, N11=0, OR(AND(C11>E11, RESULTADOS!C11>RESULTADOS!E11), AND(E11>C11, RESULTADOS!E11>RESULTADOS!C11)) ), 1, 0 ) -> 0 | P11: =IF(AND(ISNUMBER(C11), ISNUMBER(E11), ISNUMBER(RESULTADOS!C11), ISNUMBER(RESULTADOS!E11), L11=0,M11=0,O11=0, C11=RESULTADOS!C11, E11=RESULTADOS!E11), 4, 0) -> 0 | Q11: =IF(AND(ISNUMBER(C11), ISNUMBER(E11), ISNUMBER(RESULTADOS!C11), ISNUMBER(RESULTADOS!E11), L11=0,M11=0,O11=0, P11=0,C11=E11, RESULTADOS!C11=RESULTADOS!E11), 2, 0) -> 0 | R11: =IF(AND(ISNUMBER(C11), ISNUMBER(E11), ISNUMBER(RESULTADOS!C11), ISNUMBER(RESULTADOS!E11), ISNUMBER(C12), ISNUMBER(E12), ISNUMBER(RESULTADOS!C11), ISNUMBER(RESULTADOS!E11),L11=0,M11=0,O11=0, C11=E11, RESULTADOS!C11=RESULTADOS!E11, OR(AND(C12>E12, RESULTADOS!C12>RESULTADOS!E12), AND(E12>C12, RESULTADOS!E12>RESULTADOS!C12))), 1, 0) -> 0 | T11: 2.13 | U11: 3.23 | V11: 3.76 | X11: =1/T11 -> 0.46948357 | Y11: =1/U11 -> 0.30959752 | Z11: =1/V11 -> 0.26595745
B12: =IF(AND(ISNUMBER(C11),ISNUMBER(E11),C11=E11),"Pênaltis","")
B13: =RESULTADOS!B13 -> Portugal | C13: 2 | D13: x | E13: 1 | F13: =RESULTADOS!F13 -> Croácia | H13: 46205 | I13: 0.83333333 | K13: =SUM(L13:R13) -> 5 | L13: =IF(AND(ISNUMBER(C13), ISNUMBER(E13), ISNUMBER(RESULTADOS!C13), ISNUMBER(RESULTADOS!E13), C13=RESULTADOS!C13, E13=RESULTADOS!E13, C13<>E13), 5, 0) -> 5 | M13: =IF( AND(ISNUMBER(C13), ISNUMBER(E13), ISNUMBER(RESULTADOS!C13), ISNUMBER(RESULTADOS!E13), L13=0, OR(AND(C13>E13, RESULTADOS!C13>RESULTADOS!E13), AND(E13>C13, RESULTADOS!E13>RESULTADOS!C13)), OR(C13=RESULTADOS!C13, E13=RESULTADOS!E13) ), 3, 0 ) -> 0 | N13: =IF( AND(ISNUMBER(C13), ISNUMBER(E13), ISNUMBER(RESULTADOS!C13), ISNUMBER(RESULTADOS!E13), L13=0, M13=0, C13<>E13, C13-E13=RESULTADOS!C13-RESULTADOS!E13 ), 2, 0 ) -> 0 | O13: =IF( AND(ISNUMBER(C13), ISNUMBER(E13), ISNUMBER(RESULTADOS!C13), ISNUMBER(RESULTADOS!E13), L13=0, M13=0, N13=0, OR(AND(C13>E13, RESULTADOS!C13>RESULTADOS!E13), AND(E13>C13, RESULTADOS!E13>RESULTADOS!C13)) ), 1, 0 ) -> 0 | P13: =IF(AND(ISNUMBER(C13), ISNUMBER(E13), ISNUMBER(RESULTADOS!C13), ISNUMBER(RESULTADOS!E13), L13=0,M13=0,O13=0, C13=RESULTADOS!C13, E13=RESULTADOS!E13), 4, 0) -> 0 | Q13: =IF(AND(ISNUMBER(C13), ISNUMBER(E13), ISNUMBER(RESULTADOS!C13), ISNUMBER(RESULTADOS!E13), L13=0,M13=0,O13=0, P13=0,C13=E13, RESULTADOS!C13=RESULTADOS!E13), 2, 0) -> 0 | R13: =IF(AND(ISNUMBER(C13), ISNUMBER(E13), ISNUMBER(RESULTADOS!C13), ISNUMBER(RESULTADOS!E13), ISNUMBER(C14), ISNUMBER(E14), ISNUMBER(RESULTADOS!C13), ISNUMBER(RESULTADOS!E13),L13=0,M13=0,O13=0, C13=E13, RESULTADOS!C13=RESULTADOS!E13, OR(AND(C14>E14, RESULTADOS!C14>RESULTADOS!E14), AND(E14>C14, RESULTADOS!E14>RESULTADOS!C14))), 1, 0) -> 0 | T13: 1.81 | U13: 3.52 | V13: 4.81 | X13: =1/T13 -> 0.55248619 | Y13: =1/U13 -> 0.28409091 | Z13: =1/V13 -> 0.20790021
B14: =IF(AND(ISNUMBER(C13),ISNUMBER(E13),C13=E13),"Pênaltis","")
B15: =RESULTADOS!B15 -> Espanha | C15: 2 | D15: x | E15: 0 | F15: =RESULTADOS!F15 -> Áustria | H15: 46205 | I15: 0.66666667 | K15: =SUM(L15:R15) -> 3 | L15: =IF(AND(ISNUMBER(C15), ISNUMBER(E15), ISNUMBER(RESULTADOS!C15), ISNUMBER(RESULTADOS!E15), C15=RESULTADOS!C15, E15=RESULTADOS!E15, C15<>E15), 5, 0) -> 0 | M15: =IF( AND(ISNUMBER(C15), ISNUMBER(E15), ISNUMBER(RESULTADOS!C15), ISNUMBER(RESULTADOS!E15), L15=0, OR(AND(C15>E15, RESULTADOS!C15>RESULTADOS!E15), AND(E15>C15, RESULTADOS!E15>RESULTADOS!C15)), OR(C15=RESULTADOS!C15, E15=RESULTADOS!E15) ), 3, 0 ) -> 3 | N15: =IF( AND(ISNUMBER(C15), ISNUMBER(E15), ISNUMBER(RESULTADOS!C15), ISNUMBER(RESULTADOS!E15), L15=0, M15=0, C15<>E15, C15-E15=RESULTADOS!C15-RESULTADOS!E15 ), 2, 0 ) -> 0 | O15: =IF( AND(ISNUMBER(C15), ISNUMBER(E15), ISNUMBER(RESULTADOS!C15), ISNUMBER(RESULTADOS!E15), L15=0, M15=0, N15=0, OR(AND(C15>E15, RESULTADOS!C15>RESULTADOS!E15), AND(E15>C15, RESULTADOS!E15>RESULTADOS!C15)) ), 1, 0 ) -> 0 | P15: =IF(AND(ISNUMBER(C15), ISNUMBER(E15), ISNUMBER(RESULTADOS!C15), ISNUMBER(RESULTADOS!E15), L15=0,M15=0,O15=0, C15=RESULTADOS!C15, E15=RESULTADOS!E15), 4, 0) -> 0 | Q15: =IF(AND(ISNUMBER(C15), ISNUMBER(E15), ISNUMBER(RESULTADOS!C15), ISNUMBER(RESULTADOS!E15), L15=0,M15=0,O15=0, P15=0,C15=E15, RESULTADOS!C15=RESULTADOS!E15), 2, 0) -> 0 | R15: =IF(AND(ISNUMBER(C15), ISNUMBER(E15), ISNUMBER(RESULTADOS!C15), ISNUMBER(RESULTADOS!E15), ISNUMBER(C16), ISNUMBER(E16), ISNUMBER(RESULTADOS!C15), ISNUMBER(RESULTADOS!E15),L15=0,M15=0,O15=0, C15=E15, RESULTADOS!C15=RESULTADOS!E15, OR(AND(C16>E16, RESULTADOS!C16>RESULTADOS!E16), AND(E16>C16, RESULTADOS!E16>RESULTADOS!C16))), 1, 0) -> 0 | T15: 1.31 | U15: 5.26 | V15: 10.61 | X15: =1/T15 -> 0.76335878 | Y15: =1/U15 -> 0.19011407 | Z15: =1/V15 -> 0.094250707
B16: =IF(AND(ISNUMBER(C15),ISNUMBER(E15),C15=E15),"Pênaltis","")
B17: =RESULTADOS!B17 -> Estados Unidos | C17: 2 | D17: x | E17: 0 | F17: =RESULTADOS!F17 -> Bósnia | H17: 46204 | I17: 0.875 | K17: =SUM(L17:R17) -> 5 | L17: =IF(AND(ISNUMBER(C17), ISNUMBER(E17), ISNUMBER(RESULTADOS!C17), ISNUMBER(RESULTADOS!E17), C17=RESULTADOS!C17, E17=RESULTADOS!E17, C17<>E17), 5, 0) -> 5 | M17: =IF( AND(ISNUMBER(C17), ISNUMBER(E17), ISNUMBER(RESULTADOS!C17), ISNUMBER(RESULTADOS!E17), L17=0, OR(AND(C17>E17, RESULTADOS!C17>RESULTADOS!E17), AND(E17>C17, RESULTADOS!E17>RESULTADOS!C17)), OR(C17=RESULTADOS!C17, E17=RESULTADOS!E17) ), 3, 0 ) -> 0 | N17: =IF( AND(ISNUMBER(C17), ISNUMBER(E17), ISNUMBER(RESULTADOS!C17), ISNUMBER(RESULTADOS!E17), L17=0, M17=0, C17<>E17, C17-E17=RESULTADOS!C17-RESULTADOS!E17 ), 2, 0 ) -> 0 | O17: =IF( AND(ISNUMBER(C17), ISNUMBER(E17), ISNUMBER(RESULTADOS!C17), ISNUMBER(RESULTADOS!E17), L17=0, M17=0, N17=0, OR(AND(C17>E17, RESULTADOS!C17>RESULTADOS!E17), AND(E17>C17, RESULTADOS!E17>RESULTADOS!C17)) ), 1, 0 ) -> 0 | P17: =IF(AND(ISNUMBER(C17), ISNUMBER(E17), ISNUMBER(RESULTADOS!C17), ISNUMBER(RESULTADOS!E17), L17=0,M17=0,O17=0, C17=RESULTADOS!C17, E17=RESULTADOS!E17), 4, 0) -> 0 | Q17: =IF(AND(ISNUMBER(C17), ISNUMBER(E17), ISNUMBER(RESULTADOS!C17), ISNUMBER(RESULTADOS!E17), L17=0,M17=0,O17=0, P17=0,C17=E17, RESULTADOS!C17=RESULTADOS!E17), 2, 0) -> 0 | R17: =IF(AND(ISNUMBER(C17), ISNUMBER(E17), ISNUMBER(RESULTADOS!C17), ISNUMBER(RESULTADOS!E17), ISNUMBER(C18), ISNUMBER(E18), ISNUMBER(RESULTADOS!C17), ISNUMBER(RESULTADOS!E17),L17=0,M17=0,O17=0, C17=E17, RESULTADOS!C17=RESULTADOS!E17, OR(AND(C18>E18, RESULTADOS!C18>RESULTADOS!E18), AND(E18>C18, RESULTADOS!E18>RESULTADOS!C18))), 1, 0) -> 0 | T17: 1.4 | U17: 4.75 | V17: 8.41 | X17: =1/T17 -> 0.71428571 | Y17: =1/U17 -> 0.21052632 | Z17: =1/V17 -> 0.11890606
B18: =IF(AND(ISNUMBER(C17),ISNUMBER(E17),C17=E17),"Pênaltis","")
B19: =RESULTADOS!B19 -> Bélgica | C19: 2 | D19: x | E19: 1 | F19: =RESULTADOS!F19 -> Senegal | H19: 46204 | I19: 0.70833333 | K19: =SUM(L19:R19) -> 2 | L19: =IF(AND(ISNUMBER(C19), ISNUMBER(E19), ISNUMBER(RESULTADOS!C19), ISNUMBER(RESULTADOS!E19), C19=RESULTADOS!C19, E19=RESULTADOS!E19, C19<>E19), 5, 0) -> 0 | M19: =IF( AND(ISNUMBER(C19), ISNUMBER(E19), ISNUMBER(RESULTADOS!C19), ISNUMBER(RESULTADOS!E19), L19=0, OR(AND(C19>E19, RESULTADOS!C19>RESULTADOS!E19), AND(E19>C19, RESULTADOS!E19>RESULTADOS!C19)), OR(C19=RESULTADOS!C19, E19=RESULTADOS!E19) ), 3, 0 ) -> 0 | N19: =IF( AND(ISNUMBER(C19), ISNUMBER(E19), ISNUMBER(RESULTADOS!C19), ISNUMBER(RESULTADOS!E19), L19=0, M19=0, C19<>E19, C19-E19=RESULTADOS!C19-RESULTADOS!E19 ), 2, 0 ) -> 2 | O19: =IF( AND(ISNUMBER(C19), ISNUMBER(E19), ISNUMBER(RESULTADOS!C19), ISNUMBER(RESULTADOS!E19), L19=0, M19=0, N19=0, OR(AND(C19>E19, RESULTADOS!C19>RESULTADOS!E19), AND(E19>C19, RESULTADOS!E19>RESULTADOS!C19)) ), 1, 0 ) -> 0 | P19: =IF(AND(ISNUMBER(C19), ISNUMBER(E19), ISNUMBER(RESULTADOS!C19), ISNUMBER(RESULTADOS!E19), L19=0,M19=0,O19=0, C19=RESULTADOS!C19, E19=RESULTADOS!E19), 4, 0) -> 0 | Q19: =IF(AND(ISNUMBER(C19), ISNUMBER(E19), ISNUMBER(RESULTADOS!C19), ISNUMBER(RESULTADOS!E19), L19=0,M19=0,O19=0, P19=0,C19=E19, RESULTADOS!C19=RESULTADOS!E19), 2, 0) -> 0 | R19: =IF(AND(ISNUMBER(C19), ISNUMBER(E19), ISNUMBER(RESULTADOS!C19), ISNUMBER(RESULTADOS!E19), ISNUMBER(C20), ISNUMBER(E20), ISNUMBER(RESULTADOS!C19), ISNUMBER(RESULTADOS!E19),L19=0,M19=0,O19=0, C19=E19, RESULTADOS!C19=RESULTADOS!E19, OR(AND(C20>E20, RESULTADOS!C20>RESULTADOS!E20), AND(E20>C20, RESULTADOS!E20>RESULTADOS!C20))), 1, 0) -> 0 | T19: 2.16 | U19: 3.26 | V19: 3.64 | X19: =1/T19 -> 0.46296296 | Y19: =1/U19 -> 0.30674847 | Z19: =1/V19 -> 0.27472527
B20: =IF(AND(ISNUMBER(C19),ISNUMBER(E19),C19=E19),"Pênaltis","")
B21: =RESULTADOS!B21 -> Brasil | C21: 2 | D21: x | E21: 1 | F21: =RESULTADOS!F21 -> Japão | H21: 46202 | I21: 0.58333333 | K21: =SUM(L21:R21) -> 5 | L21: =IF(AND(ISNUMBER(C21), ISNUMBER(E21), ISNUMBER(RESULTADOS!C21), ISNUMBER(RESULTADOS!E21), C21=RESULTADOS!C21, E21=RESULTADOS!E21, C21<>E21), 5, 0) -> 5 | M21: =IF( AND(ISNUMBER(C21), ISNUMBER(E21), ISNUMBER(RESULTADOS!C21), ISNUMBER(RESULTADOS!E21), L21=0, OR(AND(C21>E21, RESULTADOS!C21>RESULTADOS!E21), AND(E21>C21, RESULTADOS!E21>RESULTADOS!C21)), OR(C21=RESULTADOS!C21, E21=RESULTADOS!E21) ), 3, 0 ) -> 0 | N21: =IF( AND(ISNUMBER(C21), ISNUMBER(E21), ISNUMBER(RESULTADOS!C21), ISNUMBER(RESULTADOS!E21), L21=0, M21=0, C21<>E21, C21-E21=RESULTADOS!C21-RESULTADOS!E21 ), 2, 0 ) -> 0 | O21: =IF( AND(ISNUMBER(C21), ISNUMBER(E21), ISNUMBER(RESULTADOS!C21), ISNUMBER(RESULTADOS!E21), L21=0, M21=0, N21=0, OR(AND(C21>E21, RESULTADOS!C21>RESULTADOS!E21), AND(E21>C21, RESULTADOS!E21>RESULTADOS!C21)) ), 1, 0 ) -> 0 | P21: =IF(AND(ISNUMBER(C21), ISNUMBER(E21), ISNUMBER(RESULTADOS!C21), ISNUMBER(RESULTADOS!E21), L21=0,M21=0,O21=0, C21=RESULTADOS!C21, E21=RESULTADOS!E21), 4, 0) -> 0 | Q21: =IF(AND(ISNUMBER(C21), ISNUMBER(E21), ISNUMBER(RESULTADOS!C21), ISNUMBER(RESULTADOS!E21), L21=0,M21=0,O21=0, P21=0,C21=E21, RESULTADOS!C21=RESULTADOS!E21), 2, 0) -> 0 | R21: =IF(AND(ISNUMBER(C21), ISNUMBER(E21), ISNUMBER(RESULTADOS!C21), ISNUMBER(RESULTADOS!E21), ISNUMBER(C22), ISNUMBER(E22), ISNUMBER(RESULTADOS!C21), ISNUMBER(RESULTADOS!E21),L21=0,M21=0,O21=0, C21=E21, RESULTADOS!C21=RESULTADOS!E21, OR(AND(C22>E22, RESULTADOS!C22>RESULTADOS!E22), AND(E22>C22, RESULTADOS!E22>RESULTADOS!C22))), 1, 0) -> 0 | T21: 1.7 | U21: 3.78 | V21: 5.07 | X21: =1/T21 -> 0.58823529 | Y21: =1/U21 -> 0.26455026 | Z21: =1/V21 -> 0.19723866
B22: =IF(AND(ISNUMBER(C21),ISNUMBER(E21),C21=E21),"Pênaltis","")
B23: =RESULTADOS!B23 -> Costa do Marfim | C23: 1 | D23: x | E23: 2 | F23: =RESULTADOS!F23 -> Noruega | H23: 46203 | I23: 0.58333333 | K23: =SUM(L23:R23) -> 5 | L23: =IF(AND(ISNUMBER(C23), ISNUMBER(E23), ISNUMBER(RESULTADOS!C23), ISNUMBER(RESULTADOS!E23), C23=RESULTADOS!C23, E23=RESULTADOS!E23, C23<>E23), 5, 0) -> 5 | M23: =IF( AND(ISNUMBER(C23), ISNUMBER(E23), ISNUMBER(RESULTADOS!C23), ISNUMBER(RESULTADOS!E23), L23=0, OR(AND(C23>E23, RESULTADOS!C23>RESULTADOS!E23), AND(E23>C23, RESULTADOS!E23>RESULTADOS!C23)), OR(C23=RESULTADOS!C23, E23=RESULTADOS!E23) ), 3, 0 ) -> 0 | N23: =IF( AND(ISNUMBER(C23), ISNUMBER(E23), ISNUMBER(RESULTADOS!C23), ISNUMBER(RESULTADOS!E23), L23=0, M23=0, C23<>E23, C23-E23=RESULTADOS!C23-RESULTADOS!E23 ), 2, 0 ) -> 0 | O23: =IF( AND(ISNUMBER(C23), ISNUMBER(E23), ISNUMBER(RESULTADOS!C23), ISNUMBER(RESULTADOS!E23), L23=0, M23=0, N23=0, OR(AND(C23>E23, RESULTADOS!C23>RESULTADOS!E23), AND(E23>C23, RESULTADOS!E23>RESULTADOS!C23)) ), 1, 0 ) -> 0 | P23: =IF(AND(ISNUMBER(C23), ISNUMBER(E23), ISNUMBER(RESULTADOS!C23), ISNUMBER(RESULTADOS!E23), L23=0,M23=0,O23=0, C23=RESULTADOS!C23, E23=RESULTADOS!E23), 4, 0) -> 0 | Q23: =IF(AND(ISNUMBER(C23), ISNUMBER(E23), ISNUMBER(RESULTADOS!C23), ISNUMBER(RESULTADOS!E23), L23=0,M23=0,O23=0, P23=0,C23=E23, RESULTADOS!C23=RESULTADOS!E23), 2, 0) -> 0 | R23: =IF(AND(ISNUMBER(C23), ISNUMBER(E23), ISNUMBER(RESULTADOS!C23), ISNUMBER(RESULTADOS!E23), ISNUMBER(C24), ISNUMBER(E24), ISNUMBER(RESULTADOS!C23), ISNUMBER(RESULTADOS!E23),L23=0,M23=0,O23=0, C23=E23, RESULTADOS!C23=RESULTADOS!E23, OR(AND(C24>E24, RESULTADOS!C24>RESULTADOS!E24), AND(E24>C24, RESULTADOS!E24>RESULTADOS!C24))), 1, 0) -> 0 | T23: 3.55 | U23: 3.53 | V23: 2.08 | X23: =1/T23 -> 0.28169014 | Y23: =1/U23 -> 0.28328612 | Z23: =1/V23 -> 0.48076923
B24: =IF(AND(ISNUMBER(C23),ISNUMBER(E23),C23=E23),"Pênaltis","")
B25: =RESULTADOS!B25 -> México | C25: 2 | D25: x | E25: 1 | F25: =RESULTADOS!F25 -> Equador | H25: 46203 | I25: 0.91666667 | K25: =SUM(L25:R25) -> 3 | L25: =IF(AND(ISNUMBER(C25), ISNUMBER(E25), ISNUMBER(RESULTADOS!C25), ISNUMBER(RESULTADOS!E25), C25=RESULTADOS!C25, E25=RESULTADOS!E25, C25<>E25), 5, 0) -> 0 | M25: =IF( AND(ISNUMBER(C25), ISNUMBER(E25), ISNUMBER(RESULTADOS!C25), ISNUMBER(RESULTADOS!E25), L25=0, OR(AND(C25>E25, RESULTADOS!C25>RESULTADOS!E25), AND(E25>C25, RESULTADOS!E25>RESULTADOS!C25)), OR(C25=RESULTADOS!C25, E25=RESULTADOS!E25) ), 3, 0 ) -> 3 | N25: =IF( AND(ISNUMBER(C25), ISNUMBER(E25), ISNUMBER(RESULTADOS!C25), ISNUMBER(RESULTADOS!E25), L25=0, M25=0, C25<>E25, C25-E25=RESULTADOS!C25-RESULTADOS!E25 ), 2, 0 ) -> 0 | O25: =IF( AND(ISNUMBER(C25), ISNUMBER(E25), ISNUMBER(RESULTADOS!C25), ISNUMBER(RESULTADOS!E25), L25=0, M25=0, N25=0, OR(AND(C25>E25, RESULTADOS!C25>RESULTADOS!E25), AND(E25>C25, RESULTADOS!E25>RESULTADOS!C25)) ), 1, 0 ) -> 0 | P25: =IF(AND(ISNUMBER(C25), ISNUMBER(E25), ISNUMBER(RESULTADOS!C25), ISNUMBER(RESULTADOS!E25), L25=0,M25=0,O25=0, C25=RESULTADOS!C25, E25=RESULTADOS!E25), 4, 0) -> 0 | Q25: =IF(AND(ISNUMBER(C25), ISNUMBER(E25), ISNUMBER(RESULTADOS!C25), ISNUMBER(RESULTADOS!E25), L25=0,M25=0,O25=0, P25=0,C25=E25, RESULTADOS!C25=RESULTADOS!E25), 2, 0) -> 0 | R25: =IF(AND(ISNUMBER(C25), ISNUMBER(E25), ISNUMBER(RESULTADOS!C25), ISNUMBER(RESULTADOS!E25), ISNUMBER(C26), ISNUMBER(E26), ISNUMBER(RESULTADOS!C25), ISNUMBER(RESULTADOS!E25),L25=0,M25=0,O25=0, C25=E25, RESULTADOS!C25=RESULTADOS!E25, OR(AND(C26>E26, RESULTADOS!C26>RESULTADOS!E26), AND(E26>C26, RESULTADOS!E26>RESULTADOS!C26))), 1, 0) -> 0 | T25: 2.26 | U25: 2.98 | V25: 3.75 | X25: =1/T25 -> 0.44247788 | Y25: =1/U25 -> 0.33557047 | Z25: =1/V25 -> 0.26666667
B26: =IF(AND(ISNUMBER(C25),ISNUMBER(E25),C25=E25),"Pênaltis","")
B27: =RESULTADOS!B27 -> Inglaterra | C27: 2 | D27: x | E27: 0 | F27: =RESULTADOS!F27 -> RD Congo | H27: 46204 | I27: 0.54166667 | K27: =SUM(L27:R27) -> 3 | L27: =IF(AND(ISNUMBER(C27), ISNUMBER(E27), ISNUMBER(RESULTADOS!C27), ISNUMBER(RESULTADOS!E27), C27=RESULTADOS!C27, E27=RESULTADOS!E27, C27<>E27), 5, 0) -> 0 | M27: =IF( AND(ISNUMBER(C27), ISNUMBER(E27), ISNUMBER(RESULTADOS!C27), ISNUMBER(RESULTADOS!E27), L27=0, OR(AND(C27>E27, RESULTADOS!C27>RESULTADOS!E27), AND(E27>C27, RESULTADOS!E27>RESULTADOS!C27)), OR(C27=RESULTADOS!C27, E27=RESULTADOS!E27) ), 3, 0 ) -> 3 | N27: =IF( AND(ISNUMBER(C27), ISNUMBER(E27), ISNUMBER(RESULTADOS!C27), ISNUMBER(RESULTADOS!E27), L27=0, M27=0, C27<>E27, C27-E27=RESULTADOS!C27-RESULTADOS!E27 ), 2, 0 ) -> 0 | O27: =IF( AND(ISNUMBER(C27), ISNUMBER(E27), ISNUMBER(RESULTADOS!C27), ISNUMBER(RESULTADOS!E27), L27=0, M27=0, N27=0, OR(AND(C27>E27, RESULTADOS!C27>RESULTADOS!E27), AND(E27>C27, RESULTADOS!E27>RESULTADOS!C27)) ), 1, 0 ) -> 0 | P27: =IF(AND(ISNUMBER(C27), ISNUMBER(E27), ISNUMBER(RESULTADOS!C27), ISNUMBER(RESULTADOS!E27), L27=0,M27=0,O27=0, C27=RESULTADOS!C27, E27=RESULTADOS!E27), 4, 0) -> 0 | Q27: =IF(AND(ISNUMBER(C27), ISNUMBER(E27), ISNUMBER(RESULTADOS!C27), ISNUMBER(RESULTADOS!E27), L27=0,M27=0,O27=0, P27=0,C27=E27, RESULTADOS!C27=RESULTADOS!E27), 2, 0) -> 0 | R27: =IF(AND(ISNUMBER(C27), ISNUMBER(E27), ISNUMBER(RESULTADOS!C27), ISNUMBER(RESULTADOS!E27), ISNUMBER(C28), ISNUMBER(E28), ISNUMBER(RESULTADOS!C27), ISNUMBER(RESULTADOS!E27),L27=0,M27=0,O27=0, C27=E27, RESULTADOS!C27=RESULTADOS!E27, OR(AND(C28>E28, RESULTADOS!C28>RESULTADOS!E28), AND(E28>C28, RESULTADOS!E28>RESULTADOS!C28))), 1, 0) -> 0 | T27: 1.28 | U27: 5.52 | V27: 12.4 | X27: =1/T27 -> 0.78125 | Y27: =1/U27 -> 0.18115942 | Z27: =1/V27 -> 0.080645161
B28: =IF(AND(ISNUMBER(C27),ISNUMBER(E27),C27=E27),"Pênaltis","")
