Workbook

Sheet PAGAMENTO
A1: Joels Soares | B1: OK
A2: Lucas Joels | B2: OK
A3: Tuka | B3: OK
A4: Barrão | B4: OK
A5: Zé Luis | B5: OK
A6: Nelson Emoção | B6: OK
A7: Nelson Razão | B7: OK
A8: Davi | B8: OK
A9: Mekler | B9: OK
A10: José | B10: OK
A11: Noé | B11: OK
A12: Pedro Hersz
A13: Matheus | B13: OK
A14: Daniel | B14: OK
A15: Jê | B15: OK
A16: Quito | B16: OK
A17: Diana | B17: OK
A18: Humberto
A19: Laufer
A20: Bento
A21: Tello

Sheet APOSTAS
B2: SEU NOME AQUI | H2: DATA | K2: CLASSIFICAÇÃO | T2: PONTUAÇÃO
T3: TOTAL | U3: =SUM(U5:U10,U13:U18,U21:U26,U29:U34,U37:U42,U45:U50,U53:U58,U61:U66) -> 0
B4: GRUPO A | H4: DIA | I4: HORA
B5: México | D5: x | F5: África do Sul | H5: 46184 | I5: 0.66666667 | L5: P | M5: SG | N5: GP | O5: GC | P5: V | Q5: E | R5: D | T5: =IF(NOT(AND(ISNUMBER(C5),ISNUMBER(E5))),"XXX","") -> XXX | U5: =SUM(Y5,Z5,AA5, AB5) -> 0 | Y5: =IF(AND(ISNUMBER(RESULTADOS!C5),ISNUMBER(RESULTADOS!E5),ISNUMBER(C5),ISNUMBER(E5),C5=RESULTADOS!C5,E5=RESULTADOS!E5),2,0) -> 0 | Z5: =IF(AND(ISNUMBER(RESULTADOS!C5),ISNUMBER(RESULTADOS!E5),ISNUMBER(C5),ISNUMBER(E5)),IF(OR(AND(C5>E5,RESULTADOS!C5>RESULTADOS!E5),AND(C5<E5,RESULTADOS!C5<RESULTADOS!E5)),1,IF(AND(C5=E5,RESULTADOS!C5=RESULTADOS!E5),2,0)),0) -> 0 | AA5: =IF(AND(ISNUMBER(RESULTADOS!C5),ISNUMBER(RESULTADOS!E5),ISNUMBER(C5),ISNUMBER(E5),AND(Z5=1,OR(C5=RESULTADOS!C5,E5=RESULTADOS!E5))),1,0) -> 0 | AB5: =IF( AND( ISNUMBER(RESULTADOS!C5), ISNUMBER(RESULTADOS!E5), ISNUMBER(C5), ISNUMBER(E5), AND(Z5=1,AA5=0,(RESULTADOS!C5-RESULTADOS!E5)=(C5-E5)) ), 1, 0 ) -> 0
B6: Coreia do Sul | D6: x | F6: República Tcheca | H6: 46184 | I6: 0.95833333 | K6: Coreia do Sul | L6: =SUM(IF(AND(ISNUMBER(INDIRECT($AC6)),INDIRECT($AC6)>INDIRECT($AF6)),3,IF(AND(ISNUMBER(INDIRECT($AC6)),INDIRECT($AC6)=INDIRECT($AF6)),1,0)),IF(AND(ISNUMBER(INDIRECT($AD6)),INDIRECT($AD6)>INDIRECT($AG6)),3,IF(AND(ISNUMBER(INDIRECT($AD6)),INDIRECT($AD6)=INDIRECT($AG6)),1,0)),IF(AND(ISNUMBER(INDIRECT($AE6)),INDIRECT($AE6)>INDIRECT($AH6)),3,IF(AND(ISNUMBER(INDIRECT($AE6)),INDIRECT($AE6)=INDIRECT($AH6)),1,0))) -> 0 | M6: =N6-O6 -> 0 | N6: =SUM(INDIRECT($AC6),INDIRECT($AD6),INDIRECT($AE6)) -> 0 | O6: =SUM(INDIRECT($AF6),INDIRECT($AG6),INDIRECT($AH6)) -> 0 | P6: =SUM(IF(AND(ISNUMBER(INDIRECT($AC6)),INDIRECT($AC6)>INDIRECT($AF6)),1,0),IF(AND(ISNUMBER(INDIRECT($AD6)),INDIRECT($AD6)>INDIRECT($AG6)),1,0),IF(AND(ISNUMBER(INDIRECT($AE6)),INDIRECT($AE6)>INDIRECT($AH6)),1,0)) -> 0 | Q6: =SUM(IF(AND(ISNUMBER(INDIRECT($AC6)),INDIRECT($AC6)=INDIRECT($AF6)),1,0),IF(AND(ISNUMBER(INDIRECT($AD6)),INDIRECT($AD6)=INDIRECT($AG6)),1,0),IF(AND(ISNUMBER(INDIRECT($AE6)),INDIRECT($AE6)=INDIRECT($AH6)),1,0)) -> 0 | R6: =SUM(IF(AND(ISNUMBER(INDIRECT($AC6)),INDIRECT($AC6)<INDIRECT($AF6)),1,0),IF(AND(ISNUMBER(INDIRECT($AD6)),INDIRECT($AD6)<INDIRECT($AG6)),1,0),IF(AND(ISNUMBER(INDIRECT($AE6)),INDIRECT($AE6)<INDIRECT($AH6)),1,0)) -> 0 | T6: =IF(NOT(AND(ISNUMBER(C6),ISNUMBER(E6))),"XXX","") -> XXX | U6: =SUM(Y6,Z6,AA6, AB6) -> 0 | Y6: =IF(AND(ISNUMBER(RESULTADOS!C6),ISNUMBER(RESULTADOS!E6),ISNUMBER(C6),ISNUMBER(E6),C6=RESULTADOS!C6,E6=RESULTADOS!E6),2,0) -> 0 | Z6: =IF(AND(ISNUMBER(RESULTADOS!C6),ISNUMBER(RESULTADOS!E6),ISNUMBER(C6),ISNUMBER(E6)),IF(OR(AND(C6>E6,RESULTADOS!C6>RESULTADOS!E6),AND(C6<E6,RESULTADOS!C6<RESULTADOS!E6)),1,IF(AND(C6=E6,RESULTADOS!C6=RESULTADOS!E6),2,0)),0) -> 0 | AA6: =IF(AND(ISNUMBER(RESULTADOS!C6),ISNUMBER(RESULTADOS!E6),ISNUMBER(C6),ISNUMBER(E6),AND(Z6=1,OR(C6=RESULTADOS!C6,E6=RESULTADOS!E6))),1,0) -> 0 | AB6: =IF( AND( ISNUMBER(RESULTADOS!C6), ISNUMBER(RESULTADOS!E6), ISNUMBER(C6), ISNUMBER(E6), AND(Z6=1,AA6=0,(RESULTADOS!C6-RESULTADOS!E6)=(C6-E6)) ), 1, 0 ) -> 0 | AC6: C6 | AD6: E8 | AE6: E9 | AF6: =IF(ISNUMBER(FIND("C", AC6, 1)), SUBSTITUTE(AC6, "C", "E"), SUBSTITUTE(AC6, "E", "C")) -> E6 | AG6: =IF(ISNUMBER(FIND("C", AD6, 1)), SUBSTITUTE(AD6, "C", "E"), SUBSTITUTE(AD6, "E", "C")) -> C8 | AH6: =IF(ISNUMBER(FIND("C", AE6, 1)), SUBSTITUTE(AE6, "C", "E"), SUBSTITUTE(AE6, "E", "C")) -> C9
B7: República Tcheca | D7: x | F7: África do Sul | H7: 46191 | I7: 0.54166667 | K7: México | L7: =SUM(IF(AND(ISNUMBER(INDIRECT($AC7)),INDIRECT($AC7)>INDIRECT($AF7)),3,IF(AND(ISNUMBER(INDIRECT($AC7)),INDIRECT($AC7)=INDIRECT($AF7)),1,0)),IF(AND(ISNUMBER(INDIRECT($AD7)),INDIRECT($AD7)>INDIRECT($AG7)),3,IF(AND(ISNUMBER(INDIRECT($AD7)),INDIRECT($AD7)=INDIRECT($AG7)),1,0)),IF(AND(ISNUMBER(INDIRECT($AE7)),INDIRECT($AE7)>INDIRECT($AH7)),3,IF(AND(ISNUMBER(INDIRECT($AE7)),INDIRECT($AE7)=INDIRECT($AH7)),1,0))) -> 0 | M7: =N7-O7 -> 0 | N7: =SUM(INDIRECT($AC7),INDIRECT($AD7),INDIRECT($AE7)) -> 0 | O7: =SUM(INDIRECT($AF7),INDIRECT($AG7),INDIRECT($AH7)) -> 0 | P7: =SUM(IF(AND(ISNUMBER(INDIRECT($AC7)),INDIRECT($AC7)>INDIRECT($AF7)),1,0),IF(AND(ISNUMBER(INDIRECT($AD7)),INDIRECT($AD7)>INDIRECT($AG7)),1,0),IF(AND(ISNUMBER(INDIRECT($AE7)),INDIRECT($AE7)>INDIRECT($AH7)),1,0)) -> 0 | Q7: =SUM(IF(AND(ISNUMBER(INDIRECT($AC7)),INDIRECT($AC7)=INDIRECT($AF7)),1,0),IF(AND(ISNUMBER(INDIRECT($AD7)),INDIRECT($AD7)=INDIRECT($AG7)),1,0),IF(AND(ISNUMBER(INDIRECT($AE7)),INDIRECT($AE7)=INDIRECT($AH7)),1,0)) -> 0 | R7: =SUM(IF(AND(ISNUMBER(INDIRECT($AC7)),INDIRECT($AC7)<INDIRECT($AF7)),1,0),IF(AND(ISNUMBER(INDIRECT($AD7)),INDIRECT($AD7)<INDIRECT($AG7)),1,0),IF(AND(ISNUMBER(INDIRECT($AE7)),INDIRECT($AE7)<INDIRECT($AH7)),1,0)) -> 0 | T7: =IF(NOT(AND(ISNUMBER(C7),ISNUMBER(E7))),"XXX","") -> XXX | U7: =SUM(Y7,Z7,AA7, AB7) -> 0 | Y7: =IF(AND(ISNUMBER(RESULTADOS!C7),ISNUMBER(RESULTADOS!E7),ISNUMBER(C7),ISNUMBER(E7),C7=RESULTADOS!C7,E7=RESULTADOS!E7),2,0) -> 0 | Z7: =IF(AND(ISNUMBER(RESULTADOS!C7),ISNUMBER(RESULTADOS!E7),ISNUMBER(C7),ISNUMBER(E7)),IF(OR(AND(C7>E7,RESULTADOS!C7>RESULTADOS!E7),AND(C7<E7,RESULTADOS!C7<RESULTADOS!E7)),1,IF(AND(C7=E7,RESULTADOS!C7=RESULTADOS!E7),2,0)),0) -> 0 | AA7: =IF(AND(ISNUMBER(RESULTADOS!C7),ISNUMBER(RESULTADOS!E7),ISNUMBER(C7),ISNUMBER(E7),AND(Z7=1,OR(C7=RESULTADOS!C7,E7=RESULTADOS!E7))),1,0) -> 0 | AB7: =IF( AND( ISNUMBER(RESULTADOS!C7), ISNUMBER(RESULTADOS!E7), ISNUMBER(C7), ISNUMBER(E7), AND(Z7=1,AA7=0,(RESULTADOS!C7-RESULTADOS!E7)=(C7-E7)) ), 1, 0 ) -> 0 | AC7: C5 | AD7: C8 | AE7: E10 | AF7: =IF(ISNUMBER(FIND("C", AC7, 1)), SUBSTITUTE(AC7, "C", "E"), SUBSTITUTE(AC7, "E", "C")) -> E5 | AG7: =IF(ISNUMBER(FIND("C", AD7, 1)), SUBSTITUTE(AD7, "C", "E"), SUBSTITUTE(AD7, "E", "C")) -> E8 | AH7: =IF(ISNUMBER(FIND("C", AE7, 1)), SUBSTITUTE(AE7, "C", "E"), SUBSTITUTE(AE7, "E", "C")) -> C10
B8: México | D8: x | F8: Coreia do Sul | H8: 46191 | I8: 0.91666667 | K8: República Tcheca | L8: =SUM(IF(AND(ISNUMBER(INDIRECT($AC8)),INDIRECT($AC8)>INDIRECT($AF8)),3,IF(AND(ISNUMBER(INDIRECT($AC8)),INDIRECT($AC8)=INDIRECT($AF8)),1,0)),IF(AND(ISNUMBER(INDIRECT($AD8)),INDIRECT($AD8)>INDIRECT($AG8)),3,IF(AND(ISNUMBER(INDIRECT($AD8)),INDIRECT($AD8)=INDIRECT($AG8)),1,0)),IF(AND(ISNUMBER(INDIRECT($AE8)),INDIRECT($AE8)>INDIRECT($AH8)),3,IF(AND(ISNUMBER(INDIRECT($AE8)),INDIRECT($AE8)=INDIRECT($AH8)),1,0))) -> 0 | M8: =N8-O8 -> 0 | N8: =SUM(INDIRECT($AC8),INDIRECT($AD8),INDIRECT($AE8)) -> 0 | O8: =SUM(INDIRECT($AF8),INDIRECT($AG8),INDIRECT($AH8)) -> 0 | P8: =SUM(IF(AND(ISNUMBER(INDIRECT($AC8)),INDIRECT($AC8)>INDIRECT($AF8)),1,0),IF(AND(ISNUMBER(INDIRECT($AD8)),INDIRECT($AD8)>INDIRECT($AG8)),1,0),IF(AND(ISNUMBER(INDIRECT($AE8)),INDIRECT($AE8)>INDIRECT($AH8)),1,0)) -> 0 | Q8: =SUM(IF(AND(ISNUMBER(INDIRECT($AC8)),INDIRECT($AC8)=INDIRECT($AF8)),1,0),IF(AND(ISNUMBER(INDIRECT($AD8)),INDIRECT($AD8)=INDIRECT($AG8)),1,0),IF(AND(ISNUMBER(INDIRECT($AE8)),INDIRECT($AE8)=INDIRECT($AH8)),1,0)) -> 0 | R8: =SUM(IF(AND(ISNUMBER(INDIRECT($AC8)),INDIRECT($AC8)<INDIRECT($AF8)),1,0),IF(AND(ISNUMBER(INDIRECT($AD8)),INDIRECT($AD8)<INDIRECT($AG8)),1,0),IF(AND(ISNUMBER(INDIRECT($AE8)),INDIRECT($AE8)<INDIRECT($AH8)),1,0)) -> 0 | T8: =IF(NOT(AND(ISNUMBER(C8),ISNUMBER(E8))),"XXX","") -> XXX | U8: =SUM(Y8,Z8,AA8, AB8) -> 0 | Y8: =IF(AND(ISNUMBER(RESULTADOS!C8),ISNUMBER(RESULTADOS!E8),ISNUMBER(C8),ISNUMBER(E8),C8=RESULTADOS!C8,E8=RESULTADOS!E8),2,0) -> 0 | Z8: =IF(AND(ISNUMBER(RESULTADOS!C8),ISNUMBER(RESULTADOS!E8),ISNUMBER(C8),ISNUMBER(E8)),IF(OR(AND(C8>E8,RESULTADOS!C8>RESULTADOS!E8),AND(C8<E8,RESULTADOS!C8<RESULTADOS!E8)),1,IF(AND(C8=E8,RESULTADOS!C8=RESULTADOS!E8),2,0)),0) -> 0 | AA8: =IF(AND(ISNUMBER(RESULTADOS!C8),ISNUMBER(RESULTADOS!E8),ISNUMBER(C8),ISNUMBER(E8),AND(Z8=1,OR(C8=RESULTADOS!C8,E8=RESULTADOS!E8))),1,0) -> 0 | AB8: =IF( AND( ISNUMBER(RESULTADOS!C8), ISNUMBER(RESULTADOS!E8), ISNUMBER(C8), ISNUMBER(E8), AND(Z8=1,AA8=0,(RESULTADOS!C8-RESULTADOS!E8)=(C8-E8)) ), 1, 0 ) -> 0 | AC8: E6 | AD8: C7 | AE8: C10 | AF8: =IF(ISNUMBER(FIND("C", AC8, 1)), SUBSTITUTE(AC8, "C", "E"), SUBSTITUTE(AC8, "E", "C")) -> C6 | AG8: =IF(ISNUMBER(FIND("C", AD8, 1)), SUBSTITUTE(AD8, "C", "E"), SUBSTITUTE(AD8, "E", "C")) -> E7 | AH8: =IF(ISNUMBER(FIND("C", AE8, 1)), SUBSTITUTE(AE8, "C", "E"), SUBSTITUTE(AE8, "E", "C")) -> E10
B9: África do Sul | D9: x | F9: Coreia do Sul | H9: 46197 | I9: 0.91666667 | K9: África do Sul | L9: =SUM(IF(AND(ISNUMBER(INDIRECT($AC9)),INDIRECT($AC9)>INDIRECT($AF9)),3,IF(AND(ISNUMBER(INDIRECT($AC9)),INDIRECT($AC9)=INDIRECT($AF9)),1,0)),IF(AND(ISNUMBER(INDIRECT($AD9)),INDIRECT($AD9)>INDIRECT($AG9)),3,IF(AND(ISNUMBER(INDIRECT($AD9)),INDIRECT($AD9)=INDIRECT($AG9)),1,0)),IF(AND(ISNUMBER(INDIRECT($AE9)),INDIRECT($AE9)>INDIRECT($AH9)),3,IF(AND(ISNUMBER(INDIRECT($AE9)),INDIRECT($AE9)=INDIRECT($AH9)),1,0))) -> 0 | M9: =N9-O9 -> 0 | N9: =SUM(INDIRECT($AC9),INDIRECT($AD9),INDIRECT($AE9)) -> 0 | O9: =SUM(INDIRECT($AF9),INDIRECT($AG9),INDIRECT($AH9)) -> 0 | P9: =SUM(IF(AND(ISNUMBER(INDIRECT($AC9)),INDIRECT($AC9)>INDIRECT($AF9)),1,0),IF(AND(ISNUMBER(INDIRECT($AD9)),INDIRECT($AD9)>INDIRECT($AG9)),1,0),IF(AND(ISNUMBER(INDIRECT($AE9)),INDIRECT($AE9)>INDIRECT($AH9)),1,0)) -> 0 | Q9: =SUM(IF(AND(ISNUMBER(INDIRECT($AC9)),INDIRECT($AC9)=INDIRECT($AF9)),1,0),IF(AND(ISNUMBER(INDIRECT($AD9)),INDIRECT($AD9)=INDIRECT($AG9)),1,0),IF(AND(ISNUMBER(INDIRECT($AE9)),INDIRECT($AE9)=INDIRECT($AH9)),1,0)) -> 0 | R9: =SUM(IF(AND(ISNUMBER(INDIRECT($AC9)),INDIRECT($AC9)<INDIRECT($AF9)),1,0),IF(AND(ISNUMBER(INDIRECT($AD9)),INDIRECT($AD9)<INDIRECT($AG9)),1,0),IF(AND(ISNUMBER(INDIRECT($AE9)),INDIRECT($AE9)<INDIRECT($AH9)),1,0)) -> 0 | T9: =IF(NOT(AND(ISNUMBER(C9),ISNUMBER(E9))),"XXX","") -> XXX | U9: =SUM(Y9,Z9,AA9, AB9) -> 0 | Y9: =IF(AND(ISNUMBER(RESULTADOS!C9),ISNUMBER(RESULTADOS!E9),ISNUMBER(C9),ISNUMBER(E9),C9=RESULTADOS!C9,E9=RESULTADOS!E9),2,0) -> 0 | Z9: =IF(AND(ISNUMBER(RESULTADOS!C9),ISNUMBER(RESULTADOS!E9),ISNUMBER(C9),ISNUMBER(E9)),IF(OR(AND(C9>E9,RESULTADOS!C9>RESULTADOS!E9),AND(C9<E9,RESULTADOS!C9<RESULTADOS!E9)),1,IF(AND(C9=E9,RESULTADOS!C9=RESULTADOS!E9),2,0)),0) -> 0 | AA9: =IF(AND(ISNUMBER(RESULTADOS!C9),ISNUMBER(RESULTADOS!E9),ISNUMBER(C9),ISNUMBER(E9),AND(Z9=1,OR(C9=RESULTADOS!C9,E9=RESULTADOS!E9))),1,0) -> 0 | AB9: =IF( AND( ISNUMBER(RESULTADOS!C9), ISNUMBER(RESULTADOS!E9), ISNUMBER(C9), ISNUMBER(E9), AND(Z9=1,AA9=0,(RESULTADOS!C9-RESULTADOS!E9)=(C9-E9)) ), 1, 0 ) -> 0 | AC9: E5 | AD9: E7 | AE9: C9 | AF9: =IF(ISNUMBER(FIND("C", AC9, 1)), SUBSTITUTE(AC9, "C", "E"), SUBSTITUTE(AC9, "E", "C")) -> C5 | AG9: =IF(ISNUMBER(FIND("C", AD9, 1)), SUBSTITUTE(AD9, "C", "E"), SUBSTITUTE(AD9, "E", "C")) -> C7 | AH9: =IF(ISNUMBER(FIND("C", AE9, 1)), SUBSTITUTE(AE9, "C", "E"), SUBSTITUTE(AE9, "E", "C")) -> E9
B10: República Tcheca | D10: x | F10: México | H10: 46197 | I10: 0.91666667 | T10: =IF(NOT(AND(ISNUMBER(C10),ISNUMBER(E10))),"XXX","") -> XXX | U10: =SUM(Y10,Z10,AA10, AB10) -> 0 | Y10: =IF(AND(ISNUMBER(RESULTADOS!C10),ISNUMBER(RESULTADOS!E10),ISNUMBER(C10),ISNUMBER(E10),C10=RESULTADOS!C10,E10=RESULTADOS!E10),2,0) -> 0 | Z10: =IF(AND(ISNUMBER(RESULTADOS!C10),ISNUMBER(RESULTADOS!E10),ISNUMBER(C10),ISNUMBER(E10)),IF(OR(AND(C10>E10,RESULTADOS!C10>RESULTADOS!E10),AND(C10<E10,RESULTADOS!C10<RESULTADOS!E10)),1,IF(AND(C10=E10,RESULTADOS!C10=RESULTADOS!E10),2,0)),0) -> 0 | AA10: =IF(AND(ISNUMBER(RESULTADOS!C10),ISNUMBER(RESULTADOS!E10),ISNUMBER(C10),ISNUMBER(E10),AND(Z10=1,OR(C10=RESULTADOS!C10,E10=RESULTADOS!E10))),1,0) -> 0 | AB10: =IF( AND( ISNUMBER(RESULTADOS!C10), ISNUMBER(RESULTADOS!E10), ISNUMBER(C10), ISNUMBER(E10), AND(Z10=1,AA10=0,(RESULTADOS!C10-RESULTADOS!E10)=(C10-E10)) ), 1, 0 ) -> 0
B12: GRUPO B | H12: DIA | I12: HORA
B13: Canadá | D13: x | F13: Bósnia | H13: 46185 | I13: 0.66666667 | L13: P | M13: SG | N13: GP | O13: GC | P13: V | Q13: E | R13: D | T13: =IF(NOT(AND(ISNUMBER(C13),ISNUMBER(E13))),"XXX","") -> XXX | U13: =SUM(Y13,Z13,AA13, AB13) -> 0 | Y13: =IF(AND(ISNUMBER(RESULTADOS!C13),ISNUMBER(RESULTADOS!E13),ISNUMBER(C13),ISNUMBER(E13),C13=RESULTADOS!C13,E13=RESULTADOS!E13),2,0) -> 0 | Z13: =IF(AND(ISNUMBER(RESULTADOS!C13),ISNUMBER(RESULTADOS!E13),ISNUMBER(C13),ISNUMBER(E13)),IF(OR(AND(C13>E13,RESULTADOS!C13>RESULTADOS!E13),AND(C13<E13,RESULTADOS!C13<RESULTADOS!E13)),1,IF(AND(C13=E13,RESULTADOS!C13=RESULTADOS!E13),2,0)),0) -> 0 | AA13: =IF(AND(ISNUMBER(RESULTADOS!C13),ISNUMBER(RESULTADOS!E13),ISNUMBER(C13),ISNUMBER(E13),AND(Z13=1,OR(C13=RESULTADOS!C13,E13=RESULTADOS!E13))),1,0) -> 0 | AB13: =IF( AND( ISNUMBER(RESULTADOS!C13), ISNUMBER(RESULTADOS!E13), ISNUMBER(C13), ISNUMBER(E13), AND(Z13=1,AA13=0,(RESULTADOS!C13-RESULTADOS!E13)=(C13-E13)) ), 1, 0 ) -> 0
B14: Catar | D14: x | F14: Suíça | H14: 46186 | I14: 0.66666667 | K14: Bósnia | L14: =SUM(IF(AND(ISNUMBER(INDIRECT($AC14)),INDIRECT($AC14)>INDIRECT($AF14)),3,IF(AND(ISNUMBER(INDIRECT($AC14)),INDIRECT($AC14)=INDIRECT($AF14)),1,0)),IF(AND(ISNUMBER(INDIRECT($AD14)),INDIRECT($AD14)>INDIRECT($AG14)),3,IF(AND(ISNUMBER(INDIRECT($AD14)),INDIRECT($AD14)=INDIRECT($AG14)),1,0)),IF(AND(ISNUMBER(INDIRECT($AE14)),INDIRECT($AE14)>INDIRECT($AH14)),3,IF(AND(ISNUMBER(INDIRECT($AE14)),INDIRECT($AE14)=INDIRECT($AH14)),1,0))) -> 0 | M14: =N14-O14 -> 0 | N14: =SUM(INDIRECT($AC14),INDIRECT($AD14),INDIRECT($AE14)) -> 0 | O14: =SUM(INDIRECT($AF14),INDIRECT($AG14),INDIRECT($AH14)) -> 0 | P14: =SUM(IF(AND(ISNUMBER(INDIRECT($AC14)),INDIRECT($AC14)>INDIRECT($AF14)),1,0),IF(AND(ISNUMBER(INDIRECT($AD14)),INDIRECT($AD14)>INDIRECT($AG14)),1,0),IF(AND(ISNUMBER(INDIRECT($AE14)),INDIRECT($AE14)>INDIRECT($AH14)),1,0)) -> 0 | Q14: =SUM(IF(AND(ISNUMBER(INDIRECT($AC14)),INDIRECT($AC14)=INDIRECT($AF14)),1,0),IF(AND(ISNUMBER(INDIRECT($AD14)),INDIRECT($AD14)=INDIRECT($AG14)),1,0),IF(AND(ISNUMBER(INDIRECT($AE14)),INDIRECT($AE14)=INDIRECT($AH14)),1,0)) -> 0 | R14: =SUM(IF(AND(ISNUMBER(INDIRECT($AC14)),INDIRECT($AC14)<INDIRECT($AF14)),1,0),IF(AND(ISNUMBER(INDIRECT($AD14)),INDIRECT($AD14)<INDIRECT($AG14)),1,0),IF(AND(ISNUMBER(INDIRECT($AE14)),INDIRECT($AE14)<INDIRECT($AH14)),1,0)) -> 0 | T14: =IF(NOT(AND(ISNUMBER(C14),ISNUMBER(E14))),"XXX","") -> XXX | U14: =SUM(Y14,Z14,AA14, AB14) -> 0 | Y14: =IF(AND(ISNUMBER(RESULTADOS!C14),ISNUMBER(RESULTADOS!E14),ISNUMBER(C14),ISNUMBER(E14),C14=RESULTADOS!C14,E14=RESULTADOS!E14),2,0) -> 0 | Z14: =IF(AND(ISNUMBER(RESULTADOS!C14),ISNUMBER(RESULTADOS!E14),ISNUMBER(C14),ISNUMBER(E14)),IF(OR(AND(C14>E14,RESULTADOS!C14>RESULTADOS!E14),AND(C14<E14,RESULTADOS!C14<RESULTADOS!E14)),1,IF(AND(C14=E14,RESULTADOS!C14=RESULTADOS!E14),2,0)),0) -> 0 | AA14: =IF(AND(ISNUMBER(RESULTADOS!C14),ISNUMBER(RESULTADOS!E14),ISNUMBER(C14),ISNUMBER(E14),AND(Z14=1,OR(C14=RESULTADOS!C14,E14=RESULTADOS!E14))),1,0) -> 0 | AB14: =IF( AND( ISNUMBER(RESULTADOS!C14), ISNUMBER(RESULTADOS!E14), ISNUMBER(C14), ISNUMBER(E14), AND(Z14=1,AA14=0,(RESULTADOS!C14-RESULTADOS!E14)=(C14-E14)) ), 1, 0 ) -> 0 | AC14: E13 | AD14: E15 | AE14: C18 | AF14: =IF(ISNUMBER(FIND("C", AC14, 1)), SUBSTITUTE(AC14, "C", "E"), SUBSTITUTE(AC14, "E", "C")) -> C13 | AG14: =IF(ISNUMBER(FIND("C", AD14, 1)), SUBSTITUTE(AD14, "C", "E"), SUBSTITUTE(AD14, "E", "C")) -> C15 | AH14: =IF(ISNUMBER(FIND("C", AE14, 1)), SUBSTITUTE(AE14, "C", "E"), SUBSTITUTE(AE14, "E", "C")) -> E18
B15: Suíça | D15: x | F15: Bósnia | H15: 46191 | I15: 0.66666667 | K15: Canadá | L15: =SUM(IF(AND(ISNUMBER(INDIRECT($AC15)),INDIRECT($AC15)>INDIRECT($AF15)),3,IF(AND(ISNUMBER(INDIRECT($AC15)),INDIRECT($AC15)=INDIRECT($AF15)),1,0)),IF(AND(ISNUMBER(INDIRECT($AD15)),INDIRECT($AD15)>INDIRECT($AG15)),3,IF(AND(ISNUMBER(INDIRECT($AD15)),INDIRECT($AD15)=INDIRECT($AG15)),1,0)),IF(AND(ISNUMBER(INDIRECT($AE15)),INDIRECT($AE15)>INDIRECT($AH15)),3,IF(AND(ISNUMBER(INDIRECT($AE15)),INDIRECT($AE15)=INDIRECT($AH15)),1,0))) -> 0 | M15: =N15-O15 -> 0 | N15: =SUM(INDIRECT($AC15),INDIRECT($AD15),INDIRECT($AE15)) -> 0 | O15: =SUM(INDIRECT($AF15),INDIRECT($AG15),INDIRECT($AH15)) -> 0 | P15: =SUM(IF(AND(ISNUMBER(INDIRECT($AC15)),INDIRECT($AC15)>INDIRECT($AF15)),1,0),IF(AND(ISNUMBER(INDIRECT($AD15)),INDIRECT($AD15)>INDIRECT($AG15)),1,0),IF(AND(ISNUMBER(INDIRECT($AE15)),INDIRECT($AE15)>INDIRECT($AH15)),1,0)) -> 0 | Q15: =SUM(IF(AND(ISNUMBER(INDIRECT($AC15)),INDIRECT($AC15)=INDIRECT($AF15)),1,0),IF(AND(ISNUMBER(INDIRECT($AD15)),INDIRECT($AD15)=INDIRECT($AG15)),1,0),IF(AND(ISNUMBER(INDIRECT($AE15)),INDIRECT($AE15)=INDIRECT($AH15)),1,0)) -> 0 | R15: =SUM(IF(AND(ISNUMBER(INDIRECT($AC15)),INDIRECT($AC15)<INDIRECT($AF15)),1,0),IF(AND(ISNUMBER(INDIRECT($AD15)),INDIRECT($AD15)<INDIRECT($AG15)),1,0),IF(AND(ISNUMBER(INDIRECT($AE15)),INDIRECT($AE15)<INDIRECT($AH15)),1,0)) -> 0 | T15: =IF(NOT(AND(ISNUMBER(C15),ISNUMBER(E15))),"XXX","") -> XXX | U15: =SUM(Y15,Z15,AA15, AB15) -> 0 | Y15: =IF(AND(ISNUMBER(RESULTADOS!C15),ISNUMBER(RESULTADOS!E15),ISNUMBER(C15),ISNUMBER(E15),C15=RESULTADOS!C15,E15=RESULTADOS!E15),2,0) -> 0 | Z15: =IF(AND(ISNUMBER(RESULTADOS!C15),ISNUMBER(RESULTADOS!E15),ISNUMBER(C15),ISNUMBER(E15)),IF(OR(AND(C15>E15,RESULTADOS!C15>RESULTADOS!E15),AND(C15<E15,RESULTADOS!C15<RESULTADOS!E15)),1,IF(AND(C15=E15,RESULTADOS!C15=RESULTADOS!E15),2,0)),0) -> 0 | AA15: =IF(AND(ISNUMBER(RESULTADOS!C15),ISNUMBER(RESULTADOS!E15),ISNUMBER(C15),ISNUMBER(E15),AND(Z15=1,OR(C15=RESULTADOS!C15,E15=RESULTADOS!E15))),1,0) -> 0 | AB15: =IF( AND( ISNUMBER(RESULTADOS!C15), ISNUMBER(RESULTADOS!E15), ISNUMBER(C15), ISNUMBER(E15), AND(Z15=1,AA15=0,(RESULTADOS!C15-RESULTADOS!E15)=(C15-E15)) ), 1, 0 ) -> 0 | AC15: C13 | AD15: C16 | AE15: E17 | AF15: =IF(ISNUMBER(FIND("C", AC15, 1)), SUBSTITUTE(AC15, "C", "E"), SUBSTITUTE(AC15, "E", "C")) -> E13 | AG15: =IF(ISNUMBER(FIND("C", AD15, 1)), SUBSTITUTE(AD15, "C", "E"), SUBSTITUTE(AD15, "E", "C")) -> E16 | AH15: =IF(ISNUMBER(FIND("C", AE15, 1)), SUBSTITUTE(AE15, "C", "E"), SUBSTITUTE(AE15, "E", "C")) -> C17
B16: Canadá | D16: x | F16: Catar | H16: 46191 | I16: 0.79166667 | K16: Catar | L16: =SUM(IF(AND(ISNUMBER(INDIRECT($AC16)),INDIRECT($AC16)>INDIRECT($AF16)),3,IF(AND(ISNUMBER(INDIRECT($AC16)),INDIRECT($AC16)=INDIRECT($AF16)),1,0)),IF(AND(ISNUMBER(INDIRECT($AD16)),INDIRECT($AD16)>INDIRECT($AG16)),3,IF(AND(ISNUMBER(INDIRECT($AD16)),INDIRECT($AD16)=INDIRECT($AG16)),1,0)),IF(AND(ISNUMBER(INDIRECT($AE16)),INDIRECT($AE16)>INDIRECT($AH16)),3,IF(AND(ISNUMBER(INDIRECT($AE16)),INDIRECT($AE16)=INDIRECT($AH16)),1,0))) -> 0 | M16: =N16-O16 -> 0 | N16: =SUM(INDIRECT($AC16),INDIRECT($AD16),INDIRECT($AE16)) -> 0 | O16: =SUM(INDIRECT($AF16),INDIRECT($AG16),INDIRECT($AH16)) -> 0 | P16: =SUM(IF(AND(ISNUMBER(INDIRECT($AC16)),INDIRECT($AC16)>INDIRECT($AF16)),1,0),IF(AND(ISNUMBER(INDIRECT($AD16)),INDIRECT($AD16)>INDIRECT($AG16)),1,0),IF(AND(ISNUMBER(INDIRECT($AE16)),INDIRECT($AE16)>INDIRECT($AH16)),1,0)) -> 0 | Q16: =SUM(IF(AND(ISNUMBER(INDIRECT($AC16)),INDIRECT($AC16)=INDIRECT($AF16)),1,0),IF(AND(ISNUMBER(INDIRECT($AD16)),INDIRECT($AD16)=INDIRECT($AG16)),1,0),IF(AND(ISNUMBER(INDIRECT($AE16)),INDIRECT($AE16)=INDIRECT($AH16)),1,0)) -> 0 | R16: =SUM(IF(AND(ISNUMBER(INDIRECT($AC16)),INDIRECT($AC16)<INDIRECT($AF16)),1,0),IF(AND(ISNUMBER(INDIRECT($AD16)),INDIRECT($AD16)<INDIRECT($AG16)),1,0),IF(AND(ISNUMBER(INDIRECT($AE16)),INDIRECT($AE16)<INDIRECT($AH16)),1,0)) -> 0 | T16: =IF(NOT(AND(ISNUMBER(C16),ISNUMBER(E16))),"XXX","") -> XXX | U16: =SUM(Y16,Z16,AA16, AB16) -> 0 | Y16: =IF(AND(ISNUMBER(RESULTADOS!C16),ISNUMBER(RESULTADOS!E16),ISNUMBER(C16),ISNUMBER(E16),C16=RESULTADOS!C16,E16=RESULTADOS!E16),2,0) -> 0 | Z16: =IF(AND(ISNUMBER(RESULTADOS!C16),ISNUMBER(RESULTADOS!E16),ISNUMBER(C16),ISNUMBER(E16)),IF(OR(AND(C16>E16,RESULTADOS!C16>RESULTADOS!E16),AND(C16<E16,RESULTADOS!C16<RESULTADOS!E16)),1,IF(AND(C16=E16,RESULTADOS!C16=RESULTADOS!E16),2,0)),0) -> 0 | AA16: =IF(AND(ISNUMBER(RESULTADOS!C16),ISNUMBER(RESULTADOS!E16),ISNUMBER(C16),ISNUMBER(E16),AND(Z16=1,OR(C16=RESULTADOS!C16,E16=RESULTADOS!E16))),1,0) -> 0 | AB16: =IF( AND( ISNUMBER(RESULTADOS!C16), ISNUMBER(RESULTADOS!E16), ISNUMBER(C16), ISNUMBER(E16), AND(Z16=1,AA16=0,(RESULTADOS!C16-RESULTADOS!E16)=(C16-E16)) ), 1, 0 ) -> 0 | AC16: C14 | AD16: E16 | AE16: E18 | AF16: =IF(ISNUMBER(FIND("C", AC16, 1)), SUBSTITUTE(AC16, "C", "E"), SUBSTITUTE(AC16, "E", "C")) -> E14 | AG16: =IF(ISNUMBER(FIND("C", AD16, 1)), SUBSTITUTE(AD16, "C", "E"), SUBSTITUTE(AD16, "E", "C")) -> C16 | AH16: =IF(ISNUMBER(FIND("C", AE16, 1)), SUBSTITUTE(AE16, "C", "E"), SUBSTITUTE(AE16, "E", "C")) -> C18
B17: Suíça | D17: x | F17: Canadá | H17: 46197 | I17: 0.66666667 | K17: Suíça | L17: =SUM(IF(AND(ISNUMBER(INDIRECT($AC17)),INDIRECT($AC17)>INDIRECT($AF17)),3,IF(AND(ISNUMBER(INDIRECT($AC17)),INDIRECT($AC17)=INDIRECT($AF17)),1,0)),IF(AND(ISNUMBER(INDIRECT($AD17)),INDIRECT($AD17)>INDIRECT($AG17)),3,IF(AND(ISNUMBER(INDIRECT($AD17)),INDIRECT($AD17)=INDIRECT($AG17)),1,0)),IF(AND(ISNUMBER(INDIRECT($AE17)),INDIRECT($AE17)>INDIRECT($AH17)),3,IF(AND(ISNUMBER(INDIRECT($AE17)),INDIRECT($AE17)=INDIRECT($AH17)),1,0))) -> 0 | M17: =N17-O17 -> 0 | N17: =SUM(INDIRECT($AC17),INDIRECT($AD17),INDIRECT($AE17)) -> 0 | O17: =SUM(INDIRECT($AF17),INDIRECT($AG17),INDIRECT($AH17)) -> 0 | P17: =SUM(IF(AND(ISNUMBER(INDIRECT($AC17)),INDIRECT($AC17)>INDIRECT($AF17)),1,0),IF(AND(ISNUMBER(INDIRECT($AD17)),INDIRECT($AD17)>INDIRECT($AG17)),1,0),IF(AND(ISNUMBER(INDIRECT($AE17)),INDIRECT($AE17)>INDIRECT($AH17)),1,0)) -> 0 | Q17: =SUM(IF(AND(ISNUMBER(INDIRECT($AC17)),INDIRECT($AC17)=INDIRECT($AF17)),1,0),IF(AND(ISNUMBER(INDIRECT($AD17)),INDIRECT($AD17)=INDIRECT($AG17)),1,0),IF(AND(ISNUMBER(INDIRECT($AE17)),INDIRECT($AE17)=INDIRECT($AH17)),1,0)) -> 0 | R17: =SUM(IF(AND(ISNUMBER(INDIRECT($AC17)),INDIRECT($AC17)<INDIRECT($AF17)),1,0),IF(AND(ISNUMBER(INDIRECT($AD17)),INDIRECT($AD17)<INDIRECT($AG17)),1,0),IF(AND(ISNUMBER(INDIRECT($AE17)),INDIRECT($AE17)<INDIRECT($AH17)),1,0)) -> 0 | T17: =IF(NOT(AND(ISNUMBER(C17),ISNUMBER(E17))),"XXX","") -> XXX | U17: =SUM(Y17,Z17,AA17, AB17) -> 0 | Y17: =IF(AND(ISNUMBER(RESULTADOS!C17),ISNUMBER(RESULTADOS!E17),ISNUMBER(C17),ISNUMBER(E17),C17=RESULTADOS!C17,E17=RESULTADOS!E17),2,0) -> 0 | Z17: =IF(AND(ISNUMBER(RESULTADOS!C17),ISNUMBER(RESULTADOS!E17),ISNUMBER(C17),ISNUMBER(E17)),IF(OR(AND(C17>E17,RESULTADOS!C17>RESULTADOS!E17),AND(C17<E17,RESULTADOS!C17<RESULTADOS!E17)),1,IF(AND(C17=E17,RESULTADOS!C17=RESULTADOS!E17),2,0)),0) -> 0 | AA17: =IF(AND(ISNUMBER(RESULTADOS!C17),ISNUMBER(RESULTADOS!E17),ISNUMBER(C17),ISNUMBER(E17),AND(Z17=1,OR(C17=RESULTADOS!C17,E17=RESULTADOS!E17))),1,0) -> 0 | AB17: =IF( AND( ISNUMBER(RESULTADOS!C17), ISNUMBER(RESULTADOS!E17), ISNUMBER(C17), ISNUMBER(E17), AND(Z17=1,AA17=0,(RESULTADOS!C17-RESULTADOS!E17)=(C17-E17)) ), 1, 0 ) -> 0 | AC17: E14 | AD17: C15 | AE17: C17 | AF17: =IF(ISNUMBER(FIND("C", AC17, 1)), SUBSTITUTE(AC17, "C", "E"), SUBSTITUTE(AC17, "E", "C")) -> C14 | AG17: =IF(ISNUMBER(FIND("C", AD17, 1)), SUBSTITUTE(AD17, "C", "E"), SUBSTITUTE(AD17, "E", "C")) -> E15 | AH17: =IF(ISNUMBER(FIND("C", AE17, 1)), SUBSTITUTE(AE17, "C", "E"), SUBSTITUTE(AE17, "E", "C")) -> E17
B18: Bósnia | D18: x | F18: Catar | H18: 46197 | I18: 0.66666667 | T18: =IF(NOT(AND(ISNUMBER(C18),ISNUMBER(E18))),"XXX","") -> XXX | U18: =SUM(Y18,Z18,AA18, AB18) -> 0 | Y18: =IF(AND(ISNUMBER(RESULTADOS!C18),ISNUMBER(RESULTADOS!E18),ISNUMBER(C18),ISNUMBER(E18),C18=RESULTADOS!C18,E18=RESULTADOS!E18),2,0) -> 0 | Z18: =IF(AND(ISNUMBER(RESULTADOS!C18),ISNUMBER(RESULTADOS!E18),ISNUMBER(C18),ISNUMBER(E18)),IF(OR(AND(C18>E18,RESULTADOS!C18>RESULTADOS!E18),AND(C18<E18,RESULTADOS!C18<RESULTADOS!E18)),1,IF(AND(C18=E18,RESULTADOS!C18=RESULTADOS!E18),2,0)),0) -> 0 | AA18: =IF(AND(ISNUMBER(RESULTADOS!C18),ISNUMBER(RESULTADOS!E18),ISNUMBER(C18),ISNUMBER(E18),AND(Z18=1,OR(C18=RESULTADOS!C18,E18=RESULTADOS!E18))),1,0) -> 0 | AB18: =IF( AND( ISNUMBER(RESULTADOS!C18), ISNUMBER(RESULTADOS!E18), ISNUMBER(C18), ISNUMBER(E18), AND(Z18=1,AA18=0,(RESULTADOS!C18-RESULTADOS!E18)=(C18-E18)) ), 1, 0 ) -> 0
B20: GRUPO C | H20: DIA | I20: HORA
B21: Brasil | D21: x | F21: Marrocos | H21: 46186 | I21: 0.79166667 | L21: P | M21: SG | N21: GP | O21: GC | P21: V | Q21: E | R21: D | T21: =IF(NOT(AND(ISNUMBER(C21),ISNUMBER(E21))),"XXX","") -> XXX | U21: =SUM(Y21,Z21,AA21, AB21) -> 0 | Y21: =IF(AND(ISNUMBER(RESULTADOS!C21),ISNUMBER(RESULTADOS!E21),ISNUMBER(C21),ISNUMBER(E21),C21=RESULTADOS!C21,E21=RESULTADOS!E21),2,0) -> 0 | Z21: =IF(AND(ISNUMBER(RESULTADOS!C21),ISNUMBER(RESULTADOS!E21),ISNUMBER(C21),ISNUMBER(E21)),IF(OR(AND(C21>E21,RESULTADOS!C21>RESULTADOS!E21),AND(C21<E21,RESULTADOS!C21<RESULTADOS!E21)),1,IF(AND(C21=E21,RESULTADOS!C21=RESULTADOS!E21),2,0)),0) -> 0 | AA21: =IF(AND(ISNUMBER(RESULTADOS!C21),ISNUMBER(RESULTADOS!E21),ISNUMBER(C21),ISNUMBER(E21),AND(Z21=1,OR(C21=RESULTADOS!C21,E21=RESULTADOS!E21))),1,0) -> 0 | AB21: =IF( AND( ISNUMBER(RESULTADOS!C21), ISNUMBER(RESULTADOS!E21), ISNUMBER(C21), ISNUMBER(E21), AND(Z21=1,AA21=0,(RESULTADOS!C21-RESULTADOS!E21)=(C21-E21)) ), 1, 0 ) -> 0
B22: Haiti | D22: x | F22: Escócia | H22: 46186 | I22: 0.91666667 | K22: Brasil | L22: =SUM(IF(AND(ISNUMBER(INDIRECT($AC22)),INDIRECT($AC22)>INDIRECT($AF22)),3,IF(AND(ISNUMBER(INDIRECT($AC22)),INDIRECT($AC22)=INDIRECT($AF22)),1,0)),IF(AND(ISNUMBER(INDIRECT($AD22)),INDIRECT($AD22)>INDIRECT($AG22)),3,IF(AND(ISNUMBER(INDIRECT($AD22)),INDIRECT($AD22)=INDIRECT($AG22)),1,0)),IF(AND(ISNUMBER(INDIRECT($AE22)),INDIRECT($AE22)>INDIRECT($AH22)),3,IF(AND(ISNUMBER(INDIRECT($AE22)),INDIRECT($AE22)=INDIRECT($AH22)),1,0))) -> 0 | M22: =N22-O22 -> 0 | N22: =SUM(INDIRECT($AC22),INDIRECT($AD22),INDIRECT($AE22)) -> 0 | O22: =SUM(INDIRECT($AF22),INDIRECT($AG22),INDIRECT($AH22)) -> 0 | P22: =SUM(IF(AND(ISNUMBER(INDIRECT($AC22)),INDIRECT($AC22)>INDIRECT($AF22)),1,0),IF(AND(ISNUMBER(INDIRECT($AD22)),INDIRECT($AD22)>INDIRECT($AG22)),1,0),IF(AND(ISNUMBER(INDIRECT($AE22)),INDIRECT($AE22)>INDIRECT($AH22)),1,0)) -> 0 | Q22: =SUM(IF(AND(ISNUMBER(INDIRECT($AC22)),INDIRECT($AC22)=INDIRECT($AF22)),1,0),IF(AND(ISNUMBER(INDIRECT($AD22)),INDIRECT($AD22)=INDIRECT($AG22)),1,0),IF(AND(ISNUMBER(INDIRECT($AE22)),INDIRECT($AE22)=INDIRECT($AH22)),1,0)) -> 0 | R22: =SUM(IF(AND(ISNUMBER(INDIRECT($AC22)),INDIRECT($AC22)<INDIRECT($AF22)),1,0),IF(AND(ISNUMBER(INDIRECT($AD22)),INDIRECT($AD22)<INDIRECT($AG22)),1,0),IF(AND(ISNUMBER(INDIRECT($AE22)),INDIRECT($AE22)<INDIRECT($AH22)),1,0)) -> 0 | T22: =IF(NOT(AND(ISNUMBER(C22),ISNUMBER(E22))),"XXX","") -> XXX | U22: =SUM(Y22,Z22,AA22, AB22) -> 0 | Y22: =IF(AND(ISNUMBER(RESULTADOS!C22),ISNUMBER(RESULTADOS!E22),ISNUMBER(C22),ISNUMBER(E22),C22=RESULTADOS!C22,E22=RESULTADOS!E22),2,0) -> 0 | Z22: =IF(AND(ISNUMBER(RESULTADOS!C22),ISNUMBER(RESULTADOS!E22),ISNUMBER(C22),ISNUMBER(E22)),IF(OR(AND(C22>E22,RESULTADOS!C22>RESULTADOS!E22),AND(C22<E22,RESULTADOS!C22<RESULTADOS!E22)),1,IF(AND(C22=E22,RESULTADOS!C22=RESULTADOS!E22),2,0)),0) -> 0 | AA22: =IF(AND(ISNUMBER(RESULTADOS!C22),ISNUMBER(RESULTADOS!E22),ISNUMBER(C22),ISNUMBER(E22),AND(Z22=1,OR(C22=RESULTADOS!C22,E22=RESULTADOS!E22))),1,0) -> 0 | AB22: =IF( AND( ISNUMBER(RESULTADOS!C22), ISNUMBER(RESULTADOS!E22), ISNUMBER(C22), ISNUMBER(E22), AND(Z22=1,AA22=0,(RESULTADOS!C22-RESULTADOS!E22)=(C22-E22)) ), 1, 0 ) -> 0 | AC22: C21 | AD22: C24 | AE22: E26 | AF22: =IF(ISNUMBER(FIND("C", AC22, 1)), SUBSTITUTE(AC22, "C", "E"), SUBSTITUTE(AC22, "E", "C")) -> E21 | AG22: =IF(ISNUMBER(FIND("C", AD22, 1)), SUBSTITUTE(AD22, "C", "E"), SUBSTITUTE(AD22, "E", "C")) -> E24 | AH22: =IF(ISNUMBER(FIND("C", AE22, 1)), SUBSTITUTE(AE22, "C", "E"), SUBSTITUTE(AE22, "E", "C")) -> C26
B23: Escócia | D23: x | F23: Marrocos | H23: 46192 | I23: 0.79166667 | K23: Escócia | L23: =SUM(IF(AND(ISNUMBER(INDIRECT($AC23)),INDIRECT($AC23)>INDIRECT($AF23)),3,IF(AND(ISNUMBER(INDIRECT($AC23)),INDIRECT($AC23)=INDIRECT($AF23)),1,0)),IF(AND(ISNUMBER(INDIRECT($AD23)),INDIRECT($AD23)>INDIRECT($AG23)),3,IF(AND(ISNUMBER(INDIRECT($AD23)),INDIRECT($AD23)=INDIRECT($AG23)),1,0)),IF(AND(ISNUMBER(INDIRECT($AE23)),INDIRECT($AE23)>INDIRECT($AH23)),3,IF(AND(ISNUMBER(INDIRECT($AE23)),INDIRECT($AE23)=INDIRECT($AH23)),1,0))) -> 0 | M23: =N23-O23 -> 0 | N23: =SUM(INDIRECT($AC23),INDIRECT($AD23),INDIRECT($AE23)) -> 0 | O23: =SUM(INDIRECT($AF23),INDIRECT($AG23),INDIRECT($AH23)) -> 0 | P23: =SUM(IF(AND(ISNUMBER(INDIRECT($AC23)),INDIRECT($AC23)>INDIRECT($AF23)),1,0),IF(AND(ISNUMBER(INDIRECT($AD23)),INDIRECT($AD23)>INDIRECT($AG23)),1,0),IF(AND(ISNUMBER(INDIRECT($AE23)),INDIRECT($AE23)>INDIRECT($AH23)),1,0)) -> 0 | Q23: =SUM(IF(AND(ISNUMBER(INDIRECT($AC23)),INDIRECT($AC23)=INDIRECT($AF23)),1,0),IF(AND(ISNUMBER(INDIRECT($AD23)),INDIRECT($AD23)=INDIRECT($AG23)),1,0),IF(AND(ISNUMBER(INDIRECT($AE23)),INDIRECT($AE23)=INDIRECT($AH23)),1,0)) -> 0 | R23: =SUM(IF(AND(ISNUMBER(INDIRECT($AC23)),INDIRECT($AC23)<INDIRECT($AF23)),1,0),IF(AND(ISNUMBER(INDIRECT($AD23)),INDIRECT($AD23)<INDIRECT($AG23)),1,0),IF(AND(ISNUMBER(INDIRECT($AE23)),INDIRECT($AE23)<INDIRECT($AH23)),1,0)) -> 0 | T23: =IF(NOT(AND(ISNUMBER(C23),ISNUMBER(E23))),"XXX","") -> XXX | U23: =SUM(Y23,Z23,AA23, AB23) -> 0 | Y23: =IF(AND(ISNUMBER(RESULTADOS!C23),ISNUMBER(RESULTADOS!E23),ISNUMBER(C23),ISNUMBER(E23),C23=RESULTADOS!C23,E23=RESULTADOS!E23),2,0) -> 0 | Z23: =IF(AND(ISNUMBER(RESULTADOS!C23),ISNUMBER(RESULTADOS!E23),ISNUMBER(C23),ISNUMBER(E23)),IF(OR(AND(C23>E23,RESULTADOS!C23>RESULTADOS!E23),AND(C23<E23,RESULTADOS!C23<RESULTADOS!E23)),1,IF(AND(C23=E23,RESULTADOS!C23=RESULTADOS!E23),2,0)),0) -> 0 | AA23: =IF(AND(ISNUMBER(RESULTADOS!C23),ISNUMBER(RESULTADOS!E23),ISNUMBER(C23),ISNUMBER(E23),AND(Z23=1,OR(C23=RESULTADOS!C23,E23=RESULTADOS!E23))),1,0) -> 0 | AB23: =IF( AND( ISNUMBER(RESULTADOS!C23), ISNUMBER(RESULTADOS!E23), ISNUMBER(C23), ISNUMBER(E23), AND(Z23=1,AA23=0,(RESULTADOS!C23-RESULTADOS!E23)=(C23-E23)) ), 1, 0 ) -> 0 | AC23: E22 | AD23: C23 | AE23: C26 | AF23: =IF(ISNUMBER(FIND("C", AC23, 1)), SUBSTITUTE(AC23, "C", "E"), SUBSTITUTE(AC23, "E", "C")) -> C22 | AG23: =IF(ISNUMBER(FIND("C", AD23, 1)), SUBSTITUTE(AD23, "C", "E"), SUBSTITUTE(AD23, "E", "C")) -> E23 | AH23: =IF(ISNUMBER(FIND("C", AE23, 1)), SUBSTITUTE(AE23, "C", "E"), SUBSTITUTE(AE23, "E", "C")) -> E26
B24: Brasil | D24: x | F24: Haiti | H24: 46192 | I24: 0.89583333 | K24: Haiti | L24: =SUM(IF(AND(ISNUMBER(INDIRECT($AC24)),INDIRECT($AC24)>INDIRECT($AF24)),3,IF(AND(ISNUMBER(INDIRECT($AC24)),INDIRECT($AC24)=INDIRECT($AF24)),1,0)),IF(AND(ISNUMBER(INDIRECT($AD24)),INDIRECT($AD24)>INDIRECT($AG24)),3,IF(AND(ISNUMBER(INDIRECT($AD24)),INDIRECT($AD24)=INDIRECT($AG24)),1,0)),IF(AND(ISNUMBER(INDIRECT($AE24)),INDIRECT($AE24)>INDIRECT($AH24)),3,IF(AND(ISNUMBER(INDIRECT($AE24)),INDIRECT($AE24)=INDIRECT($AH24)),1,0))) -> 0 | M24: =N24-O24 -> 0 | N24: =SUM(INDIRECT($AC24),INDIRECT($AD24),INDIRECT($AE24)) -> 0 | O24: =SUM(INDIRECT($AF24),INDIRECT($AG24),INDIRECT($AH24)) -> 0 | P24: =SUM(IF(AND(ISNUMBER(INDIRECT($AC24)),INDIRECT($AC24)>INDIRECT($AF24)),1,0),IF(AND(ISNUMBER(INDIRECT($AD24)),INDIRECT($AD24)>INDIRECT($AG24)),1,0),IF(AND(ISNUMBER(INDIRECT($AE24)),INDIRECT($AE24)>INDIRECT($AH24)),1,0)) -> 0 | Q24: =SUM(IF(AND(ISNUMBER(INDIRECT($AC24)),INDIRECT($AC24)=INDIRECT($AF24)),1,0),IF(AND(ISNUMBER(INDIRECT($AD24)),INDIRECT($AD24)=INDIRECT($AG24)),1,0),IF(AND(ISNUMBER(INDIRECT($AE24)),INDIRECT($AE24)=INDIRECT($AH24)),1,0)) -> 0 | R24: =SUM(IF(AND(ISNUMBER(INDIRECT($AC24)),INDIRECT($AC24)<INDIRECT($AF24)),1,0),IF(AND(ISNUMBER(INDIRECT($AD24)),INDIRECT($AD24)<INDIRECT($AG24)),1,0),IF(AND(ISNUMBER(INDIRECT($AE24)),INDIRECT($AE24)<INDIRECT($AH24)),1,0)) -> 0 | T24: =IF(NOT(AND(ISNUMBER(C24),ISNUMBER(E24))),"XXX","") -> XXX | U24: =SUM(Y24,Z24,AA24, AB24) -> 0 | Y24: =IF(AND(ISNUMBER(RESULTADOS!C24),ISNUMBER(RESULTADOS!E24),ISNUMBER(C24),ISNUMBER(E24),C24=RESULTADOS!C24,E24=RESULTADOS!E24),2,0) -> 0 | Z24: =IF(AND(ISNUMBER(RESULTADOS!C24),ISNUMBER(RESULTADOS!E24),ISNUMBER(C24),ISNUMBER(E24)),IF(OR(AND(C24>E24,RESULTADOS!C24>RESULTADOS!E24),AND(C24<E24,RESULTADOS!C24<RESULTADOS!E24)),1,IF(AND(C24=E24,RESULTADOS!C24=RESULTADOS!E24),2,0)),0) -> 0 | AA24: =IF(AND(ISNUMBER(RESULTADOS!C24),ISNUMBER(RESULTADOS!E24),ISNUMBER(C24),ISNUMBER(E24),AND(Z24=1,OR(C24=RESULTADOS!C24,E24=RESULTADOS!E24))),1,0) -> 0 | AB24: =IF( AND( ISNUMBER(RESULTADOS!C24), ISNUMBER(RESULTADOS!E24), ISNUMBER(C24), ISNUMBER(E24), AND(Z24=1,AA24=0,(RESULTADOS!C24-RESULTADOS!E24)=(C24-E24)) ), 1, 0 ) -> 0 | AC24: C22 | AD24: E24 | AE24: E25 | AF24: =IF(ISNUMBER(FIND("C", AC24, 1)), SUBSTITUTE(AC24, "C", "E"), SUBSTITUTE(AC24, "E", "C")) -> E22 | AG24: =IF(ISNUMBER(FIND("C", AD24, 1)), SUBSTITUTE(AD24, "C", "E"), SUBSTITUTE(AD24, "E", "C")) -> C24 | AH24: =IF(ISNUMBER(FIND("C", AE24, 1)), SUBSTITUTE(AE24, "C", "E"), SUBSTITUTE(AE24, "E", "C")) -> C25
B25: Marrocos | D25: x | F25: Haiti | H25: 46197 | I25: 0.79166667 | K25: Marrocos | L25: =SUM(IF(AND(ISNUMBER(INDIRECT($AC25)),INDIRECT($AC25)>INDIRECT($AF25)),3,IF(AND(ISNUMBER(INDIRECT($AC25)),INDIRECT($AC25)=INDIRECT($AF25)),1,0)),IF(AND(ISNUMBER(INDIRECT($AD25)),INDIRECT($AD25)>INDIRECT($AG25)),3,IF(AND(ISNUMBER(INDIRECT($AD25)),INDIRECT($AD25)=INDIRECT($AG25)),1,0)),IF(AND(ISNUMBER(INDIRECT($AE25)),INDIRECT($AE25)>INDIRECT($AH25)),3,IF(AND(ISNUMBER(INDIRECT($AE25)),INDIRECT($AE25)=INDIRECT($AH25)),1,0))) -> 0 | M25: =N25-O25 -> 0 | N25: =SUM(INDIRECT($AC25),INDIRECT($AD25),INDIRECT($AE25)) -> 0 | O25: =SUM(INDIRECT($AF25),INDIRECT($AG25),INDIRECT($AH25)) -> 0 | P25: =SUM(IF(AND(ISNUMBER(INDIRECT($AC25)),INDIRECT($AC25)>INDIRECT($AF25)),1,0),IF(AND(ISNUMBER(INDIRECT($AD25)),INDIRECT($AD25)>INDIRECT($AG25)),1,0),IF(AND(ISNUMBER(INDIRECT($AE25)),INDIRECT($AE25)>INDIRECT($AH25)),1,0)) -> 0 | Q25: =SUM(IF(AND(ISNUMBER(INDIRECT($AC25)),INDIRECT($AC25)=INDIRECT($AF25)),1,0),IF(AND(ISNUMBER(INDIRECT($AD25)),INDIRECT($AD25)=INDIRECT($AG25)),1,0),IF(AND(ISNUMBER(INDIRECT($AE25)),INDIRECT($AE25)=INDIRECT($AH25)),1,0)) -> 0 | R25: =SUM(IF(AND(ISNUMBER(INDIRECT($AC25)),INDIRECT($AC25)<INDIRECT($AF25)),1,0),IF(AND(ISNUMBER(INDIRECT($AD25)),INDIRECT($AD25)<INDIRECT($AG25)),1,0),IF(AND(ISNUMBER(INDIRECT($AE25)),INDIRECT($AE25)<INDIRECT($AH25)),1,0)) -> 0 | T25: =IF(NOT(AND(ISNUMBER(C25),ISNUMBER(E25))),"XXX","") -> XXX | U25: =SUM(Y25,Z25,AA25, AB25) -> 0 | Y25: =IF(AND(ISNUMBER(RESULTADOS!C25),ISNUMBER(RESULTADOS!E25),ISNUMBER(C25),ISNUMBER(E25),C25=RESULTADOS!C25,E25=RESULTADOS!E25),2,0) -> 0 | Z25: =IF(AND(ISNUMBER(RESULTADOS!C25),ISNUMBER(RESULTADOS!E25),ISNUMBER(C25),ISNUMBER(E25)),IF(OR(AND(C25>E25,RESULTADOS!C25>RESULTADOS!E25),AND(C25<E25,RESULTADOS!C25<RESULTADOS!E25)),1,IF(AND(C25=E25,RESULTADOS!C25=RESULTADOS!E25),2,0)),0) -> 0 | AA25: =IF(AND(ISNUMBER(RESULTADOS!C25),ISNUMBER(RESULTADOS!E25),ISNUMBER(C25),ISNUMBER(E25),AND(Z25=1,OR(C25=RESULTADOS!C25,E25=RESULTADOS!E25))),1,0) -> 0 | AB25: =IF( AND( ISNUMBER(RESULTADOS!C25), ISNUMBER(RESULTADOS!E25), ISNUMBER(C25), ISNUMBER(E25), AND(Z25=1,AA25=0,(RESULTADOS!C25-RESULTADOS!E25)=(C25-E25)) ), 1, 0 ) -> 0 | AC25: E21 | AD25: E23 | AE25: C25 | AF25: =IF(ISNUMBER(FIND("C", AC25, 1)), SUBSTITUTE(AC25, "C", "E"), SUBSTITUTE(AC25, "E", "C")) -> C21 | AG25: =IF(ISNUMBER(FIND("C", AD25, 1)), SUBSTITUTE(AD25, "C", "E"), SUBSTITUTE(AD25, "E", "C")) -> C23 | AH25: =IF(ISNUMBER(FIND("C", AE25, 1)), SUBSTITUTE(AE25, "C", "E"), SUBSTITUTE(AE25, "E", "C")) -> E25
B26: Escócia | D26: x | F26: Brasil | H26: 46197 | I26: 0.79166667 | T26: =IF(NOT(AND(ISNUMBER(C26),ISNUMBER(E26))),"XXX","") -> XXX | U26: =SUM(Y26,Z26,AA26, AB26) -> 0 | Y26: =IF(AND(ISNUMBER(RESULTADOS!C26),ISNUMBER(RESULTADOS!E26),ISNUMBER(C26),ISNUMBER(E26),C26=RESULTADOS!C26,E26=RESULTADOS!E26),2,0) -> 0 | Z26: =IF(AND(ISNUMBER(RESULTADOS!C26),ISNUMBER(RESULTADOS!E26),ISNUMBER(C26),ISNUMBER(E26)),IF(OR(AND(C26>E26,RESULTADOS!C26>RESULTADOS!E26),AND(C26<E26,RESULTADOS!C26<RESULTADOS!E26)),1,IF(AND(C26=E26,RESULTADOS!C26=RESULTADOS!E26),2,0)),0) -> 0 | AA26: =IF(AND(ISNUMBER(RESULTADOS!C26),ISNUMBER(RESULTADOS!E26),ISNUMBER(C26),ISNUMBER(E26),AND(Z26=1,OR(C26=RESULTADOS!C26,E26=RESULTADOS!E26))),1,0) -> 0 | AB26: =IF( AND( ISNUMBER(RESULTADOS!C26), ISNUMBER(RESULTADOS!E26), ISNUMBER(C26), ISNUMBER(E26), AND(Z26=1,AA26=0,(RESULTADOS!C26-RESULTADOS!E26)=(C26-E26)) ), 1, 0 ) -> 0
B28: GRUPO D | H28: DIA | I28: HORA
B29: Estados Unidos | D29: x | F29: Paraguai | H29: 46185 | I29: 0.91666667 | L29: P | M29: SG | N29: GP | O29: GC | P29: V | Q29: E | R29: D | T29: =IF(NOT(AND(ISNUMBER(C29),ISNUMBER(E29))),"XXX","") -> XXX | U29: =SUM(Y29,Z29,AA29, AB29) -> 0 | Y29: =IF(AND(ISNUMBER(RESULTADOS!C29),ISNUMBER(RESULTADOS!E29),ISNUMBER(C29),ISNUMBER(E29),C29=RESULTADOS!C29,E29=RESULTADOS!E29),2,0) -> 0 | Z29: =IF(AND(ISNUMBER(RESULTADOS!C29),ISNUMBER(RESULTADOS!E29),ISNUMBER(C29),ISNUMBER(E29)),IF(OR(AND(C29>E29,RESULTADOS!C29>RESULTADOS!E29),AND(C29<E29,RESULTADOS!C29<RESULTADOS!E29)),1,IF(AND(C29=E29,RESULTADOS!C29=RESULTADOS!E29),2,0)),0) -> 0 | AA29: =IF(AND(ISNUMBER(RESULTADOS!C29),ISNUMBER(RESULTADOS!E29),ISNUMBER(C29),ISNUMBER(E29),AND(Z29=1,OR(C29=RESULTADOS!C29,E29=RESULTADOS!E29))),1,0) -> 0 | AB29: =IF( AND( ISNUMBER(RESULTADOS!C29), ISNUMBER(RESULTADOS!E29), ISNUMBER(C29), ISNUMBER(E29), AND(Z29=1,AA29=0,(RESULTADOS!C29-RESULTADOS!E29)=(C29-E29)) ), 1, 0 ) -> 0
B30: Austrália | D30: x | F30: Turquia | H30: 46187 | I30: 0.041666667 | K30: Austrália | L30: =SUM(IF(AND(ISNUMBER(INDIRECT($AC30)),INDIRECT($AC30)>INDIRECT($AF30)),3,IF(AND(ISNUMBER(INDIRECT($AC30)),INDIRECT($AC30)=INDIRECT($AF30)),1,0)),IF(AND(ISNUMBER(INDIRECT($AD30)),INDIRECT($AD30)>INDIRECT($AG30)),3,IF(AND(ISNUMBER(INDIRECT($AD30)),INDIRECT($AD30)=INDIRECT($AG30)),1,0)),IF(AND(ISNUMBER(INDIRECT($AE30)),INDIRECT($AE30)>INDIRECT($AH30)),3,IF(AND(ISNUMBER(INDIRECT($AE30)),INDIRECT($AE30)=INDIRECT($AH30)),1,0))) -> 0 | M30: =N30-O30 -> 0 | N30: =SUM(INDIRECT($AC30),INDIRECT($AD30),INDIRECT($AE30)) -> 0 | O30: =SUM(INDIRECT($AF30),INDIRECT($AG30),INDIRECT($AH30)) -> 0 | P30: =SUM(IF(AND(ISNUMBER(INDIRECT($AC30)),INDIRECT($AC30)>INDIRECT($AF30)),1,0),IF(AND(ISNUMBER(INDIRECT($AD30)),INDIRECT($AD30)>INDIRECT($AG30)),1,0),IF(AND(ISNUMBER(INDIRECT($AE30)),INDIRECT($AE30)>INDIRECT($AH30)),1,0)) -> 0 | Q30: =SUM(IF(AND(ISNUMBER(INDIRECT($AC30)),INDIRECT($AC30)=INDIRECT($AF30)),1,0),IF(AND(ISNUMBER(INDIRECT($AD30)),INDIRECT($AD30)=INDIRECT($AG30)),1,0),IF(AND(ISNUMBER(INDIRECT($AE30)),INDIRECT($AE30)=INDIRECT($AH30)),1,0)) -> 0 | R30: =SUM(IF(AND(ISNUMBER(INDIRECT($AC30)),INDIRECT($AC30)<INDIRECT($AF30)),1,0),IF(AND(ISNUMBER(INDIRECT($AD30)),INDIRECT($AD30)<INDIRECT($AG30)),1,0),IF(AND(ISNUMBER(INDIRECT($AE30)),INDIRECT($AE30)<INDIRECT($AH30)),1,0)) -> 0 | T30: =IF(NOT(AND(ISNUMBER(C30),ISNUMBER(E30))),"XXX","") -> XXX | U30: =SUM(Y30,Z30,AA30, AB30) -> 0 | Y30: =IF(AND(ISNUMBER(RESULTADOS!C30),ISNUMBER(RESULTADOS!E30),ISNUMBER(C30),ISNUMBER(E30),C30=RESULTADOS!C30,E30=RESULTADOS!E30),2,0) -> 0 | Z30: =IF(AND(ISNUMBER(RESULTADOS!C30),ISNUMBER(RESULTADOS!E30),ISNUMBER(C30),ISNUMBER(E30)),IF(OR(AND(C30>E30,RESULTADOS!C30>RESULTADOS!E30),AND(C30<E30,RESULTADOS!C30<RESULTADOS!E30)),1,IF(AND(C30=E30,RESULTADOS!C30=RESULTADOS!E30),2,0)),0) -> 0 | AA30: =IF(AND(ISNUMBER(RESULTADOS!C30),ISNUMBER(RESULTADOS!E30),ISNUMBER(C30),ISNUMBER(E30),AND(Z30=1,OR(C30=RESULTADOS!C30,E30=RESULTADOS!E30))),1,0) -> 0 | AB30: =IF( AND( ISNUMBER(RESULTADOS!C30), ISNUMBER(RESULTADOS!E30), ISNUMBER(C30), ISNUMBER(E30), AND(Z30=1,AA30=0,(RESULTADOS!C30-RESULTADOS!E30)=(C30-E30)) ), 1, 0 ) -> 0 | AC30: C30 | AD30: E31 | AE30: E34 | AF30: =IF(ISNUMBER(FIND("C", AC30, 1)), SUBSTITUTE(AC30, "C", "E"), SUBSTITUTE(AC30, "E", "C")) -> E30 | AG30: =IF(ISNUMBER(FIND("C", AD30, 1)), SUBSTITUTE(AD30, "C", "E"), SUBSTITUTE(AD30, "E", "C")) -> C31 | AH30: =IF(ISNUMBER(FIND("C", AE30, 1)), SUBSTITUTE(AE30, "C", "E"), SUBSTITUTE(AE30, "E", "C")) -> C34
B31: Estados Unidos | D31: x | F31: Austrália | H31: 46192 | I31: 0.66666667 | K31: Estados Unidos | L31: =SUM(IF(AND(ISNUMBER(INDIRECT($AC31)),INDIRECT($AC31)>INDIRECT($AF31)),3,IF(AND(ISNUMBER(INDIRECT($AC31)),INDIRECT($AC31)=INDIRECT($AF31)),1,0)),IF(AND(ISNUMBER(INDIRECT($AD31)),INDIRECT($AD31)>INDIRECT($AG31)),3,IF(AND(ISNUMBER(INDIRECT($AD31)),INDIRECT($AD31)=INDIRECT($AG31)),1,0)),IF(AND(ISNUMBER(INDIRECT($AE31)),INDIRECT($AE31)>INDIRECT($AH31)),3,IF(AND(ISNUMBER(INDIRECT($AE31)),INDIRECT($AE31)=INDIRECT($AH31)),1,0))) -> 0 | M31: =N31-O31 -> 0 | N31: =SUM(INDIRECT($AC31),INDIRECT($AD31),INDIRECT($AE31)) -> 0 | O31: =SUM(INDIRECT($AF31),INDIRECT($AG31),INDIRECT($AH31)) -> 0 | P31: =SUM(IF(AND(ISNUMBER(INDIRECT($AC31)),INDIRECT($AC31)>INDIRECT($AF31)),1,0),IF(AND(ISNUMBER(INDIRECT($AD31)),INDIRECT($AD31)>INDIRECT($AG31)),1,0),IF(AND(ISNUMBER(INDIRECT($AE31)),INDIRECT($AE31)>INDIRECT($AH31)),1,0)) -> 0 | Q31: =SUM(IF(AND(ISNUMBER(INDIRECT($AC31)),INDIRECT($AC31)=INDIRECT($AF31)),1,0),IF(AND(ISNUMBER(INDIRECT($AD31)),INDIRECT($AD31)=INDIRECT($AG31)),1,0),IF(AND(ISNUMBER(INDIRECT($AE31)),INDIRECT($AE31)=INDIRECT($AH31)),1,0)) -> 0 | R31: =SUM(IF(AND(ISNUMBER(INDIRECT($AC31)),INDIRECT($AC31)<INDIRECT($AF31)),1,0),IF(AND(ISNUMBER(INDIRECT($AD31)),INDIRECT($AD31)<INDIRECT($AG31)),1,0),IF(AND(ISNUMBER(INDIRECT($AE31)),INDIRECT($AE31)<INDIRECT($AH31)),1,0)) -> 0 | T31: =IF(NOT(AND(ISNUMBER(C31),ISNUMBER(E31))),"XXX","") -> XXX | U31: =SUM(Y31,Z31,AA31, AB31) -> 0 | Y31: =IF(AND(ISNUMBER(RESULTADOS!C31),ISNUMBER(RESULTADOS!E31),ISNUMBER(C31),ISNUMBER(E31),C31=RESULTADOS!C31,E31=RESULTADOS!E31),2,0) -> 0 | Z31: =IF(AND(ISNUMBER(RESULTADOS!C31),ISNUMBER(RESULTADOS!E31),ISNUMBER(C31),ISNUMBER(E31)),IF(OR(AND(C31>E31,RESULTADOS!C31>RESULTADOS!E31),AND(C31<E31,RESULTADOS!C31<RESULTADOS!E31)),1,IF(AND(C31=E31,RESULTADOS!C31=RESULTADOS!E31),2,0)),0) -> 0 | AA31: =IF(AND(ISNUMBER(RESULTADOS!C31),ISNUMBER(RESULTADOS!E31),ISNUMBER(C31),ISNUMBER(E31),AND(Z31=1,OR(C31=RESULTADOS!C31,E31=RESULTADOS!E31))),1,0) -> 0 | AB31: =IF( AND( ISNUMBER(RESULTADOS!C31), ISNUMBER(RESULTADOS!E31), ISNUMBER(C31), ISNUMBER(E31), AND(Z31=1,AA31=0,(RESULTADOS!C31-RESULTADOS!E31)=(C31-E31)) ), 1, 0 ) -> 0 | AC31: C29 | AD31: C31 | AE31: E33 | AF31: =IF(ISNUMBER(FIND("C", AC31, 1)), SUBSTITUTE(AC31, "C", "E"), SUBSTITUTE(AC31, "E", "C")) -> E29 | AG31: =IF(ISNUMBER(FIND("C", AD31, 1)), SUBSTITUTE(AD31, "C", "E"), SUBSTITUTE(AD31, "E", "C")) -> E31 | AH31: =IF(ISNUMBER(FIND("C", AE31, 1)), SUBSTITUTE(AE31, "C", "E"), SUBSTITUTE(AE31, "E", "C")) -> C33
B32: Turquia | D32: x | F32: Paraguai | H32: 46193 | I32: 0.041666667 | K32: Paraguai | L32: =SUM(IF(AND(ISNUMBER(INDIRECT($AC32)),INDIRECT($AC32)>INDIRECT($AF32)),3,IF(AND(ISNUMBER(INDIRECT($AC32)),INDIRECT($AC32)=INDIRECT($AF32)),1,0)),IF(AND(ISNUMBER(INDIRECT($AD32)),INDIRECT($AD32)>INDIRECT($AG32)),3,IF(AND(ISNUMBER(INDIRECT($AD32)),INDIRECT($AD32)=INDIRECT($AG32)),1,0)),IF(AND(ISNUMBER(INDIRECT($AE32)),INDIRECT($AE32)>INDIRECT($AH32)),3,IF(AND(ISNUMBER(INDIRECT($AE32)),INDIRECT($AE32)=INDIRECT($AH32)),1,0))) -> 0 | M32: =N32-O32 -> 0 | N32: =SUM(INDIRECT($AC32),INDIRECT($AD32),INDIRECT($AE32)) -> 0 | O32: =SUM(INDIRECT($AF32),INDIRECT($AG32),INDIRECT($AH32)) -> 0 | P32: =SUM(IF(AND(ISNUMBER(INDIRECT($AC32)),INDIRECT($AC32)>INDIRECT($AF32)),1,0),IF(AND(ISNUMBER(INDIRECT($AD32)),INDIRECT($AD32)>INDIRECT($AG32)),1,0),IF(AND(ISNUMBER(INDIRECT($AE32)),INDIRECT($AE32)>INDIRECT($AH32)),1,0)) -> 0 | Q32: =SUM(IF(AND(ISNUMBER(INDIRECT($AC32)),INDIRECT($AC32)=INDIRECT($AF32)),1,0),IF(AND(ISNUMBER(INDIRECT($AD32)),INDIRECT($AD32)=INDIRECT($AG32)),1,0),IF(AND(ISNUMBER(INDIRECT($AE32)),INDIRECT($AE32)=INDIRECT($AH32)),1,0)) -> 0 | R32: =SUM(IF(AND(ISNUMBER(INDIRECT($AC32)),INDIRECT($AC32)<INDIRECT($AF32)),1,0),IF(AND(ISNUMBER(INDIRECT($AD32)),INDIRECT($AD32)<INDIRECT($AG32)),1,0),IF(AND(ISNUMBER(INDIRECT($AE32)),INDIRECT($AE32)<INDIRECT($AH32)),1,0)) -> 0 | T32: =IF(NOT(AND(ISNUMBER(C32),ISNUMBER(E32))),"XXX","") -> XXX | U32: =SUM(Y32,Z32,AA32, AB32) -> 0 | Y32: =IF(AND(ISNUMBER(RESULTADOS!C32),ISNUMBER(RESULTADOS!E32),ISNUMBER(C32),ISNUMBER(E32),C32=RESULTADOS!C32,E32=RESULTADOS!E32),2,0) -> 0 | Z32: =IF(AND(ISNUMBER(RESULTADOS!C32),ISNUMBER(RESULTADOS!E32),ISNUMBER(C32),ISNUMBER(E32)),IF(OR(AND(C32>E32,RESULTADOS!C32>RESULTADOS!E32),AND(C32<E32,RESULTADOS!C32<RESULTADOS!E32)),1,IF(AND(C32=E32,RESULTADOS!C32=RESULTADOS!E32),2,0)),0) -> 0 | AA32: =IF(AND(ISNUMBER(RESULTADOS!C32),ISNUMBER(RESULTADOS!E32),ISNUMBER(C32),ISNUMBER(E32),AND(Z32=1,OR(C32=RESULTADOS!C32,E32=RESULTADOS!E32))),1,0) -> 0 | AB32: =IF( AND( ISNUMBER(RESULTADOS!C32), ISNUMBER(RESULTADOS!E32), ISNUMBER(C32), ISNUMBER(E32), AND(Z32=1,AA32=0,(RESULTADOS!C32-RESULTADOS!E32)=(C32-E32)) ), 1, 0 ) -> 0 | AC32: E29 | AD32: E32 | AE32: E34 | AF32: =IF(ISNUMBER(FIND("C", AC32, 1)), SUBSTITUTE(AC32, "C", "E"), SUBSTITUTE(AC32, "E", "C")) -> C29 | AG32: =IF(ISNUMBER(FIND("C", AD32, 1)), SUBSTITUTE(AD32, "C", "E"), SUBSTITUTE(AD32, "E", "C")) -> C32 | AH32: =IF(ISNUMBER(FIND("C", AE32, 1)), SUBSTITUTE(AE32, "C", "E"), SUBSTITUTE(AE32, "E", "C")) -> C34
B33: Turquia | D33: x | F33: Estados Unidos | H33: 46198 | I33: 0.95833333 | K33: Turquia | L33: =SUM(IF(AND(ISNUMBER(INDIRECT($AC33)),INDIRECT($AC33)>INDIRECT($AF33)),3,IF(AND(ISNUMBER(INDIRECT($AC33)),INDIRECT($AC33)=INDIRECT($AF33)),1,0)),IF(AND(ISNUMBER(INDIRECT($AD33)),INDIRECT($AD33)>INDIRECT($AG33)),3,IF(AND(ISNUMBER(INDIRECT($AD33)),INDIRECT($AD33)=INDIRECT($AG33)),1,0)),IF(AND(ISNUMBER(INDIRECT($AE33)),INDIRECT($AE33)>INDIRECT($AH33)),3,IF(AND(ISNUMBER(INDIRECT($AE33)),INDIRECT($AE33)=INDIRECT($AH33)),1,0))) -> 0 | M33: =N33-O33 -> 0 | N33: =SUM(INDIRECT($AC33),INDIRECT($AD33),INDIRECT($AE33)) -> 0 | O33: =SUM(INDIRECT($AF33),INDIRECT($AG33),INDIRECT($AH33)) -> 0 | P33: =SUM(IF(AND(ISNUMBER(INDIRECT($AC33)),INDIRECT($AC33)>INDIRECT($AF33)),1,0),IF(AND(ISNUMBER(INDIRECT($AD33)),INDIRECT($AD33)>INDIRECT($AG33)),1,0),IF(AND(ISNUMBER(INDIRECT($AE33)),INDIRECT($AE33)>INDIRECT($AH33)),1,0)) -> 0 | Q33: =SUM(IF(AND(ISNUMBER(INDIRECT($AC33)),INDIRECT($AC33)=INDIRECT($AF33)),1,0),IF(AND(ISNUMBER(INDIRECT($AD33)),INDIRECT($AD33)=INDIRECT($AG33)),1,0),IF(AND(ISNUMBER(INDIRECT($AE33)),INDIRECT($AE33)=INDIRECT($AH33)),1,0)) -> 0 | R33: =SUM(IF(AND(ISNUMBER(INDIRECT($AC33)),INDIRECT($AC33)<INDIRECT($AF33)),1,0),IF(AND(ISNUMBER(INDIRECT($AD33)),INDIRECT($AD33)<INDIRECT($AG33)),1,0),IF(AND(ISNUMBER(INDIRECT($AE33)),INDIRECT($AE33)<INDIRECT($AH33)),1,0)) -> 0 | T33: =IF(NOT(AND(ISNUMBER(C33),ISNUMBER(E33))),"XXX","") -> XXX | U33: =SUM(Y33,Z33,AA33, AB33) -> 0 | Y33: =IF(AND(ISNUMBER(RESULTADOS!C33),ISNUMBER(RESULTADOS!E33),ISNUMBER(C33),ISNUMBER(E33),C33=RESULTADOS!C33,E33=RESULTADOS!E33),2,0) -> 0 | Z33: =IF(AND(ISNUMBER(RESULTADOS!C33),ISNUMBER(RESULTADOS!E33),ISNUMBER(C33),ISNUMBER(E33)),IF(OR(AND(C33>E33,RESULTADOS!C33>RESULTADOS!E33),AND(C33<E33,RESULTADOS!C33<RESULTADOS!E33)),1,IF(AND(C33=E33,RESULTADOS!C33=RESULTADOS!E33),2,0)),0) -> 0 | AA33: =IF(AND(ISNUMBER(RESULTADOS!C33),ISNUMBER(RESULTADOS!E33),ISNUMBER(C33),ISNUMBER(E33),AND(Z33=1,OR(C33=RESULTADOS!C33,E33=RESULTADOS!E33))),1,0) -> 0 | AB33: =IF( AND( ISNUMBER(RESULTADOS!C33), ISNUMBER(RESULTADOS!E33), ISNUMBER(C33), ISNUMBER(E33), AND(Z33=1,AA33=0,(RESULTADOS!C33-RESULTADOS!E33)=(C33-E33)) ), 1, 0 ) -> 0 | AC33: E30 | AD33: C32 | AE33: C33 | AF33: =IF(ISNUMBER(FIND("C", AC33, 1)), SUBSTITUTE(AC33, "C", "E"), SUBSTITUTE(AC33, "E", "C")) -> C30 | AG33: =IF(ISNUMBER(FIND("C", AD33, 1)), SUBSTITUTE(AD33, "C", "E"), SUBSTITUTE(AD33, "E", "C")) -> E32 | AH33: =IF(ISNUMBER(FIND("C", AE33, 1)), SUBSTITUTE(AE33, "C", "E"), SUBSTITUTE(AE33, "E", "C")) -> E33
B34: Paraguai | D34: x | F34: Austrália | H34: 46198 | I34: 0.95833333 | T34: =IF(NOT(AND(ISNUMBER(C34),ISNUMBER(E34))),"XXX","") -> XXX | U34: =SUM(Y34,Z34,AA34, AB34) -> 0 | Y34: =IF(AND(ISNUMBER(RESULTADOS!C34),ISNUMBER(RESULTADOS!E34),ISNUMBER(C34),ISNUMBER(E34),C34=RESULTADOS!C34,E34=RESULTADOS!E34),2,0) -> 0 | Z34: =IF(AND(ISNUMBER(RESULTADOS!C34),ISNUMBER(RESULTADOS!E34),ISNUMBER(C34),ISNUMBER(E34)),IF(OR(AND(C34>E34,RESULTADOS!C34>RESULTADOS!E34),AND(C34<E34,RESULTADOS!C34<RESULTADOS!E34)),1,IF(AND(C34=E34,RESULTADOS!C34=RESULTADOS!E34),2,0)),0) -> 0 | AA34: =IF(AND(ISNUMBER(RESULTADOS!C34),ISNUMBER(RESULTADOS!E34),ISNUMBER(C34),ISNUMBER(E34),AND(Z34=1,OR(C34=RESULTADOS!C34,E34=RESULTADOS!E34))),1,0) -> 0 | AB34: =IF( AND( ISNUMBER(RESULTADOS!C34), ISNUMBER(RESULTADOS!E34), ISNUMBER(C34), ISNUMBER(E34), AND(Z34=1,AA34=0,(RESULTADOS!C34-RESULTADOS!E34)=(C34-E34)) ), 1, 0 ) -> 0
B36: GRUPO E | H36: DIA | I36: HORA
B37: Alemanha | D37: x | F37: Curaçao | H37: 46187 | I37: 0.58333333 | L37: P | M37: SG | N37: GP | O37: GC | P37: V | Q37: E | R37: D | T37: =IF(NOT(AND(ISNUMBER(C37),ISNUMBER(E37))),"XXX","") -> XXX | U37: =SUM(Y37,Z37,AA37, AB37) -> 0 | Y37: =IF(AND(ISNUMBER(RESULTADOS!C37),ISNUMBER(RESULTADOS!E37),ISNUMBER(C37),ISNUMBER(E37),C37=RESULTADOS!C37,E37=RESULTADOS!E37),2,0) -> 0 | Z37: =IF(AND(ISNUMBER(RESULTADOS!C37),ISNUMBER(RESULTADOS!E37),ISNUMBER(C37),ISNUMBER(E37)),IF(OR(AND(C37>E37,RESULTADOS!C37>RESULTADOS!E37),AND(C37<E37,RESULTADOS!C37<RESULTADOS!E37)),1,IF(AND(C37=E37,RESULTADOS!C37=RESULTADOS!E37),2,0)),0) -> 0 | AA37: =IF(AND(ISNUMBER(RESULTADOS!C37),ISNUMBER(RESULTADOS!E37),ISNUMBER(C37),ISNUMBER(E37),AND(Z37=1,OR(C37=RESULTADOS!C37,E37=RESULTADOS!E37))),1,0) -> 0 | AB37: =IF( AND( ISNUMBER(RESULTADOS!C37), ISNUMBER(RESULTADOS!E37), ISNUMBER(C37), ISNUMBER(E37), AND(Z37=1,AA37=0,(RESULTADOS!C37-RESULTADOS!E37)=(C37-E37)) ), 1, 0 ) -> 0
B38: Costa do Marfim | D38: x | F38: Equador | H38: 46187 | I38: 0.83333333 | K38: Alemanha | L38: =SUM(IF(AND(ISNUMBER(INDIRECT($AC38)),INDIRECT($AC38)>INDIRECT($AF38)),3,IF(AND(ISNUMBER(INDIRECT($AC38)),INDIRECT($AC38)=INDIRECT($AF38)),1,0)),IF(AND(ISNUMBER(INDIRECT($AD38)),INDIRECT($AD38)>INDIRECT($AG38)),3,IF(AND(ISNUMBER(INDIRECT($AD38)),INDIRECT($AD38)=INDIRECT($AG38)),1,0)),IF(AND(ISNUMBER(INDIRECT($AE38)),INDIRECT($AE38)>INDIRECT($AH38)),3,IF(AND(ISNUMBER(INDIRECT($AE38)),INDIRECT($AE38)=INDIRECT($AH38)),1,0))) -> 0 | M38: =N38-O38 -> 0 | N38: =SUM(INDIRECT($AC38),INDIRECT($AD38),INDIRECT($AE38)) -> 0 | O38: =SUM(INDIRECT($AF38),INDIRECT($AG38),INDIRECT($AH38)) -> 0 | P38: =SUM(IF(AND(ISNUMBER(INDIRECT($AC38)),INDIRECT($AC38)>INDIRECT($AF38)),1,0),IF(AND(ISNUMBER(INDIRECT($AD38)),INDIRECT($AD38)>INDIRECT($AG38)),1,0),IF(AND(ISNUMBER(INDIRECT($AE38)),INDIRECT($AE38)>INDIRECT($AH38)),1,0)) -> 0 | Q38: =SUM(IF(AND(ISNUMBER(INDIRECT($AC38)),INDIRECT($AC38)=INDIRECT($AF38)),1,0),IF(AND(ISNUMBER(INDIRECT($AD38)),INDIRECT($AD38)=INDIRECT($AG38)),1,0),IF(AND(ISNUMBER(INDIRECT($AE38)),INDIRECT($AE38)=INDIRECT($AH38)),1,0)) -> 0 | R38: =SUM(IF(AND(ISNUMBER(INDIRECT($AC38)),INDIRECT($AC38)<INDIRECT($AF38)),1,0),IF(AND(ISNUMBER(INDIRECT($AD38)),INDIRECT($AD38)<INDIRECT($AG38)),1,0),IF(AND(ISNUMBER(INDIRECT($AE38)),INDIRECT($AE38)<INDIRECT($AH38)),1,0)) -> 0 | T38: =IF(NOT(AND(ISNUMBER(C38),ISNUMBER(E38))),"XXX","") -> XXX | U38: =SUM(Y38,Z38,AA38, AB38) -> 0 | Y38: =IF(AND(ISNUMBER(RESULTADOS!C38),ISNUMBER(RESULTADOS!E38),ISNUMBER(C38),ISNUMBER(E38),C38=RESULTADOS!C38,E38=RESULTADOS!E38),2,0) -> 0 | Z38: =IF(AND(ISNUMBER(RESULTADOS!C38),ISNUMBER(RESULTADOS!E38),ISNUMBER(C38),ISNUMBER(E38)),IF(OR(AND(C38>E38,RESULTADOS!C38>RESULTADOS!E38),AND(C38<E38,RESULTADOS!C38<RESULTADOS!E38)),1,IF(AND(C38=E38,RESULTADOS!C38=RESULTADOS!E38),2,0)),0) -> 0 | AA38: =IF(AND(ISNUMBER(RESULTADOS!C38),ISNUMBER(RESULTADOS!E38),ISNUMBER(C38),ISNUMBER(E38),AND(Z38=1,OR(C38=RESULTADOS!C38,E38=RESULTADOS!E38))),1,0) -> 0 | AB38: =IF( AND( ISNUMBER(RESULTADOS!C38), ISNUMBER(RESULTADOS!E38), ISNUMBER(C38), ISNUMBER(E38), AND(Z38=1,AA38=0,(RESULTADOS!C38-RESULTADOS!E38)=(C38-E38)) ), 1, 0 ) -> 0 | AC38: C37 | AD38: C39 | AE38: E41 | AF38: =IF(ISNUMBER(FIND("C", AC38, 1)), SUBSTITUTE(AC38, "C", "E"), SUBSTITUTE(AC38, "E", "C")) -> E37 | AG38: =IF(ISNUMBER(FIND("C", AD38, 1)), SUBSTITUTE(AD38, "C", "E"), SUBSTITUTE(AD38, "E", "C")) -> E39 | AH38: =IF(ISNUMBER(FIND("C", AE38, 1)), SUBSTITUTE(AE38, "C", "E"), SUBSTITUTE(AE38, "E", "C")) -> C41
B39: Alemanha | D39: x | F39: Costa do Marfim | H39: 46193 | I39: 0.70833333 | K39: Costa do Marfim | L39: =SUM(IF(AND(ISNUMBER(INDIRECT($AC39)),INDIRECT($AC39)>INDIRECT($AF39)),3,IF(AND(ISNUMBER(INDIRECT($AC39)),INDIRECT($AC39)=INDIRECT($AF39)),1,0)),IF(AND(ISNUMBER(INDIRECT($AD39)),INDIRECT($AD39)>INDIRECT($AG39)),3,IF(AND(ISNUMBER(INDIRECT($AD39)),INDIRECT($AD39)=INDIRECT($AG39)),1,0)),IF(AND(ISNUMBER(INDIRECT($AE39)),INDIRECT($AE39)>INDIRECT($AH39)),3,IF(AND(ISNUMBER(INDIRECT($AE39)),INDIRECT($AE39)=INDIRECT($AH39)),1,0))) -> 0 | M39: =N39-O39 -> 0 | N39: =SUM(INDIRECT($AC39),INDIRECT($AD39),INDIRECT($AE39)) -> 0 | O39: =SUM(INDIRECT($AF39),INDIRECT($AG39),INDIRECT($AH39)) -> 0 | P39: =SUM(IF(AND(ISNUMBER(INDIRECT($AC39)),INDIRECT($AC39)>INDIRECT($AF39)),1,0),IF(AND(ISNUMBER(INDIRECT($AD39)),INDIRECT($AD39)>INDIRECT($AG39)),1,0),IF(AND(ISNUMBER(INDIRECT($AE39)),INDIRECT($AE39)>INDIRECT($AH39)),1,0)) -> 0 | Q39: =SUM(IF(AND(ISNUMBER(INDIRECT($AC39)),INDIRECT($AC39)=INDIRECT($AF39)),1,0),IF(AND(ISNUMBER(INDIRECT($AD39)),INDIRECT($AD39)=INDIRECT($AG39)),1,0),IF(AND(ISNUMBER(INDIRECT($AE39)),INDIRECT($AE39)=INDIRECT($AH39)),1,0)) -> 0 | R39: =SUM(IF(AND(ISNUMBER(INDIRECT($AC39)),INDIRECT($AC39)<INDIRECT($AF39)),1,0),IF(AND(ISNUMBER(INDIRECT($AD39)),INDIRECT($AD39)<INDIRECT($AG39)),1,0),IF(AND(ISNUMBER(INDIRECT($AE39)),INDIRECT($AE39)<INDIRECT($AH39)),1,0)) -> 0 | T39: =IF(NOT(AND(ISNUMBER(C39),ISNUMBER(E39))),"XXX","") -> XXX | U39: =SUM(Y39,Z39,AA39, AB39) -> 0 | Y39: =IF(AND(ISNUMBER(RESULTADOS!C39),ISNUMBER(RESULTADOS!E39),ISNUMBER(C39),ISNUMBER(E39),C39=RESULTADOS!C39,E39=RESULTADOS!E39),2,0) -> 0 | Z39: =IF(AND(ISNUMBER(RESULTADOS!C39),ISNUMBER(RESULTADOS!E39),ISNUMBER(C39),ISNUMBER(E39)),IF(OR(AND(C39>E39,RESULTADOS!C39>RESULTADOS!E39),AND(C39<E39,RESULTADOS!C39<RESULTADOS!E39)),1,IF(AND(C39=E39,RESULTADOS!C39=RESULTADOS!E39),2,0)),0) -> 0 | AA39: =IF(AND(ISNUMBER(RESULTADOS!C39),ISNUMBER(RESULTADOS!E39),ISNUMBER(C39),ISNUMBER(E39),AND(Z39=1,OR(C39=RESULTADOS!C39,E39=RESULTADOS!E39))),1,0) -> 0 | AB39: =IF( AND( ISNUMBER(RESULTADOS!C39), ISNUMBER(RESULTADOS!E39), ISNUMBER(C39), ISNUMBER(E39), AND(Z39=1,AA39=0,(RESULTADOS!C39-RESULTADOS!E39)=(C39-E39)) ), 1, 0 ) -> 0 | AC39: C38 | AD39: E39 | AE39: E42 | AF39: =IF(ISNUMBER(FIND("C", AC39, 1)), SUBSTITUTE(AC39, "C", "E"), SUBSTITUTE(AC39, "E", "C")) -> E38 | AG39: =IF(ISNUMBER(FIND("C", AD39, 1)), SUBSTITUTE(AD39, "C", "E"), SUBSTITUTE(AD39, "E", "C")) -> C39 | AH39: =IF(ISNUMBER(FIND("C", AE39, 1)), SUBSTITUTE(AE39, "C", "E"), SUBSTITUTE(AE39, "E", "C")) -> C42
B40: Equador | D40: x | F40: Curaçao | H40: 46193 | I40: 0.875 | K40: Curaçao | L40: =SUM(IF(AND(ISNUMBER(INDIRECT($AC40)),INDIRECT($AC40)>INDIRECT($AF40)),3,IF(AND(ISNUMBER(INDIRECT($AC40)),INDIRECT($AC40)=INDIRECT($AF40)),1,0)),IF(AND(ISNUMBER(INDIRECT($AD40)),INDIRECT($AD40)>INDIRECT($AG40)),3,IF(AND(ISNUMBER(INDIRECT($AD40)),INDIRECT($AD40)=INDIRECT($AG40)),1,0)),IF(AND(ISNUMBER(INDIRECT($AE40)),INDIRECT($AE40)>INDIRECT($AH40)),3,IF(AND(ISNUMBER(INDIRECT($AE40)),INDIRECT($AE40)=INDIRECT($AH40)),1,0))) -> 0 | M40: =N40-O40 -> 0 | N40: =SUM(INDIRECT($AC40),INDIRECT($AD40),INDIRECT($AE40)) -> 0 | O40: =SUM(INDIRECT($AF40),INDIRECT($AG40),INDIRECT($AH40)) -> 0 | P40: =SUM(IF(AND(ISNUMBER(INDIRECT($AC40)),INDIRECT($AC40)>INDIRECT($AF40)),1,0),IF(AND(ISNUMBER(INDIRECT($AD40)),INDIRECT($AD40)>INDIRECT($AG40)),1,0),IF(AND(ISNUMBER(INDIRECT($AE40)),INDIRECT($AE40)>INDIRECT($AH40)),1,0)) -> 0 | Q40: =SUM(IF(AND(ISNUMBER(INDIRECT($AC40)),INDIRECT($AC40)=INDIRECT($AF40)),1,0),IF(AND(ISNUMBER(INDIRECT($AD40)),INDIRECT($AD40)=INDIRECT($AG40)),1,0),IF(AND(ISNUMBER(INDIRECT($AE40)),INDIRECT($AE40)=INDIRECT($AH40)),1,0)) -> 0 | R40: =SUM(IF(AND(ISNUMBER(INDIRECT($AC40)),INDIRECT($AC40)<INDIRECT($AF40)),1,0),IF(AND(ISNUMBER(INDIRECT($AD40)),INDIRECT($AD40)<INDIRECT($AG40)),1,0),IF(AND(ISNUMBER(INDIRECT($AE40)),INDIRECT($AE40)<INDIRECT($AH40)),1,0)) -> 0 | T40: =IF(NOT(AND(ISNUMBER(C40),ISNUMBER(E40))),"XXX","") -> XXX | U40: =SUM(Y40,Z40,AA40, AB40) -> 0 | Y40: =IF(AND(ISNUMBER(RESULTADOS!C40),ISNUMBER(RESULTADOS!E40),ISNUMBER(C40),ISNUMBER(E40),C40=RESULTADOS!C40,E40=RESULTADOS!E40),2,0) -> 0 | Z40: =IF(AND(ISNUMBER(RESULTADOS!C40),ISNUMBER(RESULTADOS!E40),ISNUMBER(C40),ISNUMBER(E40)),IF(OR(AND(C40>E40,RESULTADOS!C40>RESULTADOS!E40),AND(C40<E40,RESULTADOS!C40<RESULTADOS!E40)),1,IF(AND(C40=E40,RESULTADOS!C40=RESULTADOS!E40),2,0)),0) -> 0 | AA40: =IF(AND(ISNUMBER(RESULTADOS!C40),ISNUMBER(RESULTADOS!E40),ISNUMBER(C40),ISNUMBER(E40),AND(Z40=1,OR(C40=RESULTADOS!C40,E40=RESULTADOS!E40))),1,0) -> 0 | AB40: =IF( AND( ISNUMBER(RESULTADOS!C40), ISNUMBER(RESULTADOS!E40), ISNUMBER(C40), ISNUMBER(E40), AND(Z40=1,AA40=0,(RESULTADOS!C40-RESULTADOS!E40)=(C40-E40)) ), 1, 0 ) -> 0 | AC40: E37 | AD40: E40 | AE40: C42 | AF40: =IF(ISNUMBER(FIND("C", AC40, 1)), SUBSTITUTE(AC40, "C", "E"), SUBSTITUTE(AC40, "E", "C")) -> C37 | AG40: =IF(ISNUMBER(FIND("C", AD40, 1)), SUBSTITUTE(AD40, "C", "E"), SUBSTITUTE(AD40, "E", "C")) -> C40 | AH40: =IF(ISNUMBER(FIND("C", AE40, 1)), SUBSTITUTE(AE40, "C", "E"), SUBSTITUTE(AE40, "E", "C")) -> E42
B41: Equador | D41: x | F41: Alemanha | H41: 46198 | I41: 0.70833333 | K41: Equador | L41: =SUM(IF(AND(ISNUMBER(INDIRECT($AC41)),INDIRECT($AC41)>INDIRECT($AF41)),3,IF(AND(ISNUMBER(INDIRECT($AC41)),INDIRECT($AC41)=INDIRECT($AF41)),1,0)),IF(AND(ISNUMBER(INDIRECT($AD41)),INDIRECT($AD41)>INDIRECT($AG41)),3,IF(AND(ISNUMBER(INDIRECT($AD41)),INDIRECT($AD41)=INDIRECT($AG41)),1,0)),IF(AND(ISNUMBER(INDIRECT($AE41)),INDIRECT($AE41)>INDIRECT($AH41)),3,IF(AND(ISNUMBER(INDIRECT($AE41)),INDIRECT($AE41)=INDIRECT($AH41)),1,0))) -> 0 | M41: =N41-O41 -> 0 | N41: =SUM(INDIRECT($AC41),INDIRECT($AD41),INDIRECT($AE41)) -> 0 | O41: =SUM(INDIRECT($AF41),INDIRECT($AG41),INDIRECT($AH41)) -> 0 | P41: =SUM(IF(AND(ISNUMBER(INDIRECT($AC41)),INDIRECT($AC41)>INDIRECT($AF41)),1,0),IF(AND(ISNUMBER(INDIRECT($AD41)),INDIRECT($AD41)>INDIRECT($AG41)),1,0),IF(AND(ISNUMBER(INDIRECT($AE41)),INDIRECT($AE41)>INDIRECT($AH41)),1,0)) -> 0 | Q41: =SUM(IF(AND(ISNUMBER(INDIRECT($AC41)),INDIRECT($AC41)=INDIRECT($AF41)),1,0),IF(AND(ISNUMBER(INDIRECT($AD41)),INDIRECT($AD41)=INDIRECT($AG41)),1,0),IF(AND(ISNUMBER(INDIRECT($AE41)),INDIRECT($AE41)=INDIRECT($AH41)),1,0)) -> 0 | R41: =SUM(IF(AND(ISNUMBER(INDIRECT($AC41)),INDIRECT($AC41)<INDIRECT($AF41)),1,0),IF(AND(ISNUMBER(INDIRECT($AD41)),INDIRECT($AD41)<INDIRECT($AG41)),1,0),IF(AND(ISNUMBER(INDIRECT($AE41)),INDIRECT($AE41)<INDIRECT($AH41)),1,0)) -> 0 | T41: =IF(NOT(AND(ISNUMBER(C41),ISNUMBER(E41))),"XXX","") -> XXX | U41: =SUM(Y41,Z41,AA41, AB41) -> 0 | Y41: =IF(AND(ISNUMBER(RESULTADOS!C41),ISNUMBER(RESULTADOS!E41),ISNUMBER(C41),ISNUMBER(E41),C41=RESULTADOS!C41,E41=RESULTADOS!E41),2,0) -> 0 | Z41: =IF(AND(ISNUMBER(RESULTADOS!C41),ISNUMBER(RESULTADOS!E41),ISNUMBER(C41),ISNUMBER(E41)),IF(OR(AND(C41>E41,RESULTADOS!C41>RESULTADOS!E41),AND(C41<E41,RESULTADOS!C41<RESULTADOS!E41)),1,IF(AND(C41=E41,RESULTADOS!C41=RESULTADOS!E41),2,0)),0) -> 0 | AA41: =IF(AND(ISNUMBER(RESULTADOS!C41),ISNUMBER(RESULTADOS!E41),ISNUMBER(C41),ISNUMBER(E41),AND(Z41=1,OR(C41=RESULTADOS!C41,E41=RESULTADOS!E41))),1,0) -> 0 | AB41: =IF( AND( ISNUMBER(RESULTADOS!C41), ISNUMBER(RESULTADOS!E41), ISNUMBER(C41), ISNUMBER(E41), AND(Z41=1,AA41=0,(RESULTADOS!C41-RESULTADOS!E41)=(C41-E41)) ), 1, 0 ) -> 0 | AC41: E38 | AD41: C40 | AE41: C41 | AF41: =IF(ISNUMBER(FIND("C", AC41, 1)), SUBSTITUTE(AC41, "C", "E"), SUBSTITUTE(AC41, "E", "C")) -> C38 | AG41: =IF(ISNUMBER(FIND("C", AD41, 1)), SUBSTITUTE(AD41, "C", "E"), SUBSTITUTE(AD41, "E", "C")) -> E40 | AH41: =IF(ISNUMBER(FIND("C", AE41, 1)), SUBSTITUTE(AE41, "C", "E"), SUBSTITUTE(AE41, "E", "C")) -> E41
